Workbook

Sheet Read Me
A1: 2026-04 April - Specialty Claims
A3: =COUNTA(BH!$D$2:$D$1000,DME!$D$2:$D$1000,GAE!$D$2:$D$1000,ORTHO!$D$2:$D$1000,US!$D$2:$D$1000)&" claims with a date of service in 2026-04 April, split into one sheet per specialty: BH, DME, GAE, ORTHO, US." -> 84 claims with a date of service in 2026-04 April, split into one sheet per specialty: BH, DME, GAE, ORTHO, US.
A5: Row order - work queue, then timely filing deadline
A6: Every specialty sheet is sorted in four groups: Rejected claims at the very top, then claims with an empty Latest Date Worked (column K), then the other open claims, and Finalized and PAID claims at the bottom (a Finalized or PAID claim with an empty Latest Date Worked stays in the empty Latest Date Worked group). Within each group, rows are ordered by how close the claim is to its primary payer's timely filing deadline. Days Until Deadline (column L) carries the count: five days or less left is shaded red, a negative number means the filing window has already closed, and a blank means no limit is on file for that payer.
A7: Deadline order within each group, with the colour band each row gets (these counts update automatically; Finalized claims with a Latest Date Worked have their deadline cells left empty and are not counted):
A8: =" 1 - Due in 5 days or less: "&SUM(COUNTIFS(BH!$L$2:$L$1000,">=0",BH!$L$2:$L$1000,"<=5"),COUNTIFS(DME!$L$2:$L$1000,">=0",DME!$L$2:$L$1000,"<=5"),COUNTIFS(GAE!$L$2:$L$1000,">=0",GAE!$L$2:$L$1000,"<=5"),COUNTIFS(ORTHO!$L$2:$L$1000,">=0",ORTHO!$L$2:$L$1000,"<=5"),COUNTIFS(US!$L$2:$L$1000,">=0",US!$L$2:$L$1000,"<=5")) -> 1 - Due in 5 days or less: 0
A9: =" 2 - Due in 6-30 days: "&SUM(COUNTIFS(BH!$L$2:$L$1000,">5",BH!$L$2:$L$1000,"<=30"),COUNTIFS(DME!$L$2:$L$1000,">5",DME!$L$2:$L$1000,"<=30"),COUNTIFS(GAE!$L$2:$L$1000,">5",GAE!$L$2:$L$1000,"<=30"),COUNTIFS(ORTHO!$L$2:$L$1000,">5",ORTHO!$L$2:$L$1000,"<=30"),COUNTIFS(US!$L$2:$L$1000,">5",US!$L$2:$L$1000,"<=30")) -> 2 - Due in 6-30 days: 0
A10: =" 3 - Due in 31+ days: "&SUM(COUNTIFS(BH!$L$2:$L$1000,">30"),COUNTIFS(DME!$L$2:$L$1000,">30"),COUNTIFS(GAE!$L$2:$L$1000,">30"),COUNTIFS(ORTHO!$L$2:$L$1000,">30"),COUNTIFS(US!$L$2:$L$1000,">30")) -> 3 - Due in 31+ days: 21
A11: =" 4 - Past deadline: "&SUM(COUNTIFS(BH!$L$2:$L$1000,"<0"),COUNTIFS(DME!$L$2:$L$1000,"<0"),COUNTIFS(GAE!$L$2:$L$1000,"<0"),COUNTIFS(ORTHO!$L$2:$L$1000,"<0"),COUNTIFS(US!$L$2:$L$1000,"<0")) -> 4 - Past deadline: 38
A12: =" 5 - No limit on file: "&SUM(SUMPRODUCT((BH!$D$2:$D$1000<>"")*(BH!$L$2:$L$1000="")*(1-(TRIM(BH!$A$2:$A$1000)="Finalized")*(BH!$K$2:$K$1000<>""))),SUMPRODUCT((DME!$D$2:$D$1000<>"")*(DME!$L$2:$L$1000="")*(1-(TRIM(DME!$A$2:$A$1000)="Finalized")*(DME!$K$2:$K$1000<>""))),SUMPRODUCT((GAE!$D$2:$D$1000<>"")*(GAE!$L$2:$L$1000="")*(1-(TRIM(GAE!$A$2:$A$1000)="Finalized")*(GAE!$K$2:$K$1000<>""))),SUMPRODUCT((ORTHO!$D$2:$D$1000<>"")*(ORTHO!$L$2:$L$1000="")*(1-(TRIM(ORTHO!$A$2:$A$1000)="Finalized")*(ORTHO!$K$2:$K$1000<>""))),SUMPRODUCT((US!$D$2:$D$1000<>"")*(US!$L$2:$L$1000="")*(1-(TRIM(US!$A$2:$A$1000)="Finalized")*(US!$K$2:$K$1000<>"")))) -> 5 - No limit on file: 8
A14: Past due rows sit below the claims that can still be filed on time rather than at the very top, so the actionable work stays first. That is why the numbers run up to the longest window and then restart at the negatives.
A15: Filing Deadline is the date of service plus the primary payer's limit, taken from 'Carrier_Timely_Filing_Reference.xlsx'. Days Until Deadline is a live formula, so the count stays true as time passes - but the row order is a snapshot taken on 12 August 2026. Sorting on Days Until Deadline alone would mix the four groups above back together, so when you re-sort keep the Rejected rows first, then the empty Latest Date Worked rows, and the Finalized and PAID rows last.
A16: Where a payer had two possible limits the shorter one was used, so the real deadline can only be later, never earlier. Filing Limit and Limit Carrier name the figure applied and the carrier row it came from.
A17: Deadlines are counted from the date of service. Secondary claims are often counted from the primary payer's remittance date instead - that is not reflected here.
A19: Cells you edit
A20: Four columns are shaded pale yellow and are the ones meant to be edited here: Claim Status (A), Notes (B), Processed Date (C) and Latest Date Worked (K). Claim Status has a drop-down list, and anything not on the list is rejected so a typo cannot slip in. To add a new status, edit the list under Data > Data Validation.
A21: Statuses on the drop-down: Denied, Finalized, Not found, PAID, Pending, Received, Rejected, Under Review.
A22: Example of the expected format - Claim Status: "Denied"; Notes: "Corrected service line 1 - resubmitted"; Processed Date: "06/25/2026"; Latest Date Worked: "08/12/2026".
A24: Processed Date and Latest Date Worked
A25: Both are real dates displayed MM/DD/YYYY, the same order as every other date column in these files and as the source data. Latest Date Worked starts empty.
A26: Processed Date is filled in wherever the row had something to fill it with: the date written into the Notes where there was one, otherwise the Insurance Check Date. A date from the Notes is never overwritten by a check date. Where the row has neither, it is blank for you to fill in.
A28: Corrected claim and appeal countdowns
... A50: Any other status is left unshaded.

Sheet BH
A1: Claim Status | B1: Notes | C1: Processed Date | D1: Primary Claim ID | E1: Chart Number | F1: Date of Service | G1: Responsible Payer | H1: Primary Payer Name | I1: Secondary Payer Name | J1: Procedure Code | K1: Latest Date Worked | L1: Days Until Deadline | M1: Days Until Corrected Claim Deadline | N1: Days Until Appeal Deadline | O1: Filing Deadline | P1: Filing Limit | Q1: Limit Carrier | R1: Corrected Claim Limit | S1: Corrected Claim From | T1: Appeal Limit | U1: Appeal From | V1: Modifier 1 | W1: Modifier 2 | X1: Modifier 3 | Y1: Units | Z1: Charge Amount | AA1: Adjustment | AB1: Insurance Payment | AC1: Insurance Check Date | AD1: Insurance Balance | AE1: AR Age by Service Date | AF1: Diagnosis Code 1 | AG1: Diagnosis Code 2 | AH1: Diagnosis Code 3 | AI1: Diagnosis Code 4 | AJ1: Secondary Claim ID | AK1: Rendering Provider | AL1: Location Name | AM1: Created Date | AN1: Specialty
A2: Pending | B2: secondary - Sent on 06/08/2026 - None of the secon claims are paid - Primary paid | D2: 556872696 | E2: HF505008638 | F2: 46133 | G2: ILWU PMA COASTWISE | H2: Medicare Railroad (RR Medicare MetraHealth) 00882 | I2: ILWU PMA COASTWISE | J2: 99492 x1; 99494 x1 | L2: =IF($O2="","",$O2-TODAY()) -> 198 | M2: =IF(AND(TRIM($A2)="Finalized",$K2<>""),"",IF($C2="","",$C2+365-TODAY())) | N2: =IF(AND(TRIM($A2)="Finalized",$K2<>""),"",IF($C2="","",$C2+120-TODAY())) | O2: =IF(AND(TRIM($A2)="Finalized",$K2<>""),"",DATE(2027,4,21)) -> 46498 | P2: 365 days | Q2: MEDICARE | R2: 365 days | S2: Processed date | T2: 120 days | U2: Processed date | Y2: 1 | Z2: 1426.25 | AA2: 1212.77 | AB2: 170.09 | AC2: 46168 | AD2: 43.39 | AE2: 109 | AF2: F4320 | AJ2: 561534353 | AK2: SARKAR, AWNIK | AL2: ASAP Peoria | AM2: 46153 | AN2: BH
A3: Under Review | B3: Waiting for account to get activated again | D3: 556047036 | E3: HF511715901 | F3: 46127 | G3: Gold Kidney Health Plan | H3: Gold Kidney Health Plan | I3: No Payer | J3: 99493 x1 | L3: =IF($O3="","",$O3-TODAY()) | Q3: Not on reference list | Y3: 1 | Z3: 976.64 | AA3: 0 | AB3: 0 | AD3: 976.64 | AE3: 115 | AF3: F1190 | AK3: O'NEIL, ROY | AL3: ASAP - Gilbert | AM3: 46153 | AN3: BH
A4: Under Review | B4: Waiting for account to get activated again | D4: 557578390 | E4: HF551860180 | F4: 46141 | G4: Gold Kidney Health Plan | H4: Gold Kidney Health Plan | I4: No Payer | J4: 99494 x1; 99492 x1 | L4: =IF($O4="","",$O4-TODAY()) | Q4: Not on reference list | Y4: 1 | Z4: 1426.25 | AA4: 0 | AB4: 0 | AD4: 1426.25 | AE4: 101 | AF4: F39 | AK4: LEATHEM, JARRETT | AL4: ASAP - Gilbert | AM4: 46153 | AN4: BH
A5: Denied | B5: Resubmitted to Humana - HCO/HMO listed Humana - DND Charges are covered under a capitation agreement/managed care plan | C5: 46157 | D5: 554943318 | E5: HF534535040 | F5: 46113 | G5: Medicare Part B Arizona * | H5: Medicare Part B Arizona * | I5: No Payer | J5: 99494 x1; 99493 x1 | K5: 46265 | L5: =IF($O5="","",$O5-TODAY()) -> 178 | M5: =IF(AND(TRIM($A5)="Finalized",$K5<>""),"",IF($C5="","",$C5+365-TODAY())) -> 222 | N5: =IF(AND(TRIM($A5)="Finalized",$K5<>""),"",IF($C5="","",$C5+120-TODAY())) -> -23 | O5: =IF(AND(TRIM($A5)="Finalized",$K5<>""),"",DATE(2027,4,1)) -> 46478 | P5: 365 days | Q5: MEDICARE | R5: 365 days | S5: Processed date | T5: 120 days | U5: Processed date | Y5: 1 | Z5: 1372.91 | AA5: 0 | AB5: 0 | AC5: 46157 | AD5: 1372.91 | AE5: 129 | AF5: F4320 | AK5: MEARS, CHAD | AL5: ASAP - DEER VALLEY | AM5: 46153 | AN5: BH
A6: Denied | B6: Jess resubmitted claim | C6: 46162 | D6: 566720408 | E6: HF537685966 | F6: 46113 | G6: Blue Cross Blue Shield of Arizona (BCBS AZ) | H6: Blue Cross Blue Shield of Arizona (BCBS AZ) | I6: Medicare Part B Arizona * | J6: 99494 x1; 99493 x1 | K6: 46231 | L6: =IF($O6="","",$O6-TODAY()) -> -97 | M6: =IF(AND(TRIM($A6)="Finalized",$K6<>""),"",IF($F6="","",$F6+90-TODAY())) -> -97 | N6: =IF(AND(TRIM($A6)="Finalized",$K6<>""),"",IF($C6="","",$C6+365-TODAY())) -> 227 | O6: =IF(AND(TRIM($A6)="Finalized",$K6<>""),"",DATE(2026,6,30)) -> 46203 | P6: 90 days | Q6: BCBS | R6: 90 days | S6: Date of service | T6: 365 days | U6: Processed date | Y6: 1 | Z6: 1372.91 | AA6: 0 | AB6: 0 | AC6: 46162 | AD6: 1372.91 | AE6: 129 | AF6: F330 | AK6: BAUGHER, TIMOTHY | AL6: ASAP - Gilbert | AM6: 46153 | AN6: BH
A7: Denied | B7: Waiting to post and adjust balance - DND The time limit for filing has expired - Added Date of Current Illness, claim note, and resubmitted | C7: 46262 | D7: 556413148 | E7: HF509386349 | F7: 46127 | G7: Optum Care Medical Network of Arizona, Utah, & Washington (LifePrint) | H7: Optum Care Medical Network of Arizona, Utah, & Washington (LifePrint) | I7: No Payer | J7: 99494 x2; 99493 x1 | K7: 46257 | L7: =IF($O7="","",$O7-TODAY()) -> -83 | M7: =IF(AND(TRIM($A7)="Finalized",$K7<>""),"",IF($C7="","",$C7+365-TODAY())) -> 327 | N7: =IF(AND(TRIM($A7)="Finalized",$K7<>""),"",IF($C7="","",$C7+365-TODAY())) -> 327 | O7: =IF(AND(TRIM($A7)="Finalized",$K7<>""),"",DATE(2026,7,14)) -> 46217 | P7: 90 days | Q7: OPTUM | R7: 365 days | S7: Processed date | T7: 365 days | U7: Processed date | Y7: 2, 1 | Z7: 1769.18 | AA7: 0 | AB7: 0 | AD7: 1769.18 | AE7: 115 | AF7: F1190 | AK7: O'NEIL, ROY | AL7: ASAP - DEER VALLEY | AM7: 46153 | AN7: BH
A8: Denied | B8: Checking with our credentialing team - OON Provider Dr. Sarkar - DND No coverage | C8: 46157 | D8: 556564886 | E8: HF331718997 | F8: 46132 | G8: Blue Cross Blue Shield of Arizona (BCBS AZ) | H8: Blue Cross Blue Shield of Arizona (BCBS AZ) | I8: No Payer | J8: 99494 x1; 99493 x1 | K8: 46276 | L8: =IF($O8="","",$O8-TODAY()) -> -78 | M8: =IF(AND(TRIM($A8)="Finalized",$K8<>""),"",IF($F8="","",$F8+90-TODAY())) -> -78 | N8: =IF(AND(TRIM($A8)="Finalized",$K8<>""),"",IF($C8="","",$C8+365-TODAY())) -> 222 | O8: =IF(AND(TRIM($A8)="Finalized",$K8<>""),"",DATE(2026,7,19)) -> 46222 | P8: 90 days | Q8: BCBS | R8: 90 days | S8: Date of service | T8: 365 days | U8: Processed date | Y8: 1 | Z8: 1372.91 | AA8: 0 | AB8: 0 | AC8: 46157 | AD8: 1372.91 | AE8: 110 | AF8: F4323 | AK8: SARKAR, AWNIK | AL8: ASAP Peoria | AM8: 46153 | AN8: BH
A9: Denied | B9: Added Date of Current Illness, claim note, and resubmitted - DND 99493 This non-payable code is for required reporting only. | C9: 46167 | D9: 556918462 | E9: HF341023592 | F9: 46134 | G9: Optum Care Medical Network of Arizona, Utah, & Washington (LifePrint) | H9: Optum Care Medical Network of Arizona, Utah, & Washington (LifePrint) | I9: No Payer | J9: 99494 x1; 99493 x1 | K9: 46265 | L9: =IF($O9="","",$O9-TODAY()) -> -76 | M9: =IF(AND(TRIM($A9)="Finalized",$K9<>""),"",IF($C9="","",$C9+365-TODAY())) -> 232 | N9: =IF(AND(TRIM($A9)="Finalized",$K9<>""),"",IF($C9="","",$C9+365-TODAY())) -> 232 | O9: =IF(AND(TRIM($A9)="Finalized",$K9<>""),"",DATE(2026,7,21)) -> 46224 | P9: 90 days | Q9: OPTUM | R9: 365 days | S9: Processed date | T9: 365 days | U9: Processed date | Y9: 1 | Z9: 1372.91 | AA9: 0 | AB9: 0 | AC9: 46167 | AD9: 1372.91 | AE9: 108 | AF9: F332 | AG9: F411 | AK9: TURLEY, TODD | AL9: ASAP - Gilbert | AM9: 46153 | AN9: BH
A10: Denied | B10: Added Date of Current Illness, claim note, and resubmitted | C10: 46167 | D10: 557132196 | E10: HF460603685 | F10: 46136 | G10: Optum Care Medical Network of Arizona, Utah, & Washington (LifePrint) | H10: Optum Care Medical Network of Arizona, Utah, & Washington (LifePrint) | I10: No Payer | J10: 99494 x1; 99493 x1 | K10: 46265 | L10: =IF($O10="","",$O10-TODAY()) -> -74 | M10: =IF(AND(TRIM($A10)="Finalized",$K10<>""),"",IF($C10="","",$C10+365-TODAY())) -> 232 | N10: =IF(AND(TRIM($A10)="Finalized",$K10<>""),"",IF($C10="","",$C10+365-TODAY())) -> 232 | O10: =IF(AND(TRIM($A10)="Finalized",$K10<>""),"",DATE(2026,7,23)) -> 46226 | P10: 90 days | Q10: OPTUM | R10: 365 days | S10: Processed date | T10: 365 days | U10: Processed date | Y10: 1 | Z10: 1372.91 | AA10: 0 | AB10: 0 | AC10: 46167 | AD10: 1372.91 | AE10: 106 | AF10: F4323 | AK10: LEATHEM, JARRETT | AL10: ASAP - Gilbert | AM10: 46153 | AN10: BH
A11: Denied | B11: Added active referral for DOS and resubmitted, but these are non-covered services by VA. We need a separate RFS approval to get BH covarage | C11: 46161 | D11: 555379100 | E11: HF549150041 | F11: 46120 | G11: TRIWEST VA CCN CLAIMS | H11: TRIWEST VA CCN CLAIMS | I11: No Payer | J11: 99492 x1; 99494 x1 | K11: 46257 | L11: =IF($O11="","",$O11-TODAY()) -> -60 | M11: =IF(AND(TRIM($A11)="Finalized",$K11<>""),"",IF($C11="","",$C11+365-TODAY())) -> 226 | N11: =IF(AND(TRIM($A11)="Finalized",$K11<>""),"",IF($C11="","",$C11+90-TODAY())) -> -49 | O11: =IF(AND(TRIM($A11)="Finalized",$K11<>""),"",DATE(2026,8,6)) -> 46240 | P11: 120 days | Q11: TRIWEST | R11: 365 days | S11: Processed date | T11: 90 days | U11: Processed date | Y11: 1 | Z11: 1426.25 | AA11: 0 | AB11: 0 | AD11: 1426.25 | AE11: 122 | AF11: F39 | AK11: TURLEY, TODD | AL11: ASAP - Gilbert | AM11: 46153 | AN11: BH
A12: Finalized | B12: Shifted balance to PT - ChampVA doesn't cover BH - $25.00 was assigned to PR 3 | C12: 46157 | D12: 557054917 | E12: HF545223898 | F12: 46135 | G12: ChampVA - HAC | H12: Humana Gold Plus HMO | I12: ChampVA - HAC | J12: 99493 x1 | K12: 46265 | L12: =IF($O12="","",$O12-TODAY()) | M12: =IF(AND(TRIM($A12)="Finalized",$K12<>""),"",IF($F12="","",$F12+90-TODAY())) | N12: =IF(AND(TRIM($A12)="Finalized",$K12<>""),"",IF($C12="","",$C12+540-TODAY())) | O12: =IF(AND(TRIM($A12)="Finalized",$K12<>""),"",DATE(2026,7,22)) | P12: 90 days | Q12: HUMANA MA | R12: 90 days | S12: Date of service | T12: 540 days | U12: Processed date | Y12: 1 | Z12: 976.64 | AA12: 843.88 | AB12: 107.76 | AC12: 46157 | AD12: 25 | AE12: 107 | AF12: F4323 | AJ12: 561534406 | AK12: BURGHER, ABRAM | AL12: ASAP - DEER VALLEY | AM12: 46153 | AN12: BH

Sheet DME
A1: Claim Status | B1: Notes | C1: Processed Date | D1: Primary Claim ID | E1: Chart Number | F1: Date of Service | G1: Responsible Payer | H1: Primary Payer Name | I1: Secondary Payer Name | J1: Procedure Code | K1: Latest Date Worked | L1: Days Until Deadline | M1: Days Until Corrected Claim Deadline | N1: Days Until Appeal Deadline | O1: Filing Deadline | P1: Filing Limit | Q1: Limit Carrier | R1: Corrected Claim Limit | S1: Corrected Claim From | T1: Appeal Limit | U1: Appeal From | V1: Modifier 1 | W1: Modifier 2 | X1: Modifier 3 | Y1: Units | Z1: Charge Amount | AA1: Adjustment | AB1: Insurance Payment | AC1: Insurance Check Date | AD1: Insurance Balance | AE1: AR Age by Service Date | AF1: Diagnosis Code 1 | AG1: Diagnosis Code 2 | AH1: Diagnosis Code 3 | AI1: Diagnosis Code 4 | AJ1: Secondary Claim ID | AK1: Rendering Provider | AL1: Location Name | AM1: Created Date | AN1: Specialty
A2: Under Review | B2: Call 800-636-2123 - DND A6010 Preferred Homecare is responsible for these services. Please submit the claim to Preferred Homecare for consideration | C2: 46141 | D2: 556770603 | E2: HF329310676 | F2: 46121 | G2: UnitedHealthcare Community Plan / Arizona Long Term Care | H2: UnitedHealthcare Community Plan / Arizona Long Term Care | I2: No Payer | J2: A6010+A1 x10 | L2: =IF($O2="","",$O2-TODAY()) -> -89 | M2: =IF(AND(TRIM($A2)="Finalized",$K2<>""),"",IF($C2="","",$C2+180-TODAY())) -> 21 | N2: =IF(AND(TRIM($A2)="Finalized",$K2<>""),"",IF($C2="","",$C2+365-TODAY())) -> 206 | O2: =IF(AND(TRIM($A2)="Finalized",$K2<>""),"",DATE(2026,7,8)) -> 46211 | P2: 90 days | Q2: UHC COMMUNITY | R2: 180 days | S2: Processed date | T2: 365 days | U2: Processed date | V2: A1 | Y2: 10 | Z2: 2958.2 | AA2: 0 | AB2: 0 | AC2: 46141 | AD2: 2958.2 | AE2: 121 | AF2: G894 | AG2: M5127 | AK2: MARTINEZ, DIANA | AL2: ASAP - DEER VALLEY | AM2: 46133 | AN2: DME
A3: Under Review | B3: Call 800-636-2123 - DND A6010 Preferred Homecare is responsible for these services. Please submit the claim to Preferred Homecare for consideration | C3: 46141 | D3: 556772233 | E3: HF537334664 | F3: 46122 | G3: UnitedHealthcare Community Plan / Arizona Long Term Care | H3: UnitedHealthcare Community Plan / Arizona Long Term Care | I3: Mercy Care Plan (AHCCCS) - Complete Care & Long Term Care (LTC) | J3: A6010+A2 x20 | L3: =IF($O3="","",$O3-TODAY()) -> -88 | M3: =IF(AND(TRIM($A3)="Finalized",$K3<>""),"",IF($C3="","",$C3+180-TODAY())) -> 21 | N3: =IF(AND(TRIM($A3)="Finalized",$K3<>""),"",IF($C3="","",$C3+365-TODAY())) -> 206 | O3: =IF(AND(TRIM($A3)="Finalized",$K3<>""),"",DATE(2026,7,9)) -> 46212 | P3: 90 days | Q3: UHC COMMUNITY | R3: 180 days | S3: Processed date | T3: 365 days | U3: Processed date | V3: A2 | Y3: 20 | Z3: 5916.4 | AA3: 0 | AB3: 0 | AC3: 46141 | AD3: 5916.4 | AE3: 120 | AF3: G894 | AK3: ADLER, STEVEN | AL3: ASAP - DEER VALLEY | AM3: 46133 | AN3: DME
A4: Under Review | B4: Checking with Bri - Dr. Awnik Sarkar OON with member's Independence Blue Cross PPO - Devereux Benefit Plan | C4: 46141 | D4: 556801807 | E4: HF331718997 | F4: 46125 | G4: Blue Cross Blue Shield of Arizona (BCBS AZ) | H4: Blue Cross Blue Shield of Arizona (BCBS AZ) | I4: No Payer | J4: A6010+A1 x10 | L4: =IF($O4="","",$O4-TODAY()) -> -85 | M4: =IF(AND(TRIM($A4)="Finalized",$K4<>""),"",IF($F4="","",$F4+90-TODAY())) -> -85 | N4: =IF(AND(TRIM($A4)="Finalized",$K4<>""),"",IF($C4="","",$C4+365-TODAY())) -> 206 | O4: =IF(AND(TRIM($A4)="Finalized",$K4<>""),"",DATE(2026,7,12)) -> 46215 | P4: 90 days | Q4: BCBS | R4: 90 days | S4: Date of service | T4: 365 days | U4: Processed date | V4: A1 | Y4: 10 | Z4: 2958.2 | AA4: 0 | AB4: 0 | AC4: 46141 | AD4: 2958.2 | AE4: 117 | AF4: G894 | AG4: G588 | AK4: SARKAR, AWNIK | AL4: ASAP - Surprise - Reems | AM4: 46134 | AN4: DME
A5: Under Review | B5: Call 800-636-2123 - DND A6010 Preferred Homecare is responsible for these services. Please submit the claim to Preferred Homecare for consideration | C5: 46143 | D5: 565388312 | E5: HF523440375 | F5: 46128 | G5: UnitedHealthcare Community Plan / Arizona Long Term Care | H5: UnitedHealthcare Community Plan / Arizona Long Term Care | I5: No Payer | J5: A6010+A1 x20 | L5: =IF($O5="","",$O5-TODAY()) -> -82 | M5: =IF(AND(TRIM($A5)="Finalized",$K5<>""),"",IF($C5="","",$C5+180-TODAY())) -> 23 | N5: =IF(AND(TRIM($A5)="Finalized",$K5<>""),"",IF($C5="","",$C5+365-TODAY())) -> 208 | O5: =IF(AND(TRIM($A5)="Finalized",$K5<>""),"",DATE(2026,7,15)) -> 46218 | P5: 90 days | Q5: UHC COMMUNITY | R5: 180 days | S5: Processed date | T5: 365 days | U5: Processed date | V5: A1 | Y5: 20 | Z5: 5916.4 | AA5: 0 | AB5: 0 | AC5: 46143 | AD5: 5916.4 | AE5: 114 | AF5: G894 | AG5: M5416 | AK5: HOLLISTER, ALICIA | AL5: ASAP - DEER VALLEY | AM5: 46134 | AN5: DME
A6: Under Review | B6: Call 800-636-2123 - DND A6010 Preferred Homecare is responsible for these services. Please submit the claim to Preferred Homecare for consideration | C6: 46141 | D6: 556833981 | E6: HF519300380 | F6: 46132 | G6: UnitedHealthcare Community Plan / Arizona Long Term Care | H6: UnitedHealthcare Community Plan / Arizona Long Term Care | I6: No Payer | J6: A6010+A1 x10 | L6: =IF($O6="","",$O6-TODAY()) -> -78 | M6: =IF(AND(TRIM($A6)="Finalized",$K6<>""),"",IF($C6="","",$C6+180-TODAY())) -> 21 | N6: =IF(AND(TRIM($A6)="Finalized",$K6<>""),"",IF($C6="","",$C6+365-TODAY())) -> 206 | O6: =IF(AND(TRIM($A6)="Finalized",$K6<>""),"",DATE(2026,7,19)) -> 46222 | P6: 90 days | Q6: UHC COMMUNITY | R6: 180 days | S6: Processed date | T6: 365 days | U6: Processed date | V6: A1 | Y6: 10 | Z6: 2958.2 | AA6: 0 | AB6: 0 | AC6: 46141 | AD6: 2958.2 | AE6: 110 | AF6: G894 | AG6: M461 | AK6: ADLER, STEVEN | AL6: ASAP - DEER VALLEY | AM6: 46134 | AN6: DME
A7: Under Review | B7: Call 800-636-2123 - DND A6010 Preferred Homecare is responsible for these services. Please submit the claim to Preferred Homecare for consideration | C7: 46162 | D7: 558739471 | E7: HF353314392 | F7: 46142 | G7: UnitedHealthcare Community Plan / Arizona Long Term Care | H7: UnitedHealthcare Community Plan / Arizona Long Term Care | I7: UnitedHealthcare Community Plan / Arizona Long Term Care | J7: A6010+A1 x10 | L7: =IF($O7="","",$O7-TODAY()) -> -68 | M7: =IF(AND(TRIM($A7)="Finalized",$K7<>""),"",IF($C7="","",$C7+180-TODAY())) -> 42 | N7: =IF(AND(TRIM($A7)="Finalized",$K7<>""),"",IF($C7="","",$C7+365-TODAY())) -> 227 | O7: =IF(AND(TRIM($A7)="Finalized",$K7<>""),"",DATE(2026,7,29)) -> 46232 | P7: 90 days | Q7: UHC COMMUNITY | R7: 180 days | S7: Processed date | T7: 365 days | U7: Processed date | V7: A1 | Y7: 10 | Z7: 2958.2 | AA7: 0 | AB7: 0 | AC7: 46162 | AD7: 2958.2 | AE7: 100 | AF7: G894 | AG7: M5416 | AK7: HOLLISTER, ALICIA | AL7: ASAP - DEER VALLEY | AM7: 46153 | AN7: DME
A8: Under Review | B8: Chat with anthem about medical records being received - Jess sent MR through fax with barcode letter | C8: 46162 | D8: 562340666 | E8: HF537685966 | F8: 46142 | G8: Blue Cross Blue Shield of Arizona (BCBS AZ) | H8: Blue Cross Blue Shield of Arizona (BCBS AZ) | I8: DME Region D | J8: A6010+A1 x20 | L8: =IF($O8="","",$O8-TODAY()) -> -68 | M8: =IF(AND(TRIM($A8)="Finalized",$K8<>""),"",IF($F8="","",$F8+90-TODAY())) -> -68 | N8: =IF(AND(TRIM($A8)="Finalized",$K8<>""),"",IF($C8="","",$C8+365-TODAY())) -> 227 | O8: =IF(AND(TRIM($A8)="Finalized",$K8<>""),"",DATE(2026,7,29)) -> 46232 | P8: 90 days | Q8: BCBS | R8: 90 days | S8: Date of service | T8: 365 days | U8: Processed date | V8: A1 | Y8: 20 | Z8: 5916.4 | AA8: 0 | AB8: 0 | AC8: 46162 | AD8: 5916.4 | AE8: 100 | AF8: G894 | AG8: M5412 | AH8: M4802 | AK8: LUKE, TIMOTHY | AL8: ASAP - Gilbert | AM8: 46153 | AN8: DME
A9: Under Review | B9: Waiting for account to get activated again | D9: 557846752 | E9: HF550464457 | F9: 46133 | G9: Gold Kidney Health Plan | H9: Gold Kidney Health Plan | I9: No Payer | J9: L0457+KX x1 | L9: =IF($O9="","",$O9-TODAY()) | Q9: Not on reference list | V9: KX | Y9: 1 | Z9: 5320.49 | AA9: 0 | AB9: 0 | AD9: 5320.49 | AE9: 109 | AF9: G90523 | AG9: M5459 | AH9: G894 | AK9: CURRIE, DAVID | AL9: ASAP - Gilbert | AM9: 46153 | AN9: DME
A10: Under Review | B10: Waiting for account to get activated again | D10: 562031529 | E10: HF526933634 | F10: 46133 | G10: Gold Kidney Health Plan | H10: Gold Kidney Health Plan | I10: No Payer | J10: L0650+KX x1 | L10: =IF($O10="","",$O10-TODAY()) | Q10: Not on reference list | V10: KX | Y10: 1 | Z10: 6392.96 | AA10: 0 | AB10: 0 | AD10: 6392.96 | AE10: 109 | AF10: M5417 | AK10: TONDINI, JENISE | AL10: ASAP - Goodyear | AM10: 46140 | AN10: DME
A11: Denied | B11: Filed appeal with MR on portal - Confirmation Number: 148586224 - L1851 requires auth, and we didn't get one | C11: 46127 | D11: 555436823 | E11: HF543718565 | F11: 46114 | G11: DME Region D | H11: DME Region D | I11: Blue Cross Blue Shield of Arizona (BCBS AZ) | J11: L1851+KX+RT x1 | K11: 46283 | L11: =IF($O11="","",$O11-TODAY()) -> 179 | M11: =IF(AND(TRIM($A11)="Finalized",$K11<>""),"",IF($C11="","",$C11+365-TODAY())) -> 192 | N11: =IF(AND(TRIM($A11)="Finalized",$K11<>""),"",IF($C11="","",$C11+120-TODAY())) -> -53 | O11: =IF(AND(TRIM($A11)="Finalized",$K11<>""),"",DATE(2027,4,2)) -> 46479 | P11: 365 days | Q11: MEDICARE | R11: 365 days | S11: Processed date | T11: 120 days | U11: Processed date | V11: KX | W11: RT | Y11: 1 | Z11: 4520.11 | AA11: 0 | AB11: 0 | AC11: 46127 | AD11: 4520.11 | AE11: 128 | AF11: G5781 | AG11: M25561 | AK11: Advanced Spine and Pain LLC DME GWY | AL11: Advanced Spine and Pain LLC DME - Surprise Reems | AM11: 46121 | AN11: DME
A12: Denied | B12: Resubmitted to Medicare Part B - Denied again - Resubmitted to Region B - PT state on portal: WI - DND N104 This claim/service is not payable under our claims jurisdiction area | C12: 46247 | D12: 556799664 | E12: HF465696073 | F12: 46125 | G12: DME Region D | H12: DME Region D | I12: Blue Cross Blue Shield of Arizona (BCBS AZ) | J12: A6010+A1 x20 | K12: 46300 | L12: =IF($O12="","",$O12-TODAY()) -> 190 | M12: =IF(AND(TRIM($A12)="Finalized",$K12<>""),"",IF($C12="","",$C12+365-TODAY())) -> 312 | N12: =IF(AND(TRIM($A12)="Finalized",$K12<>""),"",IF($C12="","",$C12+120-TODAY())) -> 67 | O12: =IF(AND(TRIM($A12)="Finalized",$K12<>""),"",DATE(2027,4,13)) -> 46490 | P12: 365 days | Q12: MEDICARE | R12: 365 days | S12: Processed date | T12: 120 days | U12: Processed date | V12: A1 | Y12: 20 | Z12: 5916.4 | AA12: 0 | AB12: 0 | AD12: 5916.4 | AE12: 117 | AF12: G894 | AG12: M48062 | AK12: Advanced Spine and Pain LLC DME SUR | AL12: Advanced Spine and Pain LLC DME - Surprise Reems | AM12: 46134 | AN12: DME
A13: Pending | B13: secondary - Primary paid | C13: 46151 | D13: 556803684 | E13: HF509774874 | F13: 46125 | G13: DME Region D | H13: DME Region D | I13: Continental Benefits | J13: A6010+A1 x10 | K13: 46261 | L13: =IF($O13="","",$O13-TODAY()) -> 190 | M13: =IF(AND(TRIM($A13)="Finalized",$K13<>""),"",IF($C13="","",$C13+365-TODAY())) -> 216 | N13: =IF(AND(TRIM($A13)="Finalized",$K13<>""),"",IF($C13="","",$C13+120-TODAY())) -> -29 | O13: =IF(AND(TRIM($A13)="Finalized",$K13<>""),"",DATE(2027,4,13)) -> 46490 | P13: 365 days | Q13: MEDICARE | R13: 365 days | S13: Processed date | T13: 120 days | U13: Processed date | V13: A1 | Y13: 10 | Z13: 2958.2 | AA13: 0 | AB13: 0 | AC13: 46151 | AD13: 2958.2 | AE13: 117 | AF13: G894 | AG13: M48062 | AK13: Advanced Spine and Pain LLC DME SUR | AL13: Advanced Spine and Pain LLC DME - Surprise Reems | AM13: 46134 | AN13: DME
A14: Denied | B14: secondary - Edited COB info, and resubmitted - Primary paid | C14: 46281 | D14: 556808178 | E14: HF470696196 | F14: 46132 | G14: DME Region D | H14: DME Region D | I14: Blue Cross Blue Shield of Arizona (BCBS AZ) | J14: A6023+A2 x20 | K14: 46283 | L14: =IF($O14="","",$O14-TODAY()) -> 197 | M14: =IF(AND(TRIM($A14)="Finalized",$K14<>""),"",IF($C14="","",$C14+365-TODAY())) -> 346 | N14: =IF(AND(TRIM($A14)="Finalized",$K14<>""),"",IF($C14="","",$C14+120-TODAY())) -> 101 | O14: =IF(AND(TRIM($A14)="Finalized",$K14<>""),"",DATE(2027,4,20)) -> 46497 | P14: 365 days | Q14: MEDICARE | R14: 365 days | S14: Processed date | T14: 120 days | U14: Processed date | V14: A2 | Y14: 20 | Z14: 36353.8 | AA14: 0 | AB14: 0 | AD14: 36353.8 | AE14: 110 | AF14: G894 | AG14: M5416 | AK14: Advanced Spine and Pain LLC DME SUR | AL14: Advanced Spine and Pain LLC DME - Surprise Reems | AM14: 46134 | AN14: DME
A15: Denied | B15: MBI updated - Resubmitted - DND Missing/incomplete/invalid patient identifier | C15: 46199 | D15: 556834981 | E15: HF342328217 | F15: 46132 | G15: DME Region D | H15: DME Region D | I15: Unicare Life and Health Insurance (Anthem) | J15: A6023+A1 x20 | K15: 46283 | L15: =IF($O15="","",$O15-TODAY()) -> 197 | M15: =IF(AND(TRIM($A15)="Finalized",$K15<>""),"",IF($C15="","",$C15+365-TODAY())) -> 264 | N15: =IF(AND(TRIM($A15)="Finalized",$K15<>""),"",IF($C15="","",$C15+120-TODAY())) -> 19 | O15: =IF(AND(TRIM($A15)="Finalized",$K15<>""),"",DATE(2027,4,20)) -> 46497 | P15: 365 days | Q15: MEDICARE | R15: 365 days | S15: Processed date | T15: 120 days | U15: Processed date | V15: A1 | Y15: 20 | Z15: 36353.8 | AA15: 0 | AB15: 0 | AC15: 46199 | AD15: 36353.8 | AE15: 110 | AF15: G894 | AK15: Advanced Spine and Pain LLC DME GWY | AL15: Advanced Spine and Pain LLC DME - Greenway | AM15: 46198 | AN15: DME
A16: Denied | B16: MBI updated on chart, and resubmitted - DND Missing/incomplete/invalid patient identifier | C16: 46142 | D16: 557499174 | E16: HF330326072 | F16: 46139 | G16: DME Region D | H16: DME Region D | I16: AARP United Healthcare | J16: A6010+A1 x10 | K16: 46278 | L16: =IF($O16="","",$O16-TODAY()) -> 204 | M16: =IF(AND(TRIM($A16)="Finalized",$K16<>""),"",IF($C16="","",$C16+365-TODAY())) -> 207 | N16: =IF(AND(TRIM($A16)="Finalized",$K16<>""),"",IF($C16="","",$C16+120-TODAY())) -> -38 | O16: =IF(AND(TRIM($A16)="Finalized",$K16<>""),"",DATE(2027,4,27)) -> 46504 | P16: 365 days | Q16: MEDICARE | R16: 365 days | S16: Processed date | T16: 120 days | U16: Processed date | V16: A1 | Y16: 10 | Z16: 2958.2 | AA16: 0 | AB16: 0 | AC16: 46142 | AD16: 2958.2 | AE16: 103 | AF16: G894 | AK16: Advanced Spine and Pain LLC DME GWY | AL16: Advanced Spine and Pain LLC DME - Greenway | AM16: 46140 | AN16: DME
A17: Pending | B17: Secondary - Added rendering NPI 1518261023 to box 24j, cob info, and resubmitted | C17: 46202 | D17: 557798679 | E17: HF454494056 | F17: 46142 | G17: Mercy Care Plan (AHCCCS) - Complete Care & Long Term Care (LTC) | H17: DME Region D | I17: Mercy Care Plan (AHCCCS) - Complete Care & Long Term Care (LTC) | J17: L0650+KX x1 | K17: 46284 | L17: =IF($O17="","",$O17-TODAY()) -> 207 | M17: =IF(AND(TRIM($A17)="Finalized",$K17<>""),"",IF($C17="","",$C17+365-TODAY())) -> 267 | N17: =IF(AND(TRIM($A17)="Finalized",$K17<>""),"",IF($C17="","",$C17+120-TODAY())) -> 22 | O17: =IF(AND(TRIM($A17)="Finalized",$K17<>""),"",DATE(2027,4,30)) -> 46507 | P17: 365 days | Q17: MEDICARE | R17: 365 days | S17: Processed date | T17: 120 days | U17: Processed date | V17: KX | Y17: 1 | Z17: 6392.96 | AA17: 5624.17 | AB17: 612.53 | AC17: 46202 | AD17: 156.26 | AE17: 100 | AF17: M5416 | AG17: M47816 | AJ17: 564922714 | AK17: Advanced Spine and Pain LLC DME GWY | AL17: Advanced Spine and Pain LLC DME - Greenway | AM17: 46153 | AN17: DME
A18: Denied | B18: Appeal form completed with MR and forwarded to April for fax submission to payer - Fax # 855-699-8985 | C18: 46197 | D18: 555586629 | E18: HF553228745 | F18: 46118 | G18: HealthSpring Medicare Advantage | H18: HealthSpring Medicare Advantage | I18: No Payer | J18: L0648+KX x1 | K18: 46300 | L18: =IF($O18="","",$O18-TODAY()) -> -92 | M18: =IF(AND(TRIM($A18)="Finalized",$K18<>""),"",IF($F18="","",$F18+90-TODAY())) -> -92 | N18: =IF(AND(TRIM($A18)="Finalized",$K18<>""),"",IF($C18="","",$C18+180-TODAY())) -> 77 | O18: =IF(AND(TRIM($A18)="Finalized",$K18<>""),"",DATE(2026,7,5)) -> 46208 | P18: 90 days | Q18: CIGNA / CIGNA MEDICARE | R18: 90 days | S18: Date of service | T18: 180 days | U18: Processed date | V18: KX | Y18: 1 | Z18: 5492.55 | AA18: 0 | AB18: 0 | AC18: 46197 | AD18: 5492.55 | AE18: 124 | AF18: M8008XA | AK18: KALLGREN, MARK | AL18: ASAP - Mesa | AM18: 46134 | AN18: DME
A19: Denied | B19: Uploaded missing MR to PIQ-85007180 - Jess uploaded POD | C19: 46156 | D19: 561043971 | E19: HF550434312 | F19: 46128 | G19: UnitedHealthcare Community Plan / Arizona Long Term Care | H19: UnitedHealthcare Community Plan / Arizona Long Term Care | I19: No Payer | J19: L0650+NU x1 | K19: 46285 | L19: =IF($O19="","",$O19-TODAY()) -> -82 | M19: =IF(AND(TRIM($A19)="Finalized",$K19<>""),"",IF($C19="","",$C19+180-TODAY())) -> 36 | N19: =IF(AND(TRIM($A19)="Finalized",$K19<>""),"",IF($C19="","",$C19+365-TODAY())) -> 221 | O19: =IF(AND(TRIM($A19)="Finalized",$K19<>""),"",DATE(2026,7,15)) -> 46218 | P19: 90 days | Q19: UHC COMMUNITY | R19: 180 days | S19: Processed date | T19: 365 days | U19: Processed date | V19: NU | Y19: 1 | Z19: 6392.96 | AA19: 0 | AB19: 0 | AC19: 46156 | AD19: 6392.96 | AE19: 114 | AF19: M5416 | AK19: LUKE, TIMOTHY | AL19: ASAP - DEER VALLEY | AM19: 46143 | AN19: DME
A20: Denied | B20: Per Medicare guidelines use of modifier NU is not typical for procedure code L1851. Resubmitted with mods KX+RT - This is a Medicare Advantage plan - DND due to invalid modifier again - Jess resubmitted with only mod NU - DND L1851 Missing procedure modifier(s) - We bill the Lcode with NU+RT | C20: 46215 | D20: 564913658 | E20: HF528969654 | F20: 46140 | G20: Humana | H20: Humana | I20: LIEN 05 | J20: L1851+NU+RT x1 | K20: 46285 | L20: =IF($O20="","",$O20-TODAY()) -> -70 | M20: =IF(AND(TRIM($A20)="Finalized",$K20<>""),"",IF($F20="","",$F20+90-TODAY())) -> -70 | N20: =IF(AND(TRIM($A20)="Finalized",$K20<>""),"",IF($C20="","",$C20+60-TODAY())) -> -25 | O20: =IF(AND(TRIM($A20)="Finalized",$K20<>""),"",DATE(2026,7,27)) -> 46230 | P20: 90 days | Q20: HUMANA COMMERCIAL | R20: 90 days | S20: Date of service | T20: 60 days | U20: Processed date | V20: NU | W20: RT | Y20: 1 | Z20: 4520.11 | AA20: 0 | AB20: 0 | AC20: 46215 | AD20: 4520.11 | AE20: 102 | AF20: M25561 | AK20: KRAUSE, JEFFREY | AL20: ASAP - DEER VALLEY | AM20: 46153 | AN20: DME
A21: Not found | B21: Check if the payer change worked - Submitted claim on portal with MR - Claim Id: 851901307 - Confirmation ID 843724183 - No auth request on file - Retro auth not available at this time | C21: 46154 | D21: 556762240 | E21: HF497623124 | F21: 46114 | G21: AMBETTER | H21: AMBETTER | I21: Mercy Care Plan (AHCCCS) - Complete Care & Long Term Care (LTC) | J21: A6010+A1 x20 | K21: 46285 | L21: =IF($O21="","",$O21-TODAY()) -> -66 | M21: =IF(AND(TRIM($A21)="Finalized",$K21<>""),"",IF($F21="","",$F21+365-TODAY())) -> 179 | N21: =IF(AND(TRIM($A21)="Finalized",$K21<>""),"",IF($C21="","",$C21+180-TODAY())) -> 34 | O21: =IF(AND(TRIM($A21)="Finalized",$K21<>""),"",DATE(2026,7,31)) -> 46234 | P21: 120 days | Q21: AMBETTER | R21: 365 days | S21: Date of service | T21: 180 days | U21: Processed date | V21: A1 | Y21: 20 | Z21: 5916.4 | AA21: 0 | AB21: 0 | AC21: 46154 | AD21: 5916.4 | AE21: 128 | AF21: G894 | AG21: M461 | AK21: TERRILL, STEPHANIE | AL21: ASAP - Gilbert | AM21: 46133 | AN21: DME
A22: Finalized | B22: Adjusted balance - Acodes not included in auth/referral | C22: 46170 | D22: 558742342 | E22: HF524861323 | F22: 46140 | G22: TRIWEST VA CCN CLAIMS | H22: TRIWEST VA CCN CLAIMS | I22: No Payer | J22: A6010+A2 x40 | K22: 46245 | L22: =IF($O22="","",$O22-TODAY()) | M22: =IF(AND(TRIM($A22)="Finalized",$K22<>""),"",IF($C22="","",$C22+365-TODAY())) | N22: =IF(AND(TRIM($A22)="Finalized",$K22<>""),"",IF($C22="","",$C22+90-TODAY())) | O22: =IF(AND(TRIM($A22)="Finalized",$K22<>""),"",DATE(2026,8,26)) | P22: 120 days | Q22: TRIWEST | R22: 365 days | S22: Processed date | T22: 90 days | U22: Processed date | V22: A2 | Y22: 40 | Z22: 72707.6 | AA22: 0 | AB22: 0 | AC22: 46170 | AD22: 72707.6 | AE22: 102 | AF22: G894 | AG22: T85192A | AH22: T85193A | AK22: LEATHEM, JARRETT | AL22: ASAP - Gilbert | AM22: 46153 | AN22: DME
A23: Finalized | B23: Adjusted balance - Only 1 Incision was performed - 20 units each were order - We dispensed 40 unit each as per POD - DND Coverage/program guidelines were exceeded. | C23: 46249 | D23: 556771003 | E23: HF480155713 | F23: 46121 | G23: DME Region D | H23: DME Region D | I23: AARP United Healthcare | J23: A6023+A1 x40 | K23: 46283 | L23: =IF($O23="","",$O23-TODAY()) | M23: =IF(AND(TRIM($A23)="Finalized",$K23<>""),"",IF($C23="","",$C23+365-TODAY())) | N23: =IF(AND(TRIM($A23)="Finalized",$K23<>""),"",IF($C23="","",$C23+120-TODAY())) | O23: =IF(AND(TRIM($A23)="Finalized",$K23<>""),"",DATE(2027,4,9)) | P23: 365 days | Q23: MEDICARE | R23: 365 days | S23: Processed date | T23: 120 days | U23: Processed date | V23: A1 | Y23: 40 | Z23: 72707.6 | AA23: 0 | AB23: 0 | AD23: 72707.6 | AE23: 121 | AF23: G894 | AK23: Advanced Spine and Pain LLC DME SUR | AL23: Advanced Spine and Pain LLC DME - Surprise Reems | AM23: 46133 | AN23: DME
A24: Finalized | B24: Shift to PT - ABN signed - Another L0650 was dispensed back on 04/25/2022 - Supplier SONOSPINE ARIZONA LLC - DND L0650 M3 Equipment is the same or similar to equipment already being used | C24: 46139 | D24: 556764690 | E24: HF551816064 | F24: 46125 | G24: DME Region D | H24: DME Region D | I24: AARP United Healthcare | J24: L0650+KX x1 | K24: 46283 | L24: =IF($O24="","",$O24-TODAY()) | M24: =IF(AND(TRIM($A24)="Finalized",$K24<>""),"",IF($C24="","",$C24+365-TODAY())) | N24: =IF(AND(TRIM($A24)="Finalized",$K24<>""),"",IF($C24="","",$C24+120-TODAY())) | O24: =IF(AND(TRIM($A24)="Finalized",$K24<>""),"",DATE(2027,4,13)) | P24: 365 days | Q24: MEDICARE | R24: 365 days | S24: Processed date | T24: 120 days | U24: Processed date | V24: KX | Y24: 1 | Z24: 6392.96 | AA24: 0 | AB24: 0 | AC24: 46139 | AD24: 6392.96 | AE24: 117 | AF24: M5116 | AK24: Advanced Spine and Pain LLC DME GWY | AL24: Advanced Spine and Pain LLC DME - Greenway | AM24: 46133 | AN24: DME
A25: Finalized | B25: Adjusted balance - No ABN signed - Another L0650 was dispensed back on 04/25/2022 - Supplier SONOSPINE ARIZONA LLC - DND L0650 M3 Equipment is the same or similar to equipment already being used | C25: 46148 | D25: 557840581 | E25: HF330326072 | F25: 46126 | G25: DME Region D | H25: DME Region D | I25: AARP United Healthcare | J25: L0650+KX x1 | K25: 46300 | L25: =IF($O25="","",$O25-TODAY()) | M25: =IF(AND(TRIM($A25)="Finalized",$K25<>""),"",IF($C25="","",$C25+365-TODAY())) | N25: =IF(AND(TRIM($A25)="Finalized",$K25<>""),"",IF($C25="","",$C25+120-TODAY())) | O25: =IF(AND(TRIM($A25)="Finalized",$K25<>""),"",DATE(2027,4,14)) | P25: 365 days | Q25: MEDICARE | R25: 365 days | S25: Processed date | T25: 120 days | U25: Processed date | V25: KX | Y25: 1 | Z25: 6392.96 | AA25: 0 | AB25: 0 | AC25: 46148 | AD25: 6392.96 | AE25: 116 | AF25: M5417 | AK25: Advanced Spine and Pain LLC DME GWY | AL25: Advanced Spine and Pain LLC DME - Greenway | AM25: 46143 | AN25: DME
A26: Finalized | B26: Auth required for 63047 - No request found | C26: 46127 | D26: 565388227 | E26: HF523440375 | F26: 46118 | G26: UnitedHealthcare Community Plan / Arizona Long Term Care | H26: UnitedHealthcare Community Plan / Arizona Long Term Care | I26: No Payer | J26: L0637+NU x1 | K26: 46284 | L26: =IF($O26="","",$O26-TODAY()) | M26: =IF(AND(TRIM($A26)="Finalized",$K26<>""),"",IF($C26="","",$C26+180-TODAY())) | N26: =IF(AND(TRIM($A26)="Finalized",$K26<>""),"",IF($C26="","",$C26+365-TODAY())) | O26: =IF(AND(TRIM($A26)="Finalized",$K26<>""),"",DATE(2026,7,5)) | P26: 90 days | Q26: UHC COMMUNITY | R26: 180 days | S26: Processed date | T26: 365 days | U26: Processed date | V26: NU | Y26: 1 | Z26: 9479.4 | AA26: 0 | AB26: 0 | AC26: 46127 | AD26: 9479.4 | AE26: 124 | AF26: M48062 | AK26: LUKE, TIMOTHY | AL26: ASAP - DEER VALLEY | AM26: 46121 | AN26: DME
A27: Finalized | B27: Adjusted balance - No auth request on file for collagen dressings - DND Acodes no auth | C27: 46170 | D27: 556802417 | E27: HF429774034 | F27: 46125 | G27: Optum Care Medical Network of Arizona, Utah, & Washington (LifePrint) | H27: Optum Care Medical Network of Arizona, Utah, & Washington (LifePrint) | I27: No Payer | J27: A6010+A1 x20 | K27: 46285 | L27: =IF($O27="","",$O27-TODAY()) | M27: =IF(AND(TRIM($A27)="Finalized",$K27<>""),"",IF($C27="","",$C27+365-TODAY())) | N27: =IF(AND(TRIM($A27)="Finalized",$K27<>""),"",IF($C27="","",$C27+365-TODAY())) | O27: =IF(AND(TRIM($A27)="Finalized",$K27<>""),"",DATE(2026,7,12)) | P27: 90 days | Q27: OPTUM | R27: 365 days | S27: Processed date | T27: 365 days | U27: Processed date | V27: A1 | Y27: 20 | Z27: 5916.4 | AA27: 0 | AB27: 0 | AC27: 46170 | AD27: 5916.4 | AE27: 117 | AF27: G894 | AG27: M48062 | AK27: SARKAR, AWNIK | AL27: ASAP - Surprise - Reems | AM27: 46134 | AN27: DME
A28: Finalized | B28: Adjusted balance - No auth request on file for collagen dressings - DND Acodes no auth | C28: 46167 | D28: 556804689 | E28: HF434869353 | F28: 46125 | G28: Optum Care Medical Network of Arizona, Utah, & Washington (LifePrint) | H28: Optum Care Medical Network of Arizona, Utah, & Washington (LifePrint) | I28: No Payer | J28: A6010+A2 x20 | K28: 46285 | L28: =IF($O28="","",$O28-TODAY()) | M28: =IF(AND(TRIM($A28)="Finalized",$K28<>""),"",IF($C28="","",$C28+365-TODAY())) | N28: =IF(AND(TRIM($A28)="Finalized",$K28<>""),"",IF($C28="","",$C28+365-TODAY())) | O28: =IF(AND(TRIM($A28)="Finalized",$K28<>""),"",DATE(2026,7,12)) | P28: 90 days | Q28: OPTUM | R28: 365 days | S28: Processed date | T28: 365 days | U28: Processed date | V28: A2 | Y28: 20 | Z28: 5916.4 | AA28: 0 | AB28: 0 | AC28: 46167 | AD28: 5916.4 | AE28: 117 | AF28: G894 | AG28: M5416 | AK28: SARKAR, AWNIK | AL28: ASAP - Surprise - Reems | AM28: 46134 | AN28: DME
A29: Finalized | B29: Adjusted balance - No auth request on file for collagen dressings - DND Acodes no auth | C29: 46170 | D29: 556801421 | E29: HF540895134 | F29: 46128 | G29: Optum Care Medical Network of Arizona, Utah, & Washington (LifePrint) | H29: Optum Care Medical Network of Arizona, Utah, & Washington (LifePrint) | I29: No Payer | J29: A6010+A1 x20 | K29: 46285 | L29: =IF($O29="","",$O29-TODAY()) | M29: =IF(AND(TRIM($A29)="Finalized",$K29<>""),"",IF($C29="","",$C29+365-TODAY())) | N29: =IF(AND(TRIM($A29)="Finalized",$K29<>""),"",IF($C29="","",$C29+365-TODAY())) | O29: =IF(AND(TRIM($A29)="Finalized",$K29<>""),"",DATE(2026,7,15)) | P29: 90 days | Q29: OPTUM | R29: 365 days | S29: Processed date | T29: 365 days | U29: Processed date | V29: A1 | Y29: 20 | Z29: 5916.4 | AA29: 0 | AB29: 0 | AC29: 46170 | AD29: 5916.4 | AE29: 114 | AF29: G894 | AG29: M48062 | AK29: Arshad, Jawad | AL29: ASAP - Mesa | AM29: 46134 | AN29: DME
A30: Finalized | B30: Shift to PT - ABN signed -No coverage - Policy Number: MP.009.35 - PR non-covered | C30: 46154 | D30: 558609820 | E30: HF331720981 | F30: 46135 | G30: United Healthcare | H30: United Healthcare | I30: No Payer | J30: A6010+A2 x10; A6023+A2 x10 | K30: 46285 | L30: =IF($O30="","",$O30-TODAY()) | M30: =IF(AND(TRIM($A30)="Finalized",$K30<>""),"",IF($C30="","",$C30+180-TODAY())) | N30: =IF(AND(TRIM($A30)="Finalized",$K30<>""),"",IF($C30="","",$C30+365-TODAY())) | O30: =IF(AND(TRIM($A30)="Finalized",$K30<>""),"",DATE(2026,7,22)) | P30: 90 days | Q30: UHC COMMERCIAL | R30: 180 days | S30: Processed date | T30: 365 days | U30: Processed date | V30: A2 | Y30: 10 | Z30: 21135.1 | AA30: 0 | AB30: 0 | AD30: 21135.1 | AE30: 107 | AF30: G894 | AK30: ADLER, STEVEN | AL30: ASAP - DEER VALLEY | AM30: 46150 | AN30: DME
A31: Finalized | B31: Shift to PT - ABN signed -No coverage - Policy Number: MP.009.35 - PR non-covered | C31: 46156 | D31: 557507395 | E31: HF522022623 | F31: 46139 | G31: United Healthcare | H31: United Healthcare | I31: United Healthcare | J31: A6010+A1 x20 | K31: 46285 | L31: =IF($O31="","",$O31-TODAY()) | M31: =IF(AND(TRIM($A31)="Finalized",$K31<>""),"",IF($C31="","",$C31+180-TODAY())) | N31: =IF(AND(TRIM($A31)="Finalized",$K31<>""),"",IF($C31="","",$C31+365-TODAY())) | O31: =IF(AND(TRIM($A31)="Finalized",$K31<>""),"",DATE(2026,7,26)) | P31: 90 days | Q31: UHC COMMERCIAL | R31: 180 days | S31: Processed date | T31: 365 days | U31: Processed date | V31: A1 | Y31: 20 | Z31: 5916.4 | AA31: 0 | AB31: 0 | AC31: 46156 | AD31: 5916.4 | AE31: 103 | AF31: G894 | AG31: M48062 | AK31: KALLGREN, MARK | AL31: ASAP - Mesa | AM31: 46140 | AN31: DME
A32: Finalized | B32: Adjusted balance - BCBS M2K will not cover collagen dressings - DND A6010 Precertification/authorization/notification/pre-treatment absent | C32: 46217 | D32: 562510509 | E32: HF497777502 | F32: 46139 | G32: Optum Care Medical Network of Arizona, Utah, & Washington (LifePrint) | H32: Optum Care Medical Network of Arizona, Utah, & Washington (LifePrint) | I32: No Payer | J32: A6010+A1 x20 | K32: 46285 | L32: =IF($O32="","",$O32-TODAY()) | M32: =IF(AND(TRIM($A32)="Finalized",$K32<>""),"",IF($C32="","",$C32+365-TODAY())) | N32: =IF(AND(TRIM($A32)="Finalized",$K32<>""),"",IF($C32="","",$C32+365-TODAY())) | O32: =IF(AND(TRIM($A32)="Finalized",$K32<>""),"",DATE(2026,7,26)) | P32: 90 days | Q32: OPTUM | R32: 365 days | S32: Processed date | T32: 365 days | U32: Processed date | V32: A1 | Y32: 20 | Z32: 5916.4 | AA32: 0 | AB32: 0 | AC32: 46217 | AD32: 5916.4 | AE32: 103 | AF32: G894 | AG32: M461 | AK32: OROC, RENEE | AL32: ASAP - Gilbert | AM32: 46189 | AN32: DME

Sheet GAE
A1: Claim Status | B1: Notes | C1: Processed Date | D1: Primary Claim ID | E1: Chart Number | F1: Date of Service | G1: Responsible Payer | H1: Primary Payer Name | I1: Secondary Payer Name | J1: Procedure Code | K1: Latest Date Worked | L1: Days Until Deadline | M1: Days Until Corrected Claim Deadline | N1: Days Until Appeal Deadline | O1: Filing Deadline | P1: Filing Limit | Q1: Limit Carrier | R1: Corrected Claim Limit | S1: Corrected Claim From | T1: Appeal Limit | U1: Appeal From | V1: Modifier 1 | W1: Modifier 2 | X1: Modifier 3 | Y1: Units | Z1: Charge Amount | AA1: Adjustment | AB1: Insurance Payment | AC1: Insurance Check Date | AD1: Insurance Balance | AE1: AR Age by Service Date | AF1: Diagnosis Code 1 | AG1: Diagnosis Code 2 | AH1: Diagnosis Code 3 | AI1: Diagnosis Code 4 | AJ1: Secondary Claim ID | AK1: Rendering Provider | AL1: Location Name | AM1: Created Date | AN1: Specialty
A2: Under Review | B2: DND 75710 This procedure or procedure/modifier combination is not compatible with another procedure or procedure/modifier combination provided on the same day according to the National Correct Coding Initiative or workers compensation state regulations/ fee schedule requirements - Adjusted balance for 36246 not included in the auth requested - 36248 add on requires payment for other cpt code - 99153 cant be billed on pos 24 | C2: 46165 | D2: 558554119 | E2: HF517884474 | F2: 46118 | G2: Humana Gold Plus HMO | H2: Humana Gold Plus HMO | I2: No Payer | J2: 36248+59 x1; 75710+26+XU+LT x1; 36246+59+LT x1 | L2: =IF($O2="","",$O2-TODAY()) -> -92 | M2: =IF(AND(TRIM($A2)="Finalized",$K2<>""),"",IF($F2="","",$F2+90-TODAY())) -> -92 | N2: =IF(AND(TRIM($A2)="Finalized",$K2<>""),"",IF($C2="","",$C2+540-TODAY())) -> 405 | O2: =IF(AND(TRIM($A2)="Finalized",$K2<>""),"",DATE(2026,7,5)) -> 46208 | P2: 90 days | Q2: HUMANA MA | R2: 90 days | S2: Date of service | T2: 540 days | U2: Processed date | V2: 59, 26 | W2: XU, LT | X2: LT | Y2: 1 | Z2: 7585.97 | AA2: 0 | AB2: 0 | AC2: 46165 | AD2: 7585.97 | AE2: 124 | AF2: M1712 | AG2: I798 | AH2: M25562 | AK2: HUNTER, DREW | AL2: Premier Endoscopy Center, LLC | AM2: 46149 | AN2: GAE
A3: Under Review | B3: DND 36248 due to exceeded MUE - DND 36245, 36246, and 75710 due to invalid dx | C3: 46162 | D3: 558686340 | E3: HF536642190 | F3: 46125 | G3: HealthSpring Medicare Advantage | H3: HealthSpring Medicare Advantage | I3: No Payer | J3: 75710+XU+LT x1; 36245+59 x1; 36248+59 x3; 36246+59+LT x1 | L3: =IF($O3="","",$O3-TODAY()) -> -85 | M3: =IF(AND(TRIM($A3)="Finalized",$K3<>""),"",IF($F3="","",$F3+90-TODAY())) -> -85 | N3: =IF(AND(TRIM($A3)="Finalized",$K3<>""),"",IF($C3="","",$C3+180-TODAY())) -> 42 | O3: =IF(AND(TRIM($A3)="Finalized",$K3<>""),"",DATE(2026,7,12)) -> 46215 | P3: 90 days | Q3: CIGNA / CIGNA MEDICARE | R3: 90 days | S3: Date of service | T3: 180 days | U3: Processed date | V3: XU, 59 | W3: LT | Y3: 1, 3 | Z3: 17767.19 | AA3: 0 | AB3: 0 | AC3: 46162 | AD3: 17767.19 | AE3: 117 | AF3: M1712 | AG3: I798 | AH3: M25562 | AK3: HUNTER, DREW | AL3: ASAP - DEER VALLEY | AM3: 46152 | AN3: GAE
A4: Denied | B4: Uploaded MR - PIQ-90772350 | C4: 46190 | D4: 558686302 | E4: HF456620712 | F4: 46125 | G4: United HealthCare Dual Complete | H4: United HealthCare Dual Complete | I4: UnitedHealthcare Community Plan / Arizona Long Term Care | J4: 37242 x1; 36246+59+RT x1; 36245+59 x1; 36248+59 x1; 75710+26+XU+RT x1; 75774+26+XU x3; 76937+26 x1 | K4: 46278 | L4: =IF($O4="","",$O4-TODAY()) -> 190 | M4: =IF(AND(TRIM($A4)="Finalized",$K4<>""),"",IF($C4="","",$C4+180-TODAY())) -> 70 | N4: =IF(AND(TRIM($A4)="Finalized",$K4<>""),"",IF($C4="","",$C4+365-TODAY())) -> 255 | O4: =IF(AND(TRIM($A4)="Finalized",$K4<>""),"",DATE(2027,4,13)) -> 46490 | P4: 365 days | Q4: UHC DUAL COMPLETE | R4: 180 days | S4: Processed date | T4: 365 days | U4: Processed date | V4: 59, 26 | W4: RT, XU | X4: RT | Y4: 1, 3 | Z4: 67599.91 | AA4: 0 | AB4: 0 | AC4: 46190 | AD4: 67599.91 | AE4: 117 | AF4: M1711 | AG4: I798 | AH4: M25561 | AK4: HUNTER, DREW | AL4: ASAP Surgery Centers North Valley LLC | AM4: 46152 | AN4: GAE
A5: Denied | B5: secondary - Added COB info, and resubmitted - Primary paid | C5: 46162 | D5: 558686710 | E5: HF330200116 | F5: 46132 | G5: Blue Cross Blue Shield of Arizona (BCBS AZ) | H5: Blue Cross Blue Shield of Arizona (BCBS AZ) | I5: Blue Cross Blue Shield of Arizona (BCBS AZ) | J5: 75774+26+XU x3; 36246+59+LT x1; 36245+59 x1; 36248+59 x1; 76937+26 x1; 37242 x1; 75710+26+XU+LT x1 | K5: 46278 | L5: =IF($O5="","",$O5-TODAY()) -> -78 | M5: =IF(AND(TRIM($A5)="Finalized",$K5<>""),"",IF($F5="","",$F5+90-TODAY())) -> -78 | N5: =IF(AND(TRIM($A5)="Finalized",$K5<>""),"",IF($C5="","",$C5+365-TODAY())) -> 227 | O5: =IF(AND(TRIM($A5)="Finalized",$K5<>""),"",DATE(2026,7,19)) -> 46222 | P5: 90 days | Q5: BCBS | R5: 90 days | S5: Date of service | T5: 365 days | U5: Processed date | V5: 26, 59 | W5: XU, LT | X5: LT | Y5: 3, 1 | Z5: 67599.91 | AA5: 66579.55 | AB5: 918.36 | AC5: 46162 | AD5: 102 | AE5: 110 | AF5: M1712 | AG5: I798 | AH5: M25562 | AJ5: 561534376 | AK5: HUNTER, DREW | AL5: Premier Endoscopy Center, LLC | AM5: 46152 | AN5: GAE
A6: Finalized | B6: Adjusted balance for 75710, 75774, 36245 | C6: 46162 | D6: 558686908 | E6: HF510777417 | F6: 46132 | G6: Health Choice Arizona | H6: Health Choice Arizona | I6: No Payer | J6: 75710+26+XU+RT x1; 36245+59 x1; 75774+26+XU x5 | K6: 46278 | L6: =IF($O6="","",$O6-TODAY()) | M6: =IF(AND(TRIM($A6)="Finalized",$K6<>""),"",IF($F6="","",$F6+365-TODAY())) | N6: =IF(AND(TRIM($A6)="Finalized",$K6<>""),"",IF($F6="","",$F6+365-TODAY())) | O6: =IF(AND(TRIM($A6)="Finalized",$K6<>""),"",DATE(2026,10,17)) | P6: 180 days | Q6: HEALTH CHOICE MEDICAID | R6: 365 days | S6: Date of service | T6: 365 days | U6: Date of service | V6: 26, 59 | W6: XU | X6: RT | Y6: 1, 5 | Z6: 12959.73 | AA6: 0 | AB6: 0 | AC6: 46162 | AD6: 12959.73 | AE6: 110 | AF6: M1711 | AG6: I798 | AH6: M25561 | AK6: HUNTER, DREW | AL6: Premier Endoscopy Center, LLC | AM6: 46152 | AN6: GAE
A7: PAID | B7: PENDING POSTING | C7: 46181 | D7: 558686759 | E7: HF522250673 | F7: 46132 | G7: Alignment Health Care | H7: Alignment Health Care | I7: No Payer | J7: 75710+26+XU+LT x1; 75774+26+XU x4; 36246+59+LT x1; 37242 x1; 36245+59 x1; 76937+26 x1; 36248+59 x1 | K7: 46199 | L7: =IF($O7="","",$O7-TODAY()) | Q7: Not on reference list | V7: 26, 59 | W7: XU, LT | X7: LT | Y7: 1, 4 | Z7: 68271.21 | AA7: 67367.5 | AB7: 0 | AC7: 46181 | AD7: 903.71 | AE7: 110 | AF7: M1712 | AG7: I798 | AH7: M25562 | AK7: HUNTER, DREW | AL7: Premier Endoscopy Center, LLC | AM7: 46152 | AN7: GAE

Sheet ORTHO
A1: Claim Status | B1: Notes | C1: Processed Date | D1: Primary Claim ID | E1: Chart Number | F1: Date of Service | G1: Responsible Payer | H1: Primary Payer Name | I1: Secondary Payer Name | J1: Procedure Code | K1: Latest Date Worked | L1: Days Until Deadline | M1: Days Until Corrected Claim Deadline | N1: Days Until Appeal Deadline | O1: Filing Deadline | P1: Filing Limit | Q1: Limit Carrier | R1: Corrected Claim Limit | S1: Corrected Claim From | T1: Appeal Limit | U1: Appeal From | V1: Modifier 1 | W1: Modifier 2 | X1: Modifier 3 | Y1: Units | Z1: Charge Amount | AA1: Adjustment | AB1: Insurance Payment | AC1: Insurance Check Date | AD1: Insurance Balance | AE1: AR Age by Service Date | AF1: Diagnosis Code 1 | AG1: Diagnosis Code 2 | AH1: Diagnosis Code 3 | AI1: Diagnosis Code 4 | AJ1: Secondary Claim ID | AK1: Rendering Provider | AL1: Location Name | AM1: Created Date | AN1: Specialty
A2: Under Review | B2: trying to get access to EOB with imperial | D2: 556696226 | E2: HF488600206 | F2: 46125 | G2: Imperial Insurance Companies Inc Exchange AZ (IEXAZ) (WAYSTAR ONLY) | H2: Imperial Insurance Companies Inc Exchange AZ (IEXAZ) (WAYSTAR ONLY) | I2: No Payer | J2: 63030+50 x1; 64708 x1 | L2: =IF($O2="","",$O2-TODAY()) | Q2: Not on reference list | V2: 50 | Y2: 1 | Z2: 9768.43 | AA2: 0 | AB2: 0 | AD2: 9768.43 | AE2: 117 | AF2: M48062 | AG2: M5416 | AH2: M5126 | AI2: G549 | AK2: LUKE, TIMOTHY | AL2: ASAP Surgery Centers North Valley LLC | AM2: 46133 | AN2: ORTHO
A3: Under Review | B3: no access | D3: 556723206 | E3: HF546044961 | F3: 46127 | G3: AFSAT MEDICAL PLAN | H3: AFSAT MEDICAL PLAN | I3: No Payer | J3: 63048 x1; 63047 x1 | L3: =IF($O3="","",$O3-TODAY()) | Q3: Not on reference list | Y3: 1 | Z3: 9056.39 | AA3: 0 | AB3: 0 | AD3: 9056.39 | AE3: 115 | AF3: M4807 | AG3: M5417 | AH3: M5116 | AI3: M5126 | AK3: MCCUNNIFF, PETER | AL3: ASAP Surgery Centers North Valley LLC | AM3: 46164 | AN3: ORTHO
A4: Denied | B4: Filed new authorization on zyter # OPIXSO0914152025 -Authorization OPSQQU0402203650 was approved for 63655, but only from 06/30/2026 to 07/01/2026 - DND 63655 no auth | C4: 46135 | D4: 556660363 | E4: HF541770771 | F4: 46118 | G4: Medicare Part B Arizona * | H4: Medicare Part B Arizona * | I4: Tricare for Life (All Regions) | J4: 63655 x1 | K4: 46279 | L4: =IF($O4="","",$O4-TODAY()) -> 183 | M4: =IF(AND(TRIM($A4)="Finalized",$K4<>""),"",IF($C4="","",$C4+365-TODAY())) -> 200 | N4: =IF(AND(TRIM($A4)="Finalized",$K4<>""),"",IF($C4="","",$C4+120-TODAY())) -> -45 | O4: =IF(AND(TRIM($A4)="Finalized",$K4<>""),"",DATE(2027,4,6)) -> 46483 | P4: 365 days | Q4: MEDICARE | R4: 365 days | S4: Processed date | T4: 120 days | U4: Processed date | Y4: 1 | Z4: 5784.24 | AA4: 0 | AB4: 0 | AC4: 46135 | AD4: 5784.24 | AE4: 124 | AF4: E1142 | AG4: M5450 | AK4: LUKE, TIMOTHY | AL4: ASAP Surgery Centers North Valley LLC | AM4: 46133 | AN4: ORTHO
A5: Denied | B5: Filed authorization on zyter - Details Overview - OPFOEY0914142230 - No auth request found for 63655 - DND 63655 no auth | C5: 46140 | D5: 556661876 | E5: HF331440491 | F5: 46118 | G5: Medicare Part B Arizona * | H5: Medicare Part B Arizona * | I5: Physicians Mutual Insurance Company - ENS | J5: 63655 x1 | K5: 46279 | L5: =IF($O5="","",$O5-TODAY()) -> 183 | M5: =IF(AND(TRIM($A5)="Finalized",$K5<>""),"",IF($C5="","",$C5+365-TODAY())) -> 205 | N5: =IF(AND(TRIM($A5)="Finalized",$K5<>""),"",IF($C5="","",$C5+120-TODAY())) -> -40 | O5: =IF(AND(TRIM($A5)="Finalized",$K5<>""),"",DATE(2027,4,6)) -> 46483 | P5: 365 days | Q5: MEDICARE | R5: 365 days | S5: Processed date | T5: 120 days | U5: Processed date | Y5: 1 | Z5: 5784.24 | AA5: 0 | AB5: 0 | AC5: 46140 | AD5: 5784.24 | AE5: 124 | AF5: G90523 | AG5: M961 | AK5: LUKE, TIMOTHY | AL5: ASAP Surgery Centers North Valley LLC | AM5: 46133 | AN5: ORTHO
A6: Denied | B6: Filed new authorization on zyter # OPVWYI0914150455 - Authorization OPDCEJ0408161241 was approved for 63655, but only from 04/08/2026 to 04/09/2026 - DND 63655 no auth | C6: 46136 | D6: 556715025 | E6: HF470696196 | F6: 46128 | G6: Medicare Part B Arizona * | H6: Medicare Part B Arizona * | I6: Blue Cross Blue Shield of Arizona (BCBS AZ) | J6: 63655 x1 | K6: 46279 | L6: =IF($O6="","",$O6-TODAY()) -> 193 | M6: =IF(AND(TRIM($A6)="Finalized",$K6<>""),"",IF($C6="","",$C6+365-TODAY())) -> 201 | N6: =IF(AND(TRIM($A6)="Finalized",$K6<>""),"",IF($C6="","",$C6+120-TODAY())) -> -44 | O6: =IF(AND(TRIM($A6)="Finalized",$K6<>""),"",DATE(2027,4,16)) -> 46493 | P6: 365 days | Q6: MEDICARE | R6: 365 days | S6: Processed date | T6: 120 days | U6: Processed date | Y6: 1 | Z6: 5784.24 | AA6: 0 | AB6: 0 | AC6: 46136 | AD6: 5784.24 | AE6: 114 | AF6: M961 | AK6: LUKE, TIMOTHY | AL6: ASAP Surgery Centers North Valley LLC | AM6: 46133 | AN6: ORTHO
A7: Pending | B7: secondary - Primary paid - Deanne removed RT mod, and resubmitted | C7: 46136 | D7: 556710044 | E7: HF546095290 | F7: 46132 | G7: Medicare Part B Arizona * | H7: Medicare Part B Arizona * | I7: AARP United Healthcare | J7: 63047+RT x1 | K7: 46266 | L7: =IF($O7="","",$O7-TODAY()) -> 197 | M7: =IF(AND(TRIM($A7)="Finalized",$K7<>""),"",IF($C7="","",$C7+365-TODAY())) -> 201 | N7: =IF(AND(TRIM($A7)="Finalized",$K7<>""),"",IF($C7="","",$C7+120-TODAY())) -> -44 | O7: =IF(AND(TRIM($A7)="Finalized",$K7<>""),"",DATE(2027,4,20)) -> 46497 | P7: 365 days | Q7: MEDICARE | R7: 365 days | S7: Processed date | T7: 120 days | U7: Processed date | V7: RT | Y7: 1 | Z7: 7623.07 | AA7: 0 | AB7: 0 | AC7: 46136 | AD7: 7623.07 | AE7: 110 | AF7: M48062 | AK7: BURGHER, ABRAM | AL7: ASAP Surgery Centers North Valley LLC | AM7: 46134 | AN7: ORTHO
A8: Denied | B8: MBI updated on chart, and resubmitted - DND Missing/incomplete/invalid patient identifier | C8: 46147 | D8: 557458399 | E8: HF330326072 | F8: 46135 | G8: Medicare Part B Arizona * | H8: Medicare Part B Arizona * | I8: AARP United Healthcare | J8: 63047 x1 | K8: 46278 | L8: =IF($O8="","",$O8-TODAY()) -> 200 | M8: =IF(AND(TRIM($A8)="Finalized",$K8<>""),"",IF($C8="","",$C8+365-TODAY())) -> 212 | N8: =IF(AND(TRIM($A8)="Finalized",$K8<>""),"",IF($C8="","",$C8+120-TODAY())) -> -33 | O8: =IF(AND(TRIM($A8)="Finalized",$K8<>""),"",DATE(2027,4,23)) -> 46500 | P8: 365 days | Q8: MEDICARE | R8: 365 days | S8: Processed date | T8: 120 days | U8: Processed date | Y8: 1 | Z8: 7623.07 | AA8: 0 | AB8: 0 | AC8: 46147 | AD8: 7623.07 | AE8: 107 | AF8: M4807 | AG8: M5417 | AH8: M9963 | AK8: LUKE, TIMOTHY | AL8: ASAP Surgery Centers North Valley LLC | AM8: 46140 | AN8: ORTHO
A9: Denied | B9: Uploaded MR - PIQ-90772964 | C9: 46218 | D9: 556734047 | E9: HF531362064 | F9: 46113 | G9: UnitedHealthcare Community Plan / Arizona Long Term Care | H9: UnitedHealthcare Community Plan / Arizona Long Term Care | I9: No Payer | J9: 63047 x1; 63048 x1 | K9: 46278 | L9: =IF($O9="","",$O9-TODAY()) -> -97 | M9: =IF(AND(TRIM($A9)="Finalized",$K9<>""),"",IF($C9="","",$C9+180-TODAY())) -> 98 | N9: =IF(AND(TRIM($A9)="Finalized",$K9<>""),"",IF($C9="","",$C9+365-TODAY())) -> 283 | O9: =IF(AND(TRIM($A9)="Finalized",$K9<>""),"",DATE(2026,6,30)) -> 46203 | P9: 90 days | Q9: UHC COMMUNITY | R9: 180 days | S9: Processed date | T9: 365 days | U9: Processed date | Y9: 1 | Z9: 9056.39 | AA9: 0 | AB9: 0 | AC9: 46218 | AD9: 9056.39 | AE9: 129 | AF9: M5416, M4807 | AG9: M5116, M5417 | AH9: M5126 | AK9: MCCUNNIFF, PETER | AL9: ASAP Surgery Centers North Valley LLC | AM9: 46146 | AN9: ORTHO
A10: Denied | B10: Uploaded MR - PIQ-90772754 - Delete 20936, and resubmitted | C10: 46252 | D10: 556717576 | E10: HF525461225 | F10: 46127 | G10: UHC Group Medicare Advantage | H10: UHC Group Medicare Advantage | I10: No Payer | J10: 22845+59 x1; 22853+59 x1; 22551 x1; 22853 x1 | K10: 46278 | L10: =IF($O10="","",$O10-TODAY()) -> -83 | M10: =IF(AND(TRIM($A10)="Finalized",$K10<>""),"",IF($C10="","",$C10+180-TODAY())) -> 132 | N10: =IF(AND(TRIM($A10)="Finalized",$K10<>""),"",IF($C10="","",$C10+365-TODAY())) -> 317 | O10: =IF(AND(TRIM($A10)="Finalized",$K10<>""),"",DATE(2026,7,14)) -> 46217 | P10: 90 days | Q10: UHC MA | R10: 180 days | S10: Processed date | T10: 365 days | U10: Processed date | V10: 59 | Y10: 1 | Z10: 20158.46 | AA10: 0 | AB10: 0 | AD10: 20158.46 | AE10: 115 | AF10: M4802 | AG10: M5412 | AH10: M542 | AK10: MCCUNNIFF, PETER | AL10: ASAP Surgery Centers North Valley LLC | AM10: 46197 | AN10: ORTHO
