Workbook

Sheet BH
A1: Claim Status | B1: Notes | C1: Processed Date | D1: Primary Claim ID | E1: Chart Number | F1: Date of Service | G1: Responsible Payer | H1: Primary Payer Name | I1: Secondary Payer Name | J1: Procedure Code | K1: Latest Date Worked | L1: Days Until Deadline | M1: Days Until Corrected Claim Deadline | N1: Days Until Appeal Deadline | O1: Filing Deadline | P1: Filing Limit | Q1: Limit Carrier | R1: Corrected Claim Limit | S1: Corrected Claim From | T1: Appeal Limit | U1: Appeal From | V1: Modifier 1 | W1: Modifier 2 | X1: Modifier 3 | Y1: Units | Z1: Charge Amount | AA1: Adjustment | AB1: Insurance Payment | AC1: Insurance Check Date | AD1: Insurance Balance | AE1: AR Age by Service Date | AF1: Diagnosis Code 1 | AG1: Diagnosis Code 2 | AH1: Diagnosis Code 3 | AI1: Diagnosis Code 4 | AJ1: Secondary Claim ID | AK1: Rendering Provider | AL1: Location Name | AM1: Created Date | AN1: Specialty
A2: Rejected | B2: Resubmitted again - Aisha review Adlers status on the AHCCCS portal. He is showing active ins 2012 - Rendering OON with Medicaid AHCCCS - Confirming with Bri - DOS we were working on 05/01/2026 | D2: 558010066 | E2: HF384867230 | F2: 46143 | G2: UnitedHealthcare Community Plan / Arizona Long Term Care | H2: UnitedHealthcare Community Plan / Arizona Long Term Care | I2: No Payer | J2: 99494 x1; 99492 x1 | K2: 46300 | L2: =IF($O2="","",$O2-TODAY()) -> -70 | M2: =IF(AND(TRIM($A2)="Finalized",$K2<>""),"",IF($C2="","",$C2+180-TODAY())) | N2: =IF(AND(TRIM($A2)="Finalized",$K2<>""),"",IF($C2="","",$C2+365-TODAY())) | O2: =IF(AND(TRIM($A2)="Finalized",$K2<>""),"",DATE(2026,7,30)) -> 46233 | P2: 90 days | Q2: UHC COMMUNITY | R2: 180 days | S2: Processed date | T2: 365 days | U2: Processed date | Y2: 1 | Z2: 1426.25 | AA2: 0 | AB2: 0 | AD2: 1426.25 | AE2: 99 | AF2: F1190 | AK2: ADLER, STEVEN | AL2: ASAP - DEER VALLEY | AM2: 46180 | AN2: BH
A3: Under Review | B3: I need to call PT - Aetna termed date March 31, 2026 | C3: 46195 | D3: 560450629 | E3: HF539945835 | F3: 46169 | G3: Banner Health & Aetna Health Insurance Company | H3: Banner Health & Aetna Health Insurance Company | I3: No Payer | J3: 99493 x1 | L3: =IF($O3="","",$O3-TODAY()) -> -14 | M3: =IF(AND(TRIM($A3)="Finalized",$K3<>""),"",IF($C3="","",$C3+180-TODAY())) -> 72 | N3: =IF(AND(TRIM($A3)="Finalized",$K3<>""),"",IF($C3="","",$C3+180-TODAY())) -> 72 | O3: =IF(AND(TRIM($A3)="Finalized",$K3<>""),"",DATE(2026,9,24)) -> 46289 | P3: 120 days | Q3: BANNER HEALTH & AETNA | R3: 180 days | S3: Processed date | T3: 180 days | U3: Processed date | Y3: 1 | Z3: 976.64 | AA3: 0 | AB3: 0 | AC3: 46195 | AD3: 976.64 | AE3: 73 | AF3: F4320 | AK3: O'NEIL, ROY | AL3: ASAP - DEER VALLEY | AM3: 46182 | AN3: BH
A4: Under Review | B4: Waiting for account to get activated again | D4: 558642005 | E4: HF509754338 | F4: 46150 | G4: Gold Kidney Health Plan | H4: Gold Kidney Health Plan | I4: No Payer | J4: 99492 x1 | L4: =IF($O4="","",$O4-TODAY()) | Q4: Not on reference list | Y4: 1 | Z4: 1029.98 | AA4: 0 | AB4: 0 | AD4: 1029.98 | AE4: 92 | AF4: F1190 | AK4: KALLGREN, MARK | AL4: ASAP - Gilbert | AM4: 46188 | AN4: BH
A5: Under Review | B5: Waiting for account to get activated again | D5: 560692149 | E5: HF550464457 | F5: 46171 | G5: Gold Kidney Health Plan | H5: Gold Kidney Health Plan | I5: No Payer | J5: 99492 x1 | L5: =IF($O5="","",$O5-TODAY()) | Q5: Not on reference list | Y5: 1 | Z5: 1029.98 | AA5: 0 | AB5: 0 | AD5: 1029.98 | AE5: 71 | AF5: F1190 | AK5: LEATHEM, JARRETT | AL5: ASAP - Gilbert | AM5: 46182 | AN5: BH
A6: Pending | B6: Uploaded MR - PIQ-88903761 | D6: 559331282 | E6: HF479934906 | F6: 46156 | G6: United Healthcare | H6: United Healthcare | I6: No Payer | J6: 99494 x1; 99493 x1 | K6: 46244 | L6: =IF($O6="","",$O6-TODAY()) -> -57 | M6: =IF(AND(TRIM($A6)="Finalized",$K6<>""),"",IF($C6="","",$C6+180-TODAY())) | N6: =IF(AND(TRIM($A6)="Finalized",$K6<>""),"",IF($C6="","",$C6+365-TODAY())) | O6: =IF(AND(TRIM($A6)="Finalized",$K6<>""),"",DATE(2026,8,12)) -> 46246 | P6: 90 days | Q6: UHC COMMERCIAL | R6: 180 days | S6: Processed date | T6: 365 days | U6: Processed date | Y6: 1 | Z6: 1372.91 | AA6: 0 | AB6: 0 | AD6: 1372.91 | AE6: 86 | AF6: F4312 | AK6: MEARS, CHAD | AL6: ASAP - DEER VALLEY | AM6: 46180 | AN6: BH
A7: Pending | B7: Uploaded MR - PIQ-88903858 | D7: 559334288 | E7: HF555357253 | F7: 46156 | G7: United Healthcare | H7: United Healthcare | I7: No Payer | J7: 99494 x1; 99492 x1 | K7: 46244 | L7: =IF($O7="","",$O7-TODAY()) -> -57 | M7: =IF(AND(TRIM($A7)="Finalized",$K7<>""),"",IF($C7="","",$C7+180-TODAY())) | N7: =IF(AND(TRIM($A7)="Finalized",$K7<>""),"",IF($C7="","",$C7+365-TODAY())) | O7: =IF(AND(TRIM($A7)="Finalized",$K7<>""),"",DATE(2026,8,12)) -> 46246 | P7: 90 days | Q7: UHC COMMERCIAL | R7: 180 days | S7: Processed date | T7: 365 days | U7: Processed date | Y7: 1 | Z7: 1426.25 | AA7: 0 | AB7: 0 | AD7: 1426.25 | AE7: 86 | AF7: F4320 | AK7: MEARS, CHAD | AL7: ASAP - DEER VALLEY | AM7: 46180 | AN7: BH
A8: Pending | B8: On hold - Missing MR - Uploaded MR on portal | D8: 558887755 | E8: HF475049197 | F8: 46153 | G8: Allwell - All States (Centene) | H8: Allwell - All States (Centene) | I8: Arizona Complete Health (Centene) | J8: 99493 x1 | K8: 46245 | L8: =IF($O8="","",$O8-TODAY()) -> -55 | M8: =IF(AND(TRIM($A8)="Finalized",$K8<>""),"",IF($C8="","",$C8+90-TODAY())) | N8: =IF(AND(TRIM($A8)="Finalized",$K8<>""),"",IF($C8="","",$C8+90-TODAY())) | O8: =IF(AND(TRIM($A8)="Finalized",$K8<>""),"",DATE(2026,8,14)) -> 46248 | P8: 95 days | Q8: WELLCARE BY ALLWELL | R8: 90 days | S8: Processed date | T8: 90 days | U8: Processed date | Y8: 1 | Z8: 976.64 | AA8: 0 | AB8: 0 | AD8: 976.64 | AE8: 89 | AF8: F4320 | AK8: SARKAR, AWNIK | AL8: ASAP Peoria | AM8: 46180 | AN8: BH
A9: Pending | B9: Corrected service line 1 to 99492, and resubmitted - Processed date 06/16/2026 | C9: 46189 | D9: 559931934 | E9: HF494160468 | F9: 46162 | G9: UnitedHealthcare Community Plan / Arizona Long Term Care | H9: UnitedHealthcare Community Plan / Arizona Long Term Care | I9: No Payer | J9: 99494 x1; 99494 x1 | K9: 46245 | L9: =IF($O9="","",$O9-TODAY()) -> -51 | M9: =IF(AND(TRIM($A9)="Finalized",$K9<>""),"",IF($C9="","",$C9+180-TODAY())) -> 66 | N9: =IF(AND(TRIM($A9)="Finalized",$K9<>""),"",IF($C9="","",$C9+365-TODAY())) -> 251 | O9: =IF(AND(TRIM($A9)="Finalized",$K9<>""),"",DATE(2026,8,18)) -> 46252 | P9: 90 days | Q9: UHC COMMUNITY | R9: 180 days | S9: Processed date | T9: 365 days | U9: Processed date | Y9: 1 | Z9: 792.54 | AA9: 0 | AB9: 0 | AC9: 46196 | AD9: 792.54 | AE9: 80 | AF9: F32A | AG9: F411 | AK9: O'NEIL, ROY | AL9: ASAP - DEER VALLEY | AM9: 46182 | AN9: BH
A10: Pending | B10: Corrected service line 1 - Changed to 99492, and resubmitted - Processed date 06/10/2026 | C10: 46183 | D10: 560175340 | E10: HF485806241 | F10: 46162 | G10: UnitedHealthcare Community Plan / Arizona Long Term Care | H10: UnitedHealthcare Community Plan / Arizona Long Term Care | I10: UnitedHealthcare Community Plan / Arizona Long Term Care | J10: 99494 x1 | K10: 46245 | L10: =IF($O10="","",$O10-TODAY()) -> -51 | M10: =IF(AND(TRIM($A10)="Finalized",$K10<>""),"",IF($C10="","",$C10+180-TODAY())) -> 60 | N10: =IF(AND(TRIM($A10)="Finalized",$K10<>""),"",IF($C10="","",$C10+365-TODAY())) -> 245 | O10: =IF(AND(TRIM($A10)="Finalized",$K10<>""),"",DATE(2026,8,18)) -> 46252 | P10: 90 days | Q10: UHC COMMUNITY | R10: 180 days | S10: Processed date | T10: 365 days | U10: Processed date | Y10: 1 | Z10: 396.27 | AA10: 0 | AB10: 0 | AC10: 46195 | AD10: 396.27 | AE10: 80 | AF10: F1190 | AG10: F32A | AK10: TURLEY, TODD | AL10: ASAP - DEER VALLEY | AM10: 46182 | AN10: BH
A11: Pending | B11: Uploaded MR - PIQ-88958247 | D11: 560027331 | E11: HF495815066 | F11: 46164 | G11: United Healthcare | H11: United Healthcare | I11: No Payer | J11: 99494 x1; 99492 x1 | K11: 46245 | L11: =IF($O11="","",$O11-TODAY()) -> -49 | M11: =IF(AND(TRIM($A11)="Finalized",$K11<>""),"",IF($C11="","",$C11+180-TODAY())) | N11: =IF(AND(TRIM($A11)="Finalized",$K11<>""),"",IF($C11="","",$C11+365-TODAY())) | O11: =IF(AND(TRIM($A11)="Finalized",$K11<>""),"",DATE(2026,8,20)) -> 46254 | P11: 90 days | Q11: UHC COMMERCIAL | R11: 180 days | S11: Processed date | T11: 365 days | U11: Processed date | Y11: 1 | Z11: 1426.25 | AA11: 0 | AB11: 0 | AD11: 1426.25 | AE11: 78 | AF11: F39 | AK11: MORALES, DAVID | AL11: ASAP - Gilbert | AM11: 46182 | AN11: BH
A12: Denied | B12: UHC not active on DOS - Resubmitted to Mercy Care (secondary) | C12: 46183 | D12: 560178463 | E12: HF528535429 | F12: 46164 | G12: UnitedHealthcare Community Plan / Arizona Long Term Care | H12: UnitedHealthcare Community Plan / Arizona Long Term Care | I12: Mercy Care RBHA | J12: 99493 x1; 99494 x1 | K12: 46245 | L12: =IF($O12="","",$O12-TODAY()) -> -49 | M12: =IF(AND(TRIM($A12)="Finalized",$K12<>""),"",IF($C12="","",$C12+180-TODAY())) -> 60 | N12: =IF(AND(TRIM($A12)="Finalized",$K12<>""),"",IF($C12="","",$C12+365-TODAY())) -> 245 | O12: =IF(AND(TRIM($A12)="Finalized",$K12<>""),"",DATE(2026,8,20)) -> 46254 | P12: 90 days | Q12: UHC COMMUNITY | R12: 180 days | S12: Processed date | T12: 365 days | U12: Processed date | Y12: 1 | Z12: 1372.91 | AA12: 0 | AB12: 0 | AC12: 46189 | AD12: 1372.91 | AE12: 78 | AF12: F331 | AG12: F411 | AK12: MEARS, CHAD | AL12: ASAP - DEER VALLEY | AM12: 46181 | AN12: BH
A13: Denied | B13: We have to wait for claim on DOS 02/20/2026 approval to reprocess | C13: 46191 | D13: 560664762 | E13: HF460603685 | F13: 46171 | G13: Optum Care Medical Network of Arizona, Utah, & Washington (LifePrint) | H13: Optum Care Medical Network of Arizona, Utah, & Washington (LifePrint) | I13: No Payer | J13: 99493 x1; 99494 x1 | K13: 46245 | L13: =IF($O13="","",$O13-TODAY()) -> -42 | M13: =IF(AND(TRIM($A13)="Finalized",$K13<>""),"",IF($C13="","",$C13+365-TODAY())) -> 253 | N13: =IF(AND(TRIM($A13)="Finalized",$K13<>""),"",IF($C13="","",$C13+365-TODAY())) -> 253 | O13: =IF(AND(TRIM($A13)="Finalized",$K13<>""),"",DATE(2026,8,27)) -> 46261 | P13: 90 days | Q13: OPTUM | R13: 365 days | S13: Processed date | T13: 365 days | U13: Processed date | Y13: 1 | Z13: 1372.91 | AA13: 0 | AB13: 0 | AC13: 46191 | AD13: 1372.91 | AE13: 71 | AF13: F1190 | AK13: LEATHEM, JARRETT | AL13: ASAP - Gilbert | AM13: 46182 | AN13: BH
A14: Denied | B14: MBI updated on chart, and resubmitted - MBI End Date 04/14/2026 | C14: 46190 | D14: 558264075 | E14: HF480155713 | F14: 46146 | G14: Medicare Part B Arizona * | H14: Medicare Part B Arizona * | I14: AARP United Healthcare | J14: 99494 x2; 99492 x1 | K14: 46252 | L14: =IF($O14="","",$O14-TODAY()) -> 208 | M14: =IF(AND(TRIM($A14)="Finalized",$K14<>""),"",IF($C14="","",$C14+365-TODAY())) -> 252 | N14: =IF(AND(TRIM($A14)="Finalized",$K14<>""),"",IF($C14="","",$C14+120-TODAY())) -> 7 | O14: =IF(AND(TRIM($A14)="Finalized",$K14<>""),"",DATE(2027,5,4)) -> 46511 | P14: 365 days | Q14: MEDICARE | R14: 365 days | S14: Processed date | T14: 120 days | U14: Processed date | Y14: 2, 1 | Z14: 1822.52 | AA14: 0 | AB14: 0 | AC14: 46190 | AD14: 1822.52 | AE14: 96 | AF14: F4323 | AK14: SARKAR, AWNIK | AL14: ASAP Peoria | AM14: 46182 | AN14: BH
A15: Pending | B15: PENDING POSTING - Secondary | C15: 46196 | D15: 558264882 | E15: HF552240602 | F15: 46147 | G15: Blue Cross Blue Shield of Arizona (BCBS AZ) | H15: Medicare Part B Arizona * | I15: Blue Cross Blue Shield of Arizona (BCBS AZ) | J15: 99492 x1; 99494 x1 | K15: 46227 | L15: =IF($O15="","",$O15-TODAY()) -> 209 | M15: =IF(AND(TRIM($A15)="Finalized",$K15<>""),"",IF($C15="","",$C15+365-TODAY())) -> 258 | N15: =IF(AND(TRIM($A15)="Finalized",$K15<>""),"",IF($C15="","",$C15+120-TODAY())) -> 13 | O15: =IF(AND(TRIM($A15)="Finalized",$K15<>""),"",DATE(2027,5,5)) -> 46512 | P15: 365 days | Q15: MEDICARE | R15: 365 days | S15: Processed date | T15: 120 days | U15: Processed date | Y15: 1 | Z15: 1426.25 | AA15: 1212.77 | AB15: 170.09 | AC15: 46196 | AD15: 43.39 | AE15: 95 | AF15: F4320 | AJ15: 564131166 | AK15: SARKAR, AWNIK | AL15: ASAP Peoria | AM15: 46182 | AN15: BH
A16: Pending | B16: PENDING POSTING - Secondary | C16: 46196 | D16: 559107561 | E16: HF441452642 | F16: 46155 | G16: Blue Cross Blue Shield of Arizona (BCBS AZ) | H16: Medicare Part B Arizona * | I16: Blue Cross Blue Shield of Arizona (BCBS AZ) | J16: 99494 x1; 99492 x1 | K16: 46227 | L16: =IF($O16="","",$O16-TODAY()) -> 217 | M16: =IF(AND(TRIM($A16)="Finalized",$K16<>""),"",IF($C16="","",$C16+365-TODAY())) -> 258 | N16: =IF(AND(TRIM($A16)="Finalized",$K16<>""),"",IF($C16="","",$C16+120-TODAY())) -> 13 | O16: =IF(AND(TRIM($A16)="Finalized",$K16<>""),"",DATE(2027,5,13)) -> 46520 | P16: 365 days | Q16: MEDICARE | R16: 365 days | S16: Processed date | T16: 120 days | U16: Processed date | Y16: 1 | Z16: 1426.25 | AA16: 1228.08 | AB16: 154.78 | AC16: 46196 | AD16: 43.39 | AE16: 87 | AF16: F1190 | AJ16: 564131742 | AK16: LEATHEM, JARRETT | AL16: ASAP - Gilbert | AM16: 46182 | AN16: BH
A17: Pending | B17: PENDING POSTING - Secondary | C17: 46196 | D17: 559368713 | E17: HF537014260 | F17: 46157 | G17: Blue Cross Blue Shield of Arizona (BCBS AZ) | H17: Medicare Part B Arizona * | I17: Blue Cross Blue Shield of Arizona (BCBS AZ) | J17: 99494 x1; 99492 x1 | K17: 46227 | L17: =IF($O17="","",$O17-TODAY()) -> 219 | M17: =IF(AND(TRIM($A17)="Finalized",$K17<>""),"",IF($C17="","",$C17+365-TODAY())) -> 258 | N17: =IF(AND(TRIM($A17)="Finalized",$K17<>""),"",IF($C17="","",$C17+120-TODAY())) -> 13 | O17: =IF(AND(TRIM($A17)="Finalized",$K17<>""),"",DATE(2027,5,15)) -> 46522 | P17: 365 days | Q17: MEDICARE | R17: 365 days | S17: Processed date | T17: 120 days | U17: Processed date | Y17: 1 | Z17: 1426.25 | AA17: 1228.08 | AB17: 154.78 | AC17: 46196 | AD17: 43.39 | AE17: 85 | AF17: F39 | AJ17: 564132159 | AK17: LEATHEM, JARRETT | AL17: ASAP - Gilbert | AM17: 46182 | AN17: BH
A18: Pending | B18: PENDING POSTING - Secondary | C18: 46196 | D18: 560682170 | E18: HF494117278 | F18: 46170 | G18: Blue Cross Blue Shield of Arizona (BCBS AZ) | H18: Medicare Part B Arizona * | I18: Blue Cross Blue Shield of Arizona (BCBS AZ) | J18: 99493 x1 | K18: 46227 | L18: =IF($O18="","",$O18-TODAY()) -> 232 | M18: =IF(AND(TRIM($A18)="Finalized",$K18<>""),"",IF($C18="","",$C18+365-TODAY())) -> 258 | N18: =IF(AND(TRIM($A18)="Finalized",$K18<>""),"",IF($C18="","",$C18+120-TODAY())) -> 13 | O18: =IF(AND(TRIM($A18)="Finalized",$K18<>""),"",DATE(2027,5,28)) -> 46535 | P18: 365 days | Q18: MEDICARE | R18: 365 days | S18: Processed date | T18: 120 days | U18: Processed date | Y18: 1 | Z18: 976.64 | AA18: 844.25 | AB18: 103.98 | AC18: 46196 | AD18: 28.41 | AE18: 72 | AF18: F4320 | AJ18: 564133893 | AK18: BURGHER, ABRAM | AL18: ASAP - DEER VALLEY | AM18: 46182 | AN18: BH
A19: Pending | B19: Resubmitted to AARP MedicareComplete (SecureHorizons & Oxford Network) | D19: 568553454 | E19: HF480313866 | F19: 46149 | G19: AARP MedicareComplete (SecureHorizons & Oxford Network) | H19: No Payer | I19: No Payer | J19: 99494 x1; 99492 x1 | K19: 46247 | L19: =IF($O19="","",$O19-TODAY()) -> -64 | M19: =IF(AND(TRIM($A19)="Finalized",$K19<>""),"",IF($C19="","",$C19+365-TODAY())) | N19: =IF(AND(TRIM($A19)="Finalized",$K19<>""),"",IF($C19="","",$C19+365-TODAY())) | O19: =IF(AND(TRIM($A19)="Finalized",$K19<>""),"",DATE(2026,8,5)) -> 46239 | P19: 90 days | Q19: AARP MA CHOICE / MEDICARE COMPLETE | R19: 365 days | S19: Processed date | T19: 365 days | U19: Processed date | Y19: 1 | Z19: 1426.25 | AA19: 0 | AB19: 0 | AD19: 1426.25 | AE19: 93 | AF19: F4320 | AK19: TURLEY, TODD | AL19: ASAP - DEER VALLEY | AM19: 46182 | AN19: BH
A20: Pending | B20: Requested Linda W. fax medical records to 480-499-8744 - TAT I have to send MR 08/18/2026 | C20: 46217 | D20: 559861642 | E20: HF554254508 | F20: 46161 | G20: Arizona Priority Care Plus | H20: Arizona Priority Care Plus | I20: No Payer | J20: 99494 x1; 99492 x1 | K20: 46247 | L20: =IF($O20="","",$O20-TODAY()) -> -82 | M20: =IF(AND(TRIM($A20)="Finalized",$K20<>""),"",IF($C20="","",$C20+365-TODAY())) -> 279 | N20: =IF(AND(TRIM($A20)="Finalized",$K20<>""),"",IF($C20="","",$C20+365-TODAY())) -> 279 | O20: =IF(AND(TRIM($A20)="Finalized",$K20<>""),"",DATE(2026,7,18)) -> 46221 | P20: 60 days | Q20: AZ PRIORITY CARE | R20: 365 days | S20: Processed date | T20: 365 days | U20: Processed date | Y20: 1 | Z20: 1426.25 | AA20: 0 | AB20: 0 | AC20: 46217 | AD20: 1426.25 | AE20: 81 | AF20: F4320 | AK20: SARKAR, AWNIK | AL20: ASAP Peoria | AM20: 46181 | AN20: BH
A21: Denied | B21: Resubmitted to Optum | C21: 46191 | D21: 558331839 | E21: HF548715732 | F21: 46148 | G21: Alignment Health Care | H21: Alignment Health Care | I21: No Payer | J21: 99494 x1; 99492 x1 | K21: 46252 | L21: =IF($O21="","",$O21-TODAY()) | Q21: Not on reference list | Y21: 1 | Z21: 1426.25 | AA21: 0 | AB21: 0 | AC21: 46191 | AD21: 1426.25 | AE21: 94 | AF21: F1190 | AK21: KALLGREN, MARK | AL21: ASAP - Gilbert | AM21: 46182 | AN21: BH
A22: Denied | B22: Resubmitted to Optum | C22: 46191 | D22: 559338687 | E22: HF543849258 | F22: 46157 | G22: Alignment Health Care | H22: Alignment Health Care | I22: No Payer | J22: 99492 x1; 99494 x1 | K22: 46252 | L22: =IF($O22="","",$O22-TODAY()) | Q22: Not on reference list | Y22: 1 | Z22: 1426.25 | AA22: 0 | AB22: 0 | AC22: 46191 | AD22: 1426.25 | AE22: 85 | AF22: F4320 | AK22: KRAUSE, JEFFREY | AL22: ASAP - DEER VALLEY | AM22: 46181 | AN22: BH
A23: Denied | B23: Resubmitted to Optum | C23: 46191 | D23: 560178907 | E23: HF516521878 | F23: 46164 | G23: Alignment Health Care | H23: Alignment Health Care | I23: No Payer | J23: 99494 x1; 99492 x1 | K23: 46252 | L23: =IF($O23="","",$O23-TODAY()) | Q23: Not on reference list | Y23: 1 | Z23: 1426.25 | AA23: 0 | AB23: 0 | AC23: 46191 | AD23: 1426.25 | AE23: 78 | AF23: F32A | AG23: F411 | AK23: MORALES, DAVID | AL23: ASAP - DEER VALLEY | AM23: 46182 | AN23: BH
A24: Denied | B24: Resubmitted to Optum | C24: 46191 | D24: 560590155 | E24: HF387513216 | F24: 46170 | G24: Alignment Health Care | H24: Alignment Health Care | I24: No Payer | J24: 99492 x1; 99494 x1 | K24: 46252 | L24: =IF($O24="","",$O24-TODAY()) | Q24: Not on reference list | Y24: 1 | Z24: 1426.25 | AA24: 0 | AB24: 0 | AC24: 46191 | AD24: 1426.25 | AE24: 72 | AF24: F4320 | AK24: KRAUSE, JEFFREY | AL24: ASAP - DEER VALLEY | AM24: 46182 | AN24: BH
A25: Finalized | B25: Adjusted balance - No BH documentation found for those 20+ mins | C25: 46252 | D25: 560608599 | E25: HF559365958 | F25: 46169 | G25: Aetna Legacy | H25: Aetna Legacy | I25: No Payer | J25: 99484+95 x1 | K25: 46276 | L25: =IF($O25="","",$O25-TODAY()) | M25: =IF(AND(TRIM($A25)="Finalized",$K25<>""),"",IF($C25="","",$C25+180-TODAY())) | N25: =IF(AND(TRIM($A25)="Finalized",$K25<>""),"",IF($C25="","",$C25+180-TODAY())) | O25: =IF(AND(TRIM($A25)="Finalized",$K25<>""),"",DATE(2026,9,24)) | P25: 120 days | Q25: AETNA | R25: 180 days | S25: Processed date | T25: 180 days | U25: Processed date | V25: 95 | Y25: 1 | Z25: 294.42 | AA25: 0 | AB25: 0 | AD25: 294.42 | AE25: 73 | AF25: G959 | AG25: R7989 | AH25: Z79891 | AI25: Z1331 | AK25: WILSON, JARED | AL25: ASAP - Gilbert | AM25: 46234 | AN25: BH
A26: Finalized | B26: PAID - Edited rendering and referring provider, and resubmitted | C26: 46266 | D26: 563732700 | E26: HF548056702 | F26: 46143 | G26: Medicare Part B Arizona * | H26: Medicare Part B Arizona * | I26: ChampVA - HAC | J26: 99492 x1; 99494 x1 | K26: 46276 | L26: =IF($O26="","",$O26-TODAY()) | M26: =IF(AND(TRIM($A26)="Finalized",$K26<>""),"",IF($C26="","",$C26+365-TODAY())) | N26: =IF(AND(TRIM($A26)="Finalized",$K26<>""),"",IF($C26="","",$C26+120-TODAY())) | O26: =IF(AND(TRIM($A26)="Finalized",$K26<>""),"",DATE(2027,5,1)) | P26: 365 days | Q26: MEDICARE | R26: 365 days | S26: Processed date | T26: 120 days | U26: Processed date | Y26: 1 | Z26: 1426.25 | AA26: 0 | AB26: 0 | AD26: 1426.25 | AE26: 99 | AF26: F39 | AK26: BAUGHER, TIMOTHY | AL26: ASAP - Gilbert | AM26: 46182 | AN26: BH
A27: Finalized | B27: PAID - secondary - Added COB info and crossover electronically | C27: 46196 | D27: 558645693 | E27: HF465024111 | F27: 46149 | G27: Blue Cross Blue Shield of Arizona (BCBS AZ) | H27: Medicare Part B Arizona * | I27: Blue Cross Blue Shield of Arizona (BCBS AZ) | J27: 99492 x1; 99494 x1 | K27: 46252 | L27: =IF($O27="","",$O27-TODAY()) | M27: =IF(AND(TRIM($A27)="Finalized",$K27<>""),"",IF($C27="","",$C27+365-TODAY())) | N27: =IF(AND(TRIM($A27)="Finalized",$K27<>""),"",IF($C27="","",$C27+120-TODAY())) | O27: =IF(AND(TRIM($A27)="Finalized",$K27<>""),"",DATE(2027,5,7)) | P27: 365 days | Q27: MEDICARE | R27: 365 days | S27: Processed date | T27: 120 days | U27: Processed date | Y27: 1 | Z27: 1426.25 | AA27: 1212.77 | AB27: 170.09 | AC27: 46196 | AD27: 43.39 | AE27: 93 | AF27: F4320 | AJ27: 564131691 | AK27: MEARS, CHAD | AL27: ASAP - DEER VALLEY | AM27: 46181 | AN27: BH
A28: PAID | B28: secondary - PENDING POSTING - MBI updated on chart, and resubmitted - MBI End Date 04/14/2026 | C28: 46190 | D28: 558588714 | E28: HF514978991 | F28: 46150 | G28: Medicare Part B Arizona * | H28: Medicare Part B Arizona * | I28: Bankers Life Colonial Penn Life | J28: 99493 x1; 99494 x1 | K28: 46252 | L28: =IF($O28="","",$O28-TODAY()) -> 212 | M28: =IF(AND(TRIM($A28)="Finalized",$K28<>""),"",IF($C28="","",$C28+365-TODAY())) -> 252 | N28: =IF(AND(TRIM($A28)="Finalized",$K28<>""),"",IF($C28="","",$C28+120-TODAY())) -> 7 | O28: =IF(AND(TRIM($A28)="Finalized",$K28<>""),"",DATE(2027,5,8)) -> 46515 | P28: 365 days | Q28: MEDICARE | R28: 365 days | S28: Processed date | T28: 120 days | U28: Processed date | Y28: 1 | Z28: 1372.91 | AA28: 0 | AB28: 0 | AC28: 46190 | AD28: 1372.91 | AE28: 92 | AF28: F331 | AK28: LEATHEM, JARRETT | AL28: ASAP - Gilbert | AM28: 46182 | AN28: BH
A29: Finalized | B29: secondary - adjusted balance - Termed date 04/30/2026 | C29: 46196 | D29: 558777279 | E29: HF470696196 | F29: 46150 | G29: Blue Cross Blue Shield of Arizona (BCBS AZ) | H29: Medicare Part B Arizona * | I29: Blue Cross Blue Shield of Arizona (BCBS AZ) | J29: 99493 x1; 99494 x1 | K29: 46252 | L29: =IF($O29="","",$O29-TODAY()) | M29: =IF(AND(TRIM($A29)="Finalized",$K29<>""),"",IF($C29="","",$C29+365-TODAY())) | N29: =IF(AND(TRIM($A29)="Finalized",$K29<>""),"",IF($C29="","",$C29+120-TODAY())) | O29: =IF(AND(TRIM($A29)="Finalized",$K29<>""),"",DATE(2027,5,8)) | P29: 365 days | Q29: MEDICARE | R29: 365 days | S29: Processed date | T29: 120 days | U29: Processed date | Y29: 1 | Z29: 1372.91 | AA29: 1173.9 | AB29: 158.56 | AC29: 46196 | AD29: 40.45 | AE29: 92 | AF29: F4320 | AJ29: 564131697 | AK29: SARKAR, AWNIK | AL29: ASAP - DEER VALLEY | AM29: 46182 | AN29: BH
A30: Finalized | B30: Billed to PR - Adjusted ins balance- Provider OON - Audit #: WY03MQKV - Provider inquiry | C30: 46216 | D30: 559340053 | E30: HF458717535 | F30: 46154 | G30: Blue Cross Blue Shield of Arizona (BCBS AZ) | H30: Blue Cross Blue Shield of Arizona (BCBS AZ) | I30: No Payer | J30: 99494 x1; 99492 x1 | K30: 46245 | L30: =IF($O30="","",$O30-TODAY()) | M30: =IF(AND(TRIM($A30)="Finalized",$K30<>""),"",IF($F30="","",$F30+90-TODAY())) | N30: =IF(AND(TRIM($A30)="Finalized",$K30<>""),"",IF($C30="","",$C30+365-TODAY())) | O30: =IF(AND(TRIM($A30)="Finalized",$K30<>""),"",DATE(2026,8,10)) | P30: 90 days | Q30: BCBS | R30: 90 days | S30: Date of service | T30: 365 days | U30: Processed date | Y30: 1 | Z30: 1426.25 | AA30: 0 | AB30: 0 | AC30: 46216 | AD30: 1144.3 | AE30: 88 | AF30: F4320 | AK30: SARKAR, AWNIK | AL30: ASAP Peoria | AM30: 46180 | AN30: BH
A31: Finalized | B31: PAID - Bri resubmited claim on 08/05/2026 | C31: 46253 | D31: 567670697 | E31: HF559981122 | F31: 46170 | G31: EMI Health (Educators Mutual - EMIA) | H31: EMI Health (Educators Mutual - EMIA) | I31: No Payer | J31: 99492 x1; 99494 x1 | K31: 46262 | L31: =IF($O31="","",$O31-TODAY()) | Q31: Not on reference list | Y31: 1 | Z31: 1426.25 | AA31: 0 | AB31: 0 | AD31: 1426.25 | AE31: 72 | AF31: F4320 | AK31: MEARS, CHAD | AL31: ASAP - DEER VALLEY | AM31: 46180 | AN31: BH

Sheet DME
A1: Claim Status | B1: Notes | C1: Processed Date | D1: Primary Claim ID | E1: Chart Number | F1: Date of Service | G1: Responsible Payer | H1: Primary Payer Name | I1: Secondary Payer Name | J1: Procedure Code | K1: Latest Date Worked | L1: Days Until Deadline | M1: Days Until Corrected Claim Deadline | N1: Days Until Appeal Deadline | O1: Filing Deadline | P1: Filing Limit | Q1: Limit Carrier | R1: Corrected Claim Limit | S1: Corrected Claim From | T1: Appeal Limit | U1: Appeal From | V1: Modifier 1 | W1: Modifier 2 | X1: Modifier 3 | Y1: Units | Z1: Charge Amount | AA1: Adjustment | AB1: Insurance Payment | AC1: Insurance Check Date | AD1: Insurance Balance | AE1: AR Age by Service Date | AF1: Diagnosis Code 1 | AG1: Diagnosis Code 2 | AH1: Diagnosis Code 3 | AI1: Diagnosis Code 4 | AJ1: Secondary Claim ID | AK1: Rendering Provider | AL1: Location Name | AM1: Created Date | AN1: Specialty
A2: Under Review | B2: MUE issue - CALL INS | C2: 46190 | D2: 561880706 | E2: HF551547091 | F2: 46160 | G2: Oscar Health | H2: Oscar Health | I2: No Payer | J2: A6023+A2 x40 | L2: =IF($O2="","",$O2-TODAY()) -> 37 | M2: =IF(AND(TRIM($A2)="Finalized",$K2<>""),"",IF($F2="","",$F2+180-TODAY())) -> 37 | N2: =IF(AND(TRIM($A2)="Finalized",$K2<>""),"",IF($C2="","",$C2+180-TODAY())) -> 67 | O2: =IF(AND(TRIM($A2)="Finalized",$K2<>""),"",DATE(2026,11,14)) -> 46340 | P2: 180 days | Q2: OSCAR HEALTH | R2: 180 days | S2: Date of service | T2: 180 days | U2: Processed date | V2: A2 | Y2: 40 | Z2: 72707.6 | AA2: 0 | AB2: 0 | AC2: 46190 | AD2: 72707.6 | AE2: 82 | AF2: G894 | AG2: G90523 | AK2: Van Dyke, Sandra | AL2: ASAP - Gilbert | AM2: 46183 | AN2: DME
A3: PAID | B3: Surprise Reems - PENDING POSTING | C3: 46249 | D3: 559009959 | E3: HF557330085 | F3: 46147 | G3: DME Region D | H3: DME Region D | I3: No Payer | J3: A6010+A1 x10 | L3: =IF($O3="","",$O3-TODAY()) -> 209 | M3: =IF(AND(TRIM($A3)="Finalized",$K3<>""),"",IF($C3="","",$C3+365-TODAY())) -> 311 | N3: =IF(AND(TRIM($A3)="Finalized",$K3<>""),"",IF($C3="","",$C3+120-TODAY())) -> 66 | O3: =IF(AND(TRIM($A3)="Finalized",$K3<>""),"",DATE(2027,5,5)) -> 46512 | P3: 365 days | Q3: MEDICARE | R3: 365 days | S3: Processed date | T3: 120 days | U3: Processed date | V3: A1 | Y3: 10 | Z3: 2958.2 | AA3: 0 | AB3: 88.28 | AC3: 46197 | AD3: 2869.92 | AE3: 95 | AF3: G894 | AG3: M4312 | AK3: Advanced Spine and Pain LLC DME SUR | AL3: Advanced Spine and Pain LLC DME - Surprise Reems | AM3: 46155 | AN3: DME
A4: PAID | B4: Secondary - PENDING POSTING | C4: 46202 | D4: 559008757 | E4: HF418448812 | F4: 46150 | G4: Blue Cross Blue Shield of Arizona | H4: DME Region D | I4: Blue Cross Blue Shield of Arizona | J4: L0650+KX x1 | L4: =IF($O4="","",$O4-TODAY()) -> 212 | M4: =IF(AND(TRIM($A4)="Finalized",$K4<>""),"",IF($C4="","",$C4+365-TODAY())) -> 264 | N4: =IF(AND(TRIM($A4)="Finalized",$K4<>""),"",IF($C4="","",$C4+120-TODAY())) -> 19 | O4: =IF(AND(TRIM($A4)="Finalized",$K4<>""),"",DATE(2027,5,8)) -> 46515 | P4: 365 days | Q4: MEDICARE | R4: 365 days | S4: Processed date | T4: 120 days | U4: Processed date | V4: KX | Y4: 1 | Z4: 6392.96 | AA4: 5624.17 | AB4: 612.53 | AC4: 46202 | AD4: 156.26 | AE4: 92 | AF4: M4306 | AG4: M47817 | AJ4: 564922724 | AK4: Advanced Spine and Pain LLC DME GWY | AL4: Advanced Spine and Pain LLC DME - Greenway | AM4: 46155 | AN4: DME
A5: PAID | B5: Surprise Reems - PENDING POSTING | C5: 46209 | D5: 561853521 | E5: HF342287357 | F5: 46168 | G5: DME Region D | H5: DME Region D | I5: Physicians Mutual Insurance Company - ENS | J5: A6023+A1 x10 | L5: =IF($O5="","",$O5-TODAY()) -> 230 | M5: =IF(AND(TRIM($A5)="Finalized",$K5<>""),"",IF($C5="","",$C5+365-TODAY())) -> 271 | N5: =IF(AND(TRIM($A5)="Finalized",$K5<>""),"",IF($C5="","",$C5+120-TODAY())) -> 26 | O5: =IF(AND(TRIM($A5)="Finalized",$K5<>""),"",DATE(2027,5,26)) -> 46533 | P5: 365 days | Q5: MEDICARE | R5: 365 days | S5: Processed date | T5: 120 days | U5: Processed date | V5: A1 | Y5: 10 | Z5: 18176.9 | AA5: 0 | AB5: 542.44 | AC5: 46209 | AD5: 17634.46 | AE5: 74 | AF5: G894 | AG5: M1712 | AK5: Advanced Spine and Pain LLC DME SUR | AL5: Advanced Spine and Pain LLC DME - Surprise Reems | AM5: 46183 | AN5: DME
A6: PAID | B6: Surprise Reems - PENDING POSTING | C6: 46249 | D6: 561856360 | E6: HF555483131 | F6: 46168 | G6: DME Region D | H6: DME Region D | I6: Tricare for Life (All Regions) | J6: A6010+A1 x10 | L6: =IF($O6="","",$O6-TODAY()) -> 230 | M6: =IF(AND(TRIM($A6)="Finalized",$K6<>""),"",IF($C6="","",$C6+365-TODAY())) -> 311 | N6: =IF(AND(TRIM($A6)="Finalized",$K6<>""),"",IF($C6="","",$C6+120-TODAY())) -> 66 | O6: =IF(AND(TRIM($A6)="Finalized",$K6<>""),"",DATE(2027,5,26)) -> 46533 | P6: 365 days | Q6: MEDICARE | R6: 365 days | S6: Processed date | T6: 120 days | U6: Processed date | V6: A1 | Y6: 10 | Z6: 2958.2 | AA6: 0 | AB6: 0 | AD6: 2958.2 | AE6: 74 | AF6: G894 | AG6: M48062 | AK6: Advanced Spine and Pain LLC DME SUR | AL6: Advanced Spine and Pain LLC DME - Surprise Reems | AM6: 46183 | AN6: DME
A7: Under Review | B7: Still processing - ins received claim on 07/20/2026 | D7: 559374682 | E7: HF436451045 | F7: 46143 | G7: Optum Care Medical Network of Arizona, Utah, & Washington (LifePrint) | H7: Optum Care Medical Network of Arizona, Utah, & Washington (LifePrint) | I7: No Payer | J7: A6023+A2 x20 | L7: =IF($O7="","",$O7-TODAY()) -> -70 | M7: =IF(AND(TRIM($A7)="Finalized",$K7<>""),"",IF($C7="","",$C7+365-TODAY())) | N7: =IF(AND(TRIM($A7)="Finalized",$K7<>""),"",IF($C7="","",$C7+365-TODAY())) | O7: =IF(AND(TRIM($A7)="Finalized",$K7<>""),"",DATE(2026,7,30)) -> 46233 | P7: 90 days | Q7: OPTUM | R7: 365 days | S7: Processed date | T7: 365 days | U7: Processed date | V7: A2 | Y7: 20 | Z7: 36353.8 | AA7: 0 | AB7: 0 | AD7: 36353.8 | AE7: 99 | AF7: G894 | AG7: M961 | AK7: MCCUNNIFF, PETER | AL7: ASAP Peoria | AM7: 46217 | AN7: DME
A8: Under Review | B8: I need to get the MR request letter - MR requested - Remove CPT A6219, and resubmitted | D8: 559604554 | E8: HF549730183 | F8: 46157 | G8: Optum Care Medical Network of Arizona, Utah, & Washington (LifePrint) | H8: Optum Care Medical Network of Arizona, Utah, & Washington (LifePrint) | I8: LIEN 03 | J8: A6023+A1 x20 | K8: 46244 | L8: =IF($O8="","",$O8-TODAY()) -> -56 | M8: =IF(AND(TRIM($A8)="Finalized",$K8<>""),"",IF($C8="","",$C8+365-TODAY())) | N8: =IF(AND(TRIM($A8)="Finalized",$K8<>""),"",IF($C8="","",$C8+365-TODAY())) | O8: =IF(AND(TRIM($A8)="Finalized",$K8<>""),"",DATE(2026,8,13)) -> 46247 | P8: 90 days | Q8: OPTUM | R8: 365 days | S8: Processed date | T8: 365 days | U8: Processed date | V8: A1 | Y8: 20 | Z8: 36353.8 | AA8: 0 | AB8: 0 | AD8: 36353.8 | AE8: 85 | AF8: G894 | AG8: M50022 | AH8: M50023 | AI8: M50122 | AK8: MCCUNNIFF, PETER | AL8: ASAP Peoria | AM8: 46217 | AN8: DME
A9: Denied | B9: Checking with auth team | C9: 46196 | D9: 559742691 | E9: HF543653317 | F9: 46160 | G9: Optum Care Medical Network of Arizona, Utah, & Washington (LifePrint) | H9: Optum Care Medical Network of Arizona, Utah, & Washington (LifePrint) | I9: No Payer | J9: A6010+A2 x20 | K9: 46245 | L9: =IF($O9="","",$O9-TODAY()) -> -53 | M9: =IF(AND(TRIM($A9)="Finalized",$K9<>""),"",IF($C9="","",$C9+365-TODAY())) -> 258 | N9: =IF(AND(TRIM($A9)="Finalized",$K9<>""),"",IF($C9="","",$C9+365-TODAY())) -> 258 | O9: =IF(AND(TRIM($A9)="Finalized",$K9<>""),"",DATE(2026,8,16)) -> 46250 | P9: 90 days | Q9: OPTUM | R9: 365 days | S9: Processed date | T9: 365 days | U9: Processed date | V9: A2 | Y9: 20 | Z9: 5916.4 | AA9: 0 | AB9: 0 | AC9: 46196 | AD9: 5916.4 | AE9: 82 | AF9: G894 | AK9: TONDINI, JENISE | AL9: ASAP - Goodyear | AM9: 46162 | AN9: DME
A10: Denied | B10: Removed rendering, added servicing, changed from professional to DME, and resubmitted - Denied due to missing auth - I see rendering OON - Processed date 06/12/2026 | C10: 46185 | D10: 561880042 | E10: HF545888888 | F10: 46160 | G10: Humana Gold Plus HMO | H10: Humana Gold Plus HMO | I10: No Payer | J10: A6023+A2 x40 | K10: 46245 | L10: =IF($O10="","",$O10-TODAY()) -> -53 | M10: =IF(AND(TRIM($A10)="Finalized",$K10<>""),"",IF($F10="","",$F10+90-TODAY())) -> -53 | N10: =IF(AND(TRIM($A10)="Finalized",$K10<>""),"",IF($C10="","",$C10+540-TODAY())) -> 422 | O10: =IF(AND(TRIM($A10)="Finalized",$K10<>""),"",DATE(2026,8,16)) -> 46250 | P10: 90 days | Q10: HUMANA MA | R10: 90 days | S10: Date of service | T10: 540 days | U10: Processed date | V10: A2 | Y10: 40 | Z10: 72707.6 | AA10: 0 | AB10: 0 | AC10: 46185 | AD10: 72707.6 | AE10: 82 | AF10: G894 | AG10: G90523 | AK10: Van Dyke, Sandra | AL10: ASAP - Gilbert | AM10: 46183 | AN10: DME
A11: Not found | B11: Claim not found - Resubmitted - Asked April to print | C11: 46184 | D11: 559750877 | E11: HF400854650 | F11: 46161 | G11: TRIWEST VA CCN CLAIMS | H11: TRIWEST VA CCN CLAIMS | I11: No Payer | J11: A6023+A2 x20 | K11: 46252 | L11: =IF($O11="","",$O11-TODAY()) -> -22 | M11: =IF(AND(TRIM($A11)="Finalized",$K11<>""),"",IF($C11="","",$C11+365-TODAY())) -> 246 | N11: =IF(AND(TRIM($A11)="Finalized",$K11<>""),"",IF($C11="","",$C11+90-TODAY())) -> -29 | O11: =IF(AND(TRIM($A11)="Finalized",$K11<>""),"",DATE(2026,9,16)) -> 46281 | P11: 120 days | Q11: TRIWEST | R11: 365 days | S11: Processed date | T11: 90 days | U11: Processed date | V11: A2 | Y11: 20 | Z11: 36353.8 | AA11: 0 | AB11: 0 | AC11: 46184 | AD11: 36353.8 | AE11: 81 | AF11: G894 | AG11: M961 | AK11: LUKE, TIMOTHY | AL11: ASAP Prescott Valley | AM11: 46162 | AN11: DME
A12: Denied | B12: Dropped dx M54.16, and resubmitted | C12: 46190 | D12: 561859042 | E12: HF547456904 | F12: 46168 | G12: Arizona Complete Health (Centene) | H12: Arizona Complete Health (Centene) | I12: No Payer | J12: A6023+A2 x20 | K12: 46253 | L12: =IF($O12="","",$O12-TODAY()) -> -15 | M12: =IF(AND(TRIM($A12)="Finalized",$K12<>""),"",IF($F12="","",$F12+365-TODAY())) -> 230 | N12: =IF(AND(TRIM($A12)="Finalized",$K12<>""),"",IF($F12="","",$F12+365-TODAY())) -> 230 | O12: =IF(AND(TRIM($A12)="Finalized",$K12<>""),"",DATE(2026,9,23)) -> 46288 | P12: 120 days | Q12: AZ COMPLETE | R12: 365 days | S12: Date of service | T12: 365 days | U12: Date of service | V12: A2 | Y12: 20 | Z12: 36353.8 | AA12: 0 | AB12: 0 | AC12: 46190 | AD12: 36353.8 | AE12: 74 | AF12: G894 | AG12: M961 | AH12: M5416 | AI12: M5116 | AK12: BARCOME, MARYBETH | AL12: ASAP Peoria | AM12: 46183 | AN12: DME
A13: Denied | B13: Edited mod from A2 to KX, and resubmitted | C13: 46169 | D13: 559740566 | E13: HF513154140 | F13: 46146 | G13: Mercy Care Plan (AHCCCS) - Complete Care & Long Term Care (LTC) | H13: Mercy Care Plan (AHCCCS) - Complete Care & Long Term Care (LTC) | I13: No Payer | J13: A6023+A2 x20 | K13: 46254 | L13: =IF($O13="","",$O13-TODAY()) -> 23 | M13: =IF(AND(TRIM($A13)="Finalized",$K13<>""),"",IF($F13="","",$F13+365-TODAY())) -> 208 | N13: =IF(AND(TRIM($A13)="Finalized",$K13<>""),"",IF($F13="","",$F13+365-TODAY())) -> 208 | O13: =IF(AND(TRIM($A13)="Finalized",$K13<>""),"",DATE(2026,10,31)) -> 46326 | P13: 180 days | Q13: MERCY CARE MEDICAID | R13: 365 days | S13: Date of service | T13: 365 days | U13: Date of service | V13: A2 | Y13: 20 | Z13: 36353.8 | AA13: 0 | AB13: 0 | AC13: 46169 | AD13: 36353.8 | AE13: 96 | AF13: G894 | AG13: M961 | AK13: TONDINI, JENISE | AL13: ASAP - Goodyear | AM13: 46162 | AN13: DME
A14: Denied | B14: Removed Dx M5116, and resubmitted - Dx M5116 and M5416 can't be billed together | C14: 46195 | D14: 561866854 | E14: HF526296603 | F14: 46170 | G14: Mercy Care Plan (AHCCCS) - Complete Care & Long Term Care (LTC) | H14: Mercy Care Plan (AHCCCS) - Complete Care & Long Term Care (LTC) | I14: No Payer | J14: L0650+NU x1 | K14: 46254 | L14: =IF($O14="","",$O14-TODAY()) -> 47 | M14: =IF(AND(TRIM($A14)="Finalized",$K14<>""),"",IF($F14="","",$F14+365-TODAY())) -> 232 | N14: =IF(AND(TRIM($A14)="Finalized",$K14<>""),"",IF($F14="","",$F14+365-TODAY())) -> 232 | O14: =IF(AND(TRIM($A14)="Finalized",$K14<>""),"",DATE(2026,11,24)) -> 46350 | P14: 180 days | Q14: MERCY CARE MEDICAID | R14: 365 days | S14: Date of service | T14: 365 days | U14: Date of service | V14: NU | Y14: 1 | Z14: 6392.96 | AA14: 0 | AB14: 0 | AC14: 46195 | AD14: 6392.96 | AE14: 72 | AF14: M5116 | AG14: M5416 | AH14: M461 | AK14: MORALES, DAVID | AL14: ASAP Sun City | AM14: 46183 | AN14: DME
A15: Denied | B15: Mesa - MBI updated on chart, and resubmitted - MBI End Date 04/14/2026 | C15: 46156 | D15: 559006292 | E15: HF551706140 | F15: 46147 | G15: DME Region D | H15: DME Region D | I15: Blue Cross Blue Shield of Arizona (BCBS AZ) | J15: L0457+KX x1 | K15: 46254 | L15: =IF($O15="","",$O15-TODAY()) -> 209 | M15: =IF(AND(TRIM($A15)="Finalized",$K15<>""),"",IF($C15="","",$C15+365-TODAY())) -> 218 | N15: =IF(AND(TRIM($A15)="Finalized",$K15<>""),"",IF($C15="","",$C15+120-TODAY())) -> -27 | O15: =IF(AND(TRIM($A15)="Finalized",$K15<>""),"",DATE(2027,5,5)) -> 46512 | P15: 365 days | Q15: MEDICARE | R15: 365 days | S15: Processed date | T15: 120 days | U15: Processed date | V15: KX | Y15: 1 | Z15: 5320.49 | AA15: 0 | AB15: 0 | AC15: 46156 | AD15: 5320.49 | AE15: 95 | AF15: M48061 | AK15: Advanced Spine and Pain LLC DME MSA | AL15: Advanced Spine and Pain LLC DME - Mesa | AM15: 46155 | AN15: DME
A16: Denied | B16: Gilbert - MBI updated on chart, and resubmitted - MBI End Date 04/14/2026 | C16: 46185 | D16: 561877866 | E16: HF444976688 | F16: 46150 | G16: DME Region D | H16: DME Region D | I16: Blue Cross Blue Shield of Arizona (BCBS AZ) | J16: A6023+A2 x40 | K16: 46254 | L16: =IF($O16="","",$O16-TODAY()) -> 212 | M16: =IF(AND(TRIM($A16)="Finalized",$K16<>""),"",IF($C16="","",$C16+365-TODAY())) -> 247 | N16: =IF(AND(TRIM($A16)="Finalized",$K16<>""),"",IF($C16="","",$C16+120-TODAY())) -> 2 | O16: =IF(AND(TRIM($A16)="Finalized",$K16<>""),"",DATE(2027,5,8)) -> 46515 | P16: 365 days | Q16: MEDICARE | R16: 365 days | S16: Processed date | T16: 120 days | U16: Processed date | V16: A2 | Y16: 40 | Z16: 72707.6 | AA16: 0 | AB16: 0 | AC16: 46185 | AD16: 72707.6 | AE16: 92 | AF16: G894 | AG16: M961 | AH16: G609 | AK16: Advanced Spine and Pain LLC DME GIL | AL16: Advanced Spine and Pain LLC DME - Gilbert | AM16: 46183 | AN16: DME
A17: Pending | B17: Greenway - Billed to PT - ABN signed - Void claim 569311834 request as per Medicare recoup - Home Health Scottsdale is the delegated DME vendor on DOS | C17: 46211 | D17: 559783560 | E17: HF535853050 | F17: 46156 | G17: Tricare for Life (All Regions) | H17: DME Region D | I17: Tricare for Life (All Regions) | J17: A6010+A2 x20 | K17: 46254 | L17: =IF($O17="","",$O17-TODAY()) -> 218 | M17: =IF(AND(TRIM($A17)="Finalized",$K17<>""),"",IF($C17="","",$C17+365-TODAY())) -> 273 | N17: =IF(AND(TRIM($A17)="Finalized",$K17<>""),"",IF($C17="","",$C17+120-TODAY())) -> 28 | O17: =IF(AND(TRIM($A17)="Finalized",$K17<>""),"",DATE(2027,5,14)) -> 46521 | P17: 365 days | Q17: MEDICARE | R17: 365 days | S17: Processed date | T17: 120 days | U17: Processed date | V17: A2 | Y17: 20 | Z17: 5916.4 | AA17: 0 | AB17: 176.56 | AC17: 46211 | AD17: 5739.84 | AE17: 86 | AF17: G894 | AG17: M5416 | AJ17: 562576876 | AK17: Advanced Spine and Pain LLC DME GWY | AL17: Advanced Spine and Pain LLC DME - Greenway | AM17: 46162 | AN17: DME
A18: Denied | B18: Peoria - Added the only knee dx on order encounter notes M25562, and resubmitted - Remark says 'medical necessity' because the diagnoses on the claim aren't knee diagnoses, yet this will probably denied again for missing authorzation. | C18: 46204 | D18: 563514079 | E18: HF423871454 | F18: 46170 | G18: DME Region D | H18: DME Region D | I18: ACE MEDICARE SUPPLEMENTAL | J18: L1843+KX+LT x1 | K18: 46255 | L18: =IF($O18="","",$O18-TODAY()) -> 232 | M18: =IF(AND(TRIM($A18)="Finalized",$K18<>""),"",IF($C18="","",$C18+365-TODAY())) -> 266 | N18: =IF(AND(TRIM($A18)="Finalized",$K18<>""),"",IF($C18="","",$C18+120-TODAY())) -> 21 | O18: =IF(AND(TRIM($A18)="Finalized",$K18<>""),"",DATE(2027,5,28)) -> 46535 | P18: 365 days | Q18: MEDICARE | R18: 365 days | S18: Processed date | T18: 120 days | U18: Processed date | V18: KX | W18: LT | Y18: 1 | Z18: 7030.24 | AA18: 0 | AB18: 0 | AC18: 46204 | AD18: 7030.24 | AE18: 72 | AF18: M19072 | AG18: M79672 | AH18: M2012 | AK18: Advanced Spine and Pain LLC DME PEO | AL18: Advanced Spine and Pain LLC DME - Peoria | AM18: 46199 | AN18: DME
A19: Denied | B19: Shift to PT - ABN signed - Bundled remark - Rep Mark confirmed that Integra is the delegated DME vendor for this PT - Provider OON with Devoted - Ref # CALLX8R53SRA | C19: 46162 | D19: 559115746 | E19: HF530195235 | F19: 46153 | G19: Devoted Health Plan | H19: Devoted Health Plan | I19: No Payer | J19: A6023+A1 x20 | K19: 46255 | L19: =IF($O19="","",$O19-TODAY()) -> -90 | M19: =IF(AND(TRIM($A19)="Finalized",$K19<>""),"",IF($C19="","",$C19+365-TODAY())) -> 224 | N19: =IF(AND(TRIM($A19)="Finalized",$K19<>""),"",IF($C19="","",$C19+90-TODAY())) -> -51 | O19: =IF(AND(TRIM($A19)="Finalized",$K19<>""),"",DATE(2026,7,10)) -> 46213 | P19: 60 days | Q19: DEVOTED | R19: 365 days | S19: Processed date | T19: 90 days | U19: Processed date | V19: A1 | Y19: 20 | Z19: 36353.8 | AA19: 0 | AB19: 0 | AC19: 46162 | AD19: 36353.8 | AE19: 89 | AF19: G894 | AK19: OROC, RENEE | AL19: ASAP Prescott Valley | AM19: 46155 | AN19: DME
A20: Denied | B20: Edited mod, and resubmitted | C20: 46184 | D20: 559005954 | E20: HF529780586 | F20: 46146 | G20: Blue Cross Blue Shield of Arizona (BCBS AZ) | H20: Blue Cross Blue Shield of Arizona (BCBS AZ) | I20: No Payer | J20: L1851+KX+RT x1 | K20: 46253 | L20: =IF($O20="","",$O20-TODAY()) -> -67 | M20: =IF(AND(TRIM($A20)="Finalized",$K20<>""),"",IF($F20="","",$F20+90-TODAY())) -> -67 | N20: =IF(AND(TRIM($A20)="Finalized",$K20<>""),"",IF($C20="","",$C20+365-TODAY())) -> 246 | O20: =IF(AND(TRIM($A20)="Finalized",$K20<>""),"",DATE(2026,8,2)) -> 46236 | P20: 90 days | Q20: BCBS | R20: 90 days | S20: Date of service | T20: 365 days | U20: Processed date | V20: KX | W20: RT | Y20: 1 | Z20: 4520.11 | AA20: 0 | AB20: 0 | AC20: 46184 | AD20: 4520.11 | AE20: 96 | AF20: M25561 | AK20: BARCOME, MARYBETH | AL20: ASAP Peoria | AM20: 46157 | AN20: DME
A21: Denied | B21: Edited rendering provider, and resubmitted | C21: 46224 | D21: 559736857 | E21: HF546093906 | F21: 46150 | G21: HealthSpring Medicare Advantage | H21: HealthSpring Medicare Advantage | I21: Banner University Family Care - Arizona Long Term Care System | J21: A6010+A1 x20 | K21: 46253 | L21: =IF($O21="","",$O21-TODAY()) -> -63 | M21: =IF(AND(TRIM($A21)="Finalized",$K21<>""),"",IF($F21="","",$F21+90-TODAY())) -> -63 | N21: =IF(AND(TRIM($A21)="Finalized",$K21<>""),"",IF($C21="","",$C21+180-TODAY())) -> 101 | O21: =IF(AND(TRIM($A21)="Finalized",$K21<>""),"",DATE(2026,8,6)) -> 46240 | P21: 90 days | Q21: CIGNA / CIGNA MEDICARE | R21: 90 days | S21: Date of service | T21: 180 days | U21: Processed date | V21: A1 | Y21: 20 | Z21: 5916.4 | AA21: 0 | AB21: 0 | AC21: 46224 | AD21: 5916.4 | AE21: 92 | AF21: G894 | AG21: M48062 | AK21: OROC, RENEE | AL21: ASAP - Mesa | AM21: 46162 | AN21: DME
A22: Under Review | B22: Call PT for COB update needed by ins - Rep said the patient will need to update their Coordination of Benefits (COB) information with their insurance carrier. Once the COB has been updated, the claim can be reprocessed for review and adjudication. On yearly basis patient needs to update the COB. | C22: 46203 | D22: 562420138 | E22: HF331630717 | F22: 46153 | G22: Blue Cross Blue Shield of Arizona (BCBS AZ) | H22: Blue Cross Blue Shield of Arizona (BCBS AZ) | I22: No Payer | J22: A6010+A2 x40 | K22: 46255 | L22: =IF($O22="","",$O22-TODAY()) -> -60 | M22: =IF(AND(TRIM($A22)="Finalized",$K22<>""),"",IF($F22="","",$F22+90-TODAY())) -> -60 | N22: =IF(AND(TRIM($A22)="Finalized",$K22<>""),"",IF($C22="","",$C22+365-TODAY())) -> 265 | O22: =IF(AND(TRIM($A22)="Finalized",$K22<>""),"",DATE(2026,8,9)) -> 46243 | P22: 90 days | Q22: BCBS | R22: 90 days | S22: Date of service | T22: 365 days | U22: Processed date | V22: A2 | Y22: 40 | Z22: 11832.8 | AA22: 0 | AB22: 0 | AC22: 46203 | AD22: 11832.8 | AE22: 89 | AF22: G894 | AG22: M961 | AH22: M5417 | AK22: TURLEY, TODD | AL22: ASAP - DEER VALLEY | AM22: 46189 | AN22: DME
A23: Denied | B23: Rep Keran - Charges issue under review - Call ref # REQ0679770 - on claim 553079628 | C23: 46168 | D23: 559748258 | E23: HF538908740 | F23: 46146 | G23: Alignment Health Care | H23: Alignment Health Care | I23: No Payer | J23: L0650+KX x1 | K23: 46244 | L23: =IF($O23="","",$O23-TODAY()) | Q23: Not on reference list | V23: KX | Y23: 1 | Z23: 6392.96 | AA23: 0 | AB23: 0 | AD23: 6392.96 | AE23: 96 | AF23: M5416 | AK23: O'NEIL, ROY | AL23: ASAP - Goodyear | AM23: 46162 | AN23: DME
A24: Denied | B24: Rep Keran - Charges issue under review - Call ref # REQ0679770 - on claim 553079628 | C24: 46171 | D24: 559795824 | E24: HF403746522 | F24: 46149 | G24: Alignment Health Care | H24: Alignment Health Care | I24: No Payer | J24: A6010+A1 x20 | K24: 46244 | L24: =IF($O24="","",$O24-TODAY()) | Q24: Not on reference list | V24: A1 | Y24: 20 | Z24: 5916.4 | AA24: 0 | AB24: 0 | AC24: 46171 | AD24: 5916.4 | AE24: 93 | AF24: G894 | AG24: M461 | AK24: TERRILL, STEPHANIE | AL24: ASAP - Gilbert | AM24: 46162 | AN24: DME
A25: Finalized | B25: Billed PT according to ABN charges agreed. | C25: 46183 | D25: 561237046 | E25: HF533960930 | F25: 46163 | G25: UnitedHealthcare Community Plan / Arizona Long Term Care | H25: UnitedHealthcare Community Plan / Arizona Long Term Care | I25: Molina Complete Care of Arizona (Magellan Complete Care AZ) | J25: A6010+A1 x10 | K25: 46245 | L25: =IF($O25="","",$O25-TODAY()) | M25: =IF(AND(TRIM($A25)="Finalized",$K25<>""),"",IF($C25="","",$C25+180-TODAY())) | N25: =IF(AND(TRIM($A25)="Finalized",$K25<>""),"",IF($C25="","",$C25+365-TODAY())) | O25: =IF(AND(TRIM($A25)="Finalized",$K25<>""),"",DATE(2026,8,19)) | P25: 90 days | Q25: UHC COMMUNITY | R25: 180 days | S25: Processed date | T25: 365 days | U25: Processed date | V25: A1 | Y25: 10 | Z25: 2958.2 | AA25: 0 | AB25: 0 | AC25: 46183 | AD25: 2958.2 | AE25: 79 | AF25: M5030 | AG25: M5412 | AK25: LUKE, TIMOTHY | AL25: ASAP - DEER VALLEY | AM25: 46177 | AN25: DME
A26: Finalized | B26: No auth on file - Adjusted | C26: 46194 | D26: 561851402 | E26: HF508345961 | F26: 46164 | G26: Optum Care Medical Network of Arizona, Utah, & Washington (LifePrint) | H26: Optum Care Medical Network of Arizona, Utah, & Washington (LifePrint) | I26: No Payer | J26: A6010+A1 x20 | K26: 46245 | L26: =IF($O26="","",$O26-TODAY()) | M26: =IF(AND(TRIM($A26)="Finalized",$K26<>""),"",IF($C26="","",$C26+365-TODAY())) | N26: =IF(AND(TRIM($A26)="Finalized",$K26<>""),"",IF($C26="","",$C26+365-TODAY())) | O26: =IF(AND(TRIM($A26)="Finalized",$K26<>""),"",DATE(2026,8,20)) | P26: 90 days | Q26: OPTUM | R26: 365 days | S26: Processed date | T26: 365 days | U26: Processed date | V26: A1 | Y26: 20 | Z26: 36353.8 | AA26: 0 | AB26: 0 | AC26: 46194 | AD26: 36353.8 | AE26: 78 | AF26: G894 | AG26: M461 | AK26: CURRIE, DAVID | AL26: ASAP - Gilbert | AM26: 46183 | AN26: DME
A27: Finalized | B27: Shift to PR - ABN signed - No coverage | C27: 46191 | D27: 561860576 | E27: HF537684538 | F27: 46168 | G27: United Healthcare | H27: United Healthcare | I27: No Payer | J27: A6010+A2 x10 | K27: 46248 | L27: =IF($O27="","",$O27-TODAY()) | M27: =IF(AND(TRIM($A27)="Finalized",$K27<>""),"",IF($C27="","",$C27+180-TODAY())) | N27: =IF(AND(TRIM($A27)="Finalized",$K27<>""),"",IF($C27="","",$C27+365-TODAY())) | O27: =IF(AND(TRIM($A27)="Finalized",$K27<>""),"",DATE(2026,8,24)) | P27: 90 days | Q27: UHC COMMERCIAL | R27: 180 days | S27: Processed date | T27: 365 days | U27: Processed date | V27: A2 | Y27: 10 | Z27: 2958.2 | AA27: 0 | AB27: 0 | AC27: 46191 | AD27: 2958.2 | AE27: 74 | AF27: G894 | AG27: M5416 | AH27: M1711 | AK27: ADLER, STEVEN | AL27: ASAP - Biltmore | AM27: 46183 | AN27: DME
A28: Finalized | B28: Shift to PR - ABN signed - No auth | C28: 46223 | D28: 559770046 | E28: HF533281585 | F28: 46146 | G28: Banner Medicare Advantage Prime HMO (BMAH) | H28: Banner Medicare Advantage Prime HMO (BMAH) | I28: No Payer | J28: A6010+A1 x10 | K28: 46248 | L28: =IF($O28="","",$O28-TODAY()) | N28: =IF(AND(TRIM($A28)="Finalized",$K28<>""),"",IF($C28="","",$C28+65-TODAY())) | O28: =IF(AND(TRIM($A28)="Finalized",$K28<>""),"",DATE(2026,9,1)) | P28: 120 days | Q28: BANNER MEDICARE ADVANTAGE | T28: 65 days | U28: Processed date | V28: A1 | Y28: 10 | Z28: 2958.2 | AA28: 0 | AB28: 0 | AC28: 46223 | AD28: 2958.2 | AE28: 96 | AF28: G894 | AK28: ADLER, STEVEN | AL28: ASAP - DEER VALLEY | AM28: 46162 | AN28: DME
A29: Finalized | B29: Surprise Reems - Billed to PT - ABN signed - No auth found - Auth missing denial | C29: 46247 | D29: 564572924 | E29: HF550915147 | F29: 46156 | G29: DME Region D | H29: DME Region D | I29: Aetna Life & Casualty Company | J29: L1851+KX+RT x1; L1851+KX+LT x1 | K29: 46254 | L29: =IF($O29="","",$O29-TODAY()) | M29: =IF(AND(TRIM($A29)="Finalized",$K29<>""),"",IF($C29="","",$C29+365-TODAY())) | N29: =IF(AND(TRIM($A29)="Finalized",$K29<>""),"",IF($C29="","",$C29+120-TODAY())) | O29: =IF(AND(TRIM($A29)="Finalized",$K29<>""),"",DATE(2027,5,14)) | P29: 365 days | Q29: MEDICARE | R29: 365 days | S29: Processed date | T29: 120 days | U29: Processed date | V29: KX | W29: RT, LT | Y29: 1 | Z29: 9040.22 | AA29: 0 | AB29: 0 | AD29: 9040.22 | AE29: 86 | AF29: M25561, M25562 | AG29: M1711, M1712 | AK29: Advanced Spine and Pain LLC DME SUR | AL29: Advanced Spine and Pain LLC DME - Surprise Reems | AM29: 46210 | AN29: DME
A30: Finalized | B30: Goodyear - Adjusted balance - No auth on file | C30: 46219 | D30: 559739970 | E30: HF552653702 | F30: 46160 | G30: DME Region D | H30: DME Region D | I30: No Payer | J30: L0650+KX x1 | K30: 46255 | L30: =IF($O30="","",$O30-TODAY()) | M30: =IF(AND(TRIM($A30)="Finalized",$K30<>""),"",IF($C30="","",$C30+365-TODAY())) | N30: =IF(AND(TRIM($A30)="Finalized",$K30<>""),"",IF($C30="","",$C30+120-TODAY())) | O30: =IF(AND(TRIM($A30)="Finalized",$K30<>""),"",DATE(2027,5,18)) | P30: 365 days | Q30: MEDICARE | R30: 365 days | S30: Processed date | T30: 120 days | U30: Processed date | V30: KX | Y30: 1 | Z30: 6392.96 | AA30: 0 | AB30: 0 | AC30: 46219 | AD30: 6392.96 | AE30: 82 | AF30: M5417 | AK30: Advanced Spine and Pain LLC DME GYR | AL30: Advanced Spine and Pain LLC DME - Goodyear | AM30: 46162 | AN30: DME
A31: Finalized | B31: Peoria - Adjusted balance - No auth on file | C31: 46246 | D31: 559735530 | E31: HF546470119 | F31: 46161 | G31: DME Region D | H31: DME Region D | I31: AARP United Healthcare | J31: L0650+KX x1 | K31: 46255 | L31: =IF($O31="","",$O31-TODAY()) | M31: =IF(AND(TRIM($A31)="Finalized",$K31<>""),"",IF($C31="","",$C31+365-TODAY())) | N31: =IF(AND(TRIM($A31)="Finalized",$K31<>""),"",IF($C31="","",$C31+120-TODAY())) | O31: =IF(AND(TRIM($A31)="Finalized",$K31<>""),"",DATE(2027,5,19)) | P31: 365 days | Q31: MEDICARE | R31: 365 days | S31: Processed date | T31: 120 days | U31: Processed date | V31: KX | Y31: 1 | Z31: 6392.96 | AA31: 0 | AB31: 0 | AD31: 6392.96 | AE31: 81 | AF31: M51362 | AG31: M48062 | AH31: M4120 | AK31: Advanced Spine and Pain LLC DME PEO | AL31: Advanced Spine and Pain LLC DME - Peoria | AM31: 46183 | AN31: DME
A32: Finalized | B32: PAID - Edited ordering provider, and resubmitted | C32: 46268 | D32: 561864733 | E32: HF546470119 | F32: 46171 | G32: DME Region D | H32: DME Region D | I32: AARP United Healthcare | J32: A6023+A1 x20 | K32: 46276 | L32: =IF($O32="","",$O32-TODAY()) | M32: =IF(AND(TRIM($A32)="Finalized",$K32<>""),"",IF($C32="","",$C32+365-TODAY())) | N32: =IF(AND(TRIM($A32)="Finalized",$K32<>""),"",IF($C32="","",$C32+120-TODAY())) | O32: =IF(AND(TRIM($A32)="Finalized",$K32<>""),"",DATE(2027,5,29)) | P32: 365 days | Q32: MEDICARE | R32: 365 days | S32: Processed date | T32: 120 days | U32: Processed date | V32: A1 | Y32: 20 | Z32: 36353.8 | AA32: 0 | AB32: 0 | AD32: 36353.8 | AE32: 71 | AF32: G894 | AG32: M48062 | AH32: M4316 | AI32: M4156 | AK32: Advanced Spine and Pain LLC DME PEO | AL32: Advanced Spine and Pain LLC DME - Peoria | AM32: 46183 | AN32: DME
A33: Finalized | B33: Billed to PT - ABN signed - PCP is the delegated DME vendor | C33: 46170 | D33: 559761030 | E33: HF342742988 | F33: 46143 | G33: UnitedHealthcare Community Plan / Arizona Long Term Care | H33: UnitedHealthcare Community Plan / Arizona Long Term Care | I33: No Payer | J33: A6023+A2 x20 | K33: 46253 | L33: =IF($O33="","",$O33-TODAY()) | M33: =IF(AND(TRIM($A33)="Finalized",$K33<>""),"",IF($C33="","",$C33+180-TODAY())) | N33: =IF(AND(TRIM($A33)="Finalized",$K33<>""),"",IF($C33="","",$C33+365-TODAY())) | O33: =IF(AND(TRIM($A33)="Finalized",$K33<>""),"",DATE(2026,7,30)) | P33: 90 days | Q33: UHC COMMUNITY | R33: 180 days | S33: Processed date | T33: 365 days | U33: Processed date | V33: A2 | Y33: 20 | Z33: 36353.8 | AA33: 0 | AB33: 0 | AC33: 46170 | AD33: 36353.8 | AE33: 99 | AF33: G894 | AK33: ADLER, STEVEN | AL33: ASAP - DEER VALLEY | AM33: 46162 | AN33: DME
A34: Finalized | B34: Adjusted balance - No ABN signed - PCP is the delegated DME vendor | C34: 46195 | D34: 559737254 | E34: HF550003369 | F34: 46150 | G34: UnitedHealthcare Community Plan / Arizona Long Term Care | H34: UnitedHealthcare Community Plan / Arizona Long Term Care | I34: Mercy Care Plan (AHCCCS) - Complete Care & Long Term Care (LTC) | J34: A6010+A2 x40 | K34: 46253 | L34: =IF($O34="","",$O34-TODAY()) | M34: =IF(AND(TRIM($A34)="Finalized",$K34<>""),"",IF($C34="","",$C34+180-TODAY())) | N34: =IF(AND(TRIM($A34)="Finalized",$K34<>""),"",IF($C34="","",$C34+365-TODAY())) | O34: =IF(AND(TRIM($A34)="Finalized",$K34<>""),"",DATE(2026,8,6)) | P34: 90 days | Q34: UHC COMMUNITY | R34: 180 days | S34: Processed date | T34: 365 days | U34: Processed date | V34: A2 | Y34: 40 | Z34: 11832.8 | AA34: 0 | AB34: 0 | AC34: 46195 | AD34: 11832.8 | AE34: 92 | AF34: G894 | AG34: M2011 | AH34: M2012 | AI34: M2041 | AK34: KOMINSKY, STEPHEN | AL34: ASAP Peoria | AM34: 46183 | AN34: DME
A35: Finalized | B35: Billed to PT - ABN signed - No auth found - Auth missing denial | C35: 46198 | D35: 559775347 | E35: HF399755417 | F35: 46153 | G35: Optum Care Medical Network of Arizona, Utah, & Washington (LifePrint) | H35: Optum Care Medical Network of Arizona, Utah, & Washington (LifePrint) | I35: No Payer | J35: A6010+A2 x20 | K35: 46253 | L35: =IF($O35="","",$O35-TODAY()) | M35: =IF(AND(TRIM($A35)="Finalized",$K35<>""),"",IF($C35="","",$C35+365-TODAY())) | N35: =IF(AND(TRIM($A35)="Finalized",$K35<>""),"",IF($C35="","",$C35+365-TODAY())) | O35: =IF(AND(TRIM($A35)="Finalized",$K35<>""),"",DATE(2026,8,9)) | P35: 90 days | Q35: OPTUM | R35: 365 days | S35: Processed date | T35: 365 days | U35: Processed date | V35: A2 | Y35: 20 | Z35: 5916.4 | AA35: 0 | AB35: 0 | AC35: 46198 | AD35: 5916.4 | AE35: 89 | AF35: G894 | AG35: G90523 | AK35: HOLLISTER, ALICIA | AL35: ASAP - DEER VALLEY | AM35: 46162 | AN35: DME

Sheet GAE
A1: Claim Status | B1: Notes | C1: Processed Date | D1: Primary Claim ID | E1: Chart Number | F1: Date of Service | G1: Responsible Payer | H1: Primary Payer Name | I1: Secondary Payer Name | J1: Procedure Code | K1: Latest Date Worked | L1: Days Until Deadline | M1: Days Until Corrected Claim Deadline | N1: Days Until Appeal Deadline | O1: Filing Deadline | P1: Filing Limit | Q1: Limit Carrier | R1: Corrected Claim Limit | S1: Corrected Claim From | T1: Appeal Limit | U1: Appeal From | V1: Modifier 1 | W1: Modifier 2 | X1: Modifier 3 | Y1: Units | Z1: Charge Amount | AA1: Adjustment | AB1: Insurance Payment | AC1: Insurance Check Date | AD1: Insurance Balance | AE1: AR Age by Service Date | AF1: Diagnosis Code 1 | AG1: Diagnosis Code 2 | AH1: Diagnosis Code 3 | AI1: Diagnosis Code 4 | AJ1: Secondary Claim ID | AK1: Rendering Provider | AL1: Location Name | AM1: Created Date | AN1: Specialty
A2: Under Review | B2: Waiting for account to get activated again | D2: 561650514 | E2: HF396841556 | F2: 46153 | G2: Gold Kidney Health Plan | H2: Gold Kidney Health Plan | I2: No Payer | J2: 76937+26 x1; 36248+59 x2; 36245+59 x1; 75710+26+XU+RT x1; 75774+26+XU x4; 36246+59+RT x1; 37242 x1 | L2: =IF($O2="","",$O2-TODAY()) | Q2: Not on reference list | V2: 26, 59 | W2: XU, RT | X2: RT | Y2: 1, 2, 4 | Z2: 69078.8 | AA2: 0 | AB2: 0 | AD2: 69078.8 | AE2: 89 | AF2: M1711 | AG2: I798 | AH2: M25561 | AK2: HUNTER, DREW | AL2: ASAP Surgery Centers North Valley LLC | AM2: 46182 | AN2: GAE
A3: Denied | B3: MBI typo corrected, and resubmitted | C3: 46185 | D3: 561727580 | E3: HF555898882 | F3: 46153 | G3: Medicare Part B Arizona * | H3: Medicare Part B Arizona * | I3: AARP United Healthcare | J3: 36246+59+LT x1; 37242 x1; 36245+59 x1; 76937+26 x1; 75710+26+XU+LT x1; 36248+59 x3; 75774+26+XU x5 | K3: 46255 | L3: =IF($O3="","",$O3-TODAY()) -> 215 | M3: =IF(AND(TRIM($A3)="Finalized",$K3<>""),"",IF($C3="","",$C3+365-TODAY())) -> 247 | N3: =IF(AND(TRIM($A3)="Finalized",$K3<>""),"",IF($C3="","",$C3+120-TODAY())) -> 2 | O3: =IF(AND(TRIM($A3)="Finalized",$K3<>""),"",DATE(2027,5,11)) -> 46518 | P3: 365 days | Q3: MEDICARE | R3: 365 days | S3: Processed date | T3: 120 days | U3: Processed date | V3: 59, 26 | W3: LT, XU | X3: LT | Y3: 1, 3, 5 | Z3: 70557.69 | AA3: 0 | AB3: 0 | AC3: 46185 | AD3: 70557.69 | AE3: 89 | AF3: M1712 | AG3: I798 | AH3: M25562 | AK3: HUNTER, DREW | AL3: ASAP Surgery Centers North Valley LLC | AM3: 46182 | AN3: GAE
A4: Denied | B4: Filed dispute on portal with MR | C4: 46196 | D4: 561729597 | E4: HF534608085 | F4: 46153 | G4: Humana Gold Plus HMO | H4: Humana Gold Plus HMO | I4: No Payer | J4: 36246+59+RT x1; 36245+59 x1; 75774+26+XU x5; 75710+26+XU+RT x1; 36248+59 x3 | K4: 46256 | L4: =IF($O4="","",$O4-TODAY()) -> -60 | M4: =IF(AND(TRIM($A4)="Finalized",$K4<>""),"",IF($F4="","",$F4+90-TODAY())) -> -60 | N4: =IF(AND(TRIM($A4)="Finalized",$K4<>""),"",IF($C4="","",$C4+540-TODAY())) -> 433 | O4: =IF(AND(TRIM($A4)="Finalized",$K4<>""),"",DATE(2026,8,9)) -> 46243 | P4: 90 days | Q4: HUMANA MA | R4: 90 days | S4: Date of service | T4: 540 days | U4: Processed date | V4: 59, 26 | W4: RT, XU | X4: RT | Y4: 1, 5, 3 | Z4: 21123.69 | AA4: 0 | AB4: 0 | AC4: 46196 | AD4: 21123.69 | AE4: 89 | AF4: M1711 | AG4: I798 | AH4: M25561 | AK4: HUNTER, DREW | AL4: ASAP Surgery Centers North Valley LLC | AM4: 46182 | AN4: GAE
A5: Finalized | B5: 37242 not covered by Aetna - consider experimental when dealing with knee pain | C5: 46195 | D5: 561650229 | E5: HF523293759 | F5: 46146 | G5: Banner Health & Aetna Health Insurance Company | H5: Banner Health & Aetna Health Insurance Company | I5: No Payer | J5: 36248+59 x3; 37242 x1 | K5: 46248 | L5: =IF($O5="","",$O5-TODAY()) | M5: =IF(AND(TRIM($A5)="Finalized",$K5<>""),"",IF($C5="","",$C5+180-TODAY())) | N5: =IF(AND(TRIM($A5)="Finalized",$K5<>""),"",IF($C5="","",$C5+180-TODAY())) | O5: =IF(AND(TRIM($A5)="Finalized",$K5<>""),"",DATE(2026,9,1)) | P5: 120 days | Q5: BANNER HEALTH & AETNA | R5: 180 days | S5: Processed date | T5: 180 days | U5: Processed date | V5: 59 | Y5: 3, 1 | Z5: 51585.59 | AA5: 0 | AB5: 0 | AC5: 46195 | AD5: 51585.59 | AE5: 96 | AF5: M1712 | AG5: I798 | AH5: M25562 | AK5: HUNTER, DREW | AL5: Premier Endoscopy Center, LLC | AM5: 46182 | AN5: GAE
A6: PAID | B6: secondary - PENDING POSTING | C6: 46252 | D6: 561726685 | E6: HF495874808 | F6: 46160 | G6: Aetna Legacy | H6: Medicare Part B Arizona * | I6: Aetna Legacy | J6: 75774+26+XU x5; 36246+59+LT x1; 37242 x1; 36248+59 x3; 75710+26+XU+LT x1; 36245+59 x1; 76937+26 x1 | K6: 46224 | L6: =IF($O6="","",$O6-TODAY()) -> 222 | M6: =IF(AND(TRIM($A6)="Finalized",$K6<>""),"",IF($C6="","",$C6+365-TODAY())) -> 314 | N6: =IF(AND(TRIM($A6)="Finalized",$K6<>""),"",IF($C6="","",$C6+120-TODAY())) -> 69 | O6: =IF(AND(TRIM($A6)="Finalized",$K6<>""),"",DATE(2027,5,18)) -> 46525 | P6: 365 days | Q6: MEDICARE | R6: 365 days | S6: Processed date | T6: 120 days | U6: Processed date | V6: 26, 59 | W6: XU, LT | X6: LT | Y6: 5, 1, 3 | Z6: 70557.69 | AA6: 69521.95 | AB6: 825.23 | AC6: 46197 | AD6: 210.51 | AE6: 82 | AF6: M1712 | AG6: I798 | AH6: M25562 | AJ6: 564721013 | AK6: HUNTER, DREW | AL6: Premier Endoscopy Center, LLC | AM6: 46182 | AN6: GAE
