Workbook

Sheet Read Me
A1: ALL Claims 2026-S1 - Master
A3: ="Every one of the "&COUNTA('All Claims'!$D$2:$D$2000)&" claims for 2026 S1, all specialties and all six months in one place, on the 'All Claims' tab." -> Every one of the 476 claims for 2026 S1, all specialties and all six months in one place, on the 'All Claims' tab.
A5: Row order - timely filing deadline
A6: Sorted by Days Until Deadline, most urgent first, except that Finalized claims with a Latest Date Worked are moved to the bottom (still in deadline order among themselves). A negative number means the filing window has already closed; a blank means no limit is on file. The counts below update automatically (Finalized claims with a Latest Date Worked have their deadline cells left empty and are not counted), and the row order is a snapshot - to bring it up to date, sort ascending on Days Until Deadline and then move the Finalized rows with a Latest Date Worked back to the bottom.
A7: =" 1 - Due in 5 days or less: "&COUNTIFS('All Claims'!$L$2:$L$2000,">=0",'All Claims'!$L$2:$L$2000,"<=5") -> 1 - Due in 5 days or less: 0
A8: =" 2 - Due in 6-30 days: "&COUNTIFS('All Claims'!$L$2:$L$2000,">5",'All Claims'!$L$2:$L$2000,"<=30") -> 2 - Due in 6-30 days: 5
A9: =" 3 - Due in 31+ days: "&COUNTIFS('All Claims'!$L$2:$L$2000,">30") -> 3 - Due in 31+ days: 123
A10: =" 4 - Past deadline: "&COUNTIFS('All Claims'!$L$2:$L$2000,"<0") -> 4 - Past deadline: 210
A11: =" 5 - No limit on file: "&SUMPRODUCT(('All Claims'!$D$2:$D$2000<>"")*('All Claims'!$L$2:$L$2000="")*(1-(TRIM('All Claims'!$A$2:$A$2000)="Finalized")*('All Claims'!$K$2:$K$2000<>""))) -> 5 - No limit on file: 42
A13: Filing Deadline is the date of service plus the primary payer's limit, from 'Carrier_Timely_Filing_Reference.xlsx'. Days Until Deadline is a live formula; the row order is a snapshot taken on 12 August 2026. Check Filing Limit and Limit Carrier for the figure applied - where a payer had two possible limits the shorter one was used.
A15: Four columns are live links - do not type in them
A16: Claim Status, Notes, Processed Date and Latest Date Worked (shaded pale green) are formulas. Each one looks up its claim by Primary Claim ID in the matching specialty sheet of the matching monthly workbook and returns whatever is entered there. Edit any of the four in a monthly file, save it, and this file shows the change.
A17: Typing directly into these four columns here replaces the formula and breaks the link for that row. Make every edit in the monthly workbooks.
A18: Processed Date and Latest Date Worked are shown MM/DD/YYYY, the same as every other date column. Processed Date was seeded from the date in the Notes where there was one and from the Insurance Check Date otherwise.
A19: Days Until Corrected Claim Deadline and Days Until Appeal Deadline are live formulas counted from whichever date each carrier uses - see Corrected Claim From and Appeal From. They are not links, so they recalculate here from this file's own Processed Date, which is itself linked to the monthly workbook.
A21: Refreshing
A22: Keep all seven files together in this folder and do not rename them. When you open this file, Excel asks whether to update links - choose Enable Content / Update. To refresh while it is open: Data > Queries & Connections > Edit Links > Update Values. Values are also cached, so the last known status and notes appear even if you decline the update.
A24: Linked source files
A25: [1] SPC26S1 - 01 January v3.xlsx
A26: [2] SPC26S1 - 02 February v3.xlsx
A27: [3] SPC26S1 - 03 March v3.xlsx
... A46: Any other status is left unshaded.

Sheet All Claims
A1: Claim Status | B1: Notes | C1: Processed Date | D1: Primary Claim ID | E1: Chart Number | F1: Date of Service | G1: Responsible Payer | H1: Primary Payer Name | I1: Secondary Payer Name | J1: Procedure Code | K1: Latest Date Worked | L1: Days Until Deadline | M1: Days Until Corrected Claim Deadline | N1: Days Until Appeal Deadline | O1: Filing Deadline | P1: Filing Limit | Q1: Limit Carrier | R1: Corrected Claim Limit | S1: Corrected Claim From | T1: Appeal Limit | U1: Appeal From | V1: Service Month | W1: Specialty | X1: Modifier 1 | Y1: Modifier 2 | Z1: Modifier 3 | AA1: Units | AB1: Charge Amount | AC1: Adjustment | AD1: Insurance Payment | AE1: Insurance Check Date | AF1: Insurance Balance | AG1: AR Age by Service Date | AH1: Diagnosis Code 1 | AI1: Diagnosis Code 2 | AJ1: Diagnosis Code 3 | AK1: Diagnosis Code 4 | AL1: Secondary Claim ID | AM1: Rendering Provider | AN1: Location Name | AO1: Created Date
A2: =IFERROR(IF(INDEX([1]ORTHO!$A$2:$A$10,MATCH($D2,[1]ORTHO!$D$2:$D$10,0))="","",INDEX([1]ORTHO!$A$2:$A$10,MATCH($D2,[1]ORTHO!$D$2:$D$10,0))),"") | B2: =IFERROR(IF(INDEX([1]ORTHO!$B$2:$B$10,MATCH($D2,[1]ORTHO!$D$2:$D$10,0))="","",INDEX([1]ORTHO!$B$2:$B$10,MATCH($D2,[1]ORTHO!$D$2:$D$10,0))),"") | C2: =IFERROR(IF(INDEX([1]ORTHO!$C$2:$C$10,MATCH($D2,[1]ORTHO!$D$2:$D$10,0))="","",INDEX([1]ORTHO!$C$2:$C$10,MATCH($D2,[1]ORTHO!$D$2:$D$10,0))),"") | D2: 557028860 | E2: HF527306886 | F2: 46037 | G2: Arizona Priority Care Plus | H2: Arizona Priority Care Plus | I2: No Payer | J2: 63685 x1 | K2: =IFERROR(IF(INDEX([1]ORTHO!$K$2:$K$10,MATCH($D2,[1]ORTHO!$D$2:$D$10,0))="","",INDEX([1]ORTHO!$K$2:$K$10,MATCH($D2,[1]ORTHO!$D$2:$D$10,0))),"") | L2: =IF($O2="","",$O2-TODAY()) -> -207 | M2: =IF(AND(TRIM($A2)="Finalized",$K2<>""),"",IF($C2="","",$C2+365-TODAY())) | N2: =IF(AND(TRIM($A2)="Finalized",$K2<>""),"",IF($C2="","",$C2+365-TODAY())) | O2: =IF(AND(TRIM($A2)="Finalized",$K2<>""),"",DATE(2026,3,16)) -> 46097 | P2: 60 days | Q2: AZ PRIORITY CARE | R2: 365 days | S2: Processed date | T2: 365 days | U2: Processed date | V2: 2026-01 January | W2: ORTHO | AA2: 1 | AB2: 2493.33 | AC2: 0 | AD2: 0 | AF2: 2493.33 | AG2: 205 | AH2: M961 | AI2: M5416 | AM2: KALLGREN, MARK | AN2: Premier Endoscopy Center, LLC | AO2: 46048
A3: =IFERROR(IF(INDEX([1]DME!$A$2:$A$8,MATCH($D3,[1]DME!$D$2:$D$8,0))="","",INDEX([1]DME!$A$2:$A$8,MATCH($D3,[1]DME!$D$2:$D$8,0))),"") -> Pending | B3: =IFERROR(IF(INDEX([1]DME!$B$2:$B$8,MATCH($D3,[1]DME!$D$2:$D$8,0))="","",INDEX([1]DME!$B$2:$B$8,MATCH($D3,[1]DME!$D$2:$D$8,0))),"") -> secondary - I need to crossover claim - Corrected adjustments, and resubmitted | C3: =IFERROR(IF(INDEX([1]DME!$C$2:$C$8,MATCH($D3,[1]DME!$D$2:$D$8,0))="","",INDEX([1]DME!$C$2:$C$8,MATCH($D3,[1]DME!$D$2:$D$8,0))),"") -> 46089 | D3: 546184427 | E3: HF503610126 | F3: 46027 | G3: Tricare for Life (All Regions) | H3: Humana | I3: Tricare for Life (All Regions) | J3: A6023+A2 x20 | K3: =IFERROR(IF(INDEX([1]DME!$K$2:$K$8,MATCH($D3,[1]DME!$D$2:$D$8,0))="","",INDEX([1]DME!$K$2:$K$8,MATCH($D3,[1]DME!$D$2:$D$8,0))),"") -> 46141 | L3: =IF($O3="","",$O3-TODAY()) -> -187 | M3: =IF(AND(TRIM($A3)="Finalized",$K3<>""),"",IF($F3="","",$F3+90-TODAY())) -> -187 | N3: =IF(AND(TRIM($A3)="Finalized",$K3<>""),"",IF($C3="","",$C3+60-TODAY())) -> -155 | O3: =IF(AND(TRIM($A3)="Finalized",$K3<>""),"",DATE(2026,4,5)) -> 46117 | P3: 90 days | Q3: HUMANA COMMERCIAL | R3: 90 days | S3: Date of service | T3: 60 days | U3: Processed date | V3: 2026-01 January | W3: DME | X3: A2 | AA3: 20 | AB3: 36353.8 | AC3: 33154.53 | AD3: 2833.13 | AE3: 46089 | AF3: 366.14 | AG3: 215 | AH3: G894 | AI3: G90513 | AJ3: M961 | AL3: 557644876 | AM3: MCMURDIE, TODD | AN3: ASAP - Surprise - Reems | AO3: 46036
A4: =IFERROR(IF(INDEX([1]GAE!$A$2:$A$12,MATCH($D4,[1]GAE!$D$2:$D$12,0))="","",INDEX([1]GAE!$A$2:$A$12,MATCH($D4,[1]GAE!$D$2:$D$12,0))),"") | B4: =IFERROR(IF(INDEX([1]GAE!$B$2:$B$12,MATCH($D4,[1]GAE!$D$2:$D$12,0))="","",INDEX([1]GAE!$B$2:$B$12,MATCH($D4,[1]GAE!$D$2:$D$12,0))),"") | C4: =IFERROR(IF(INDEX([1]GAE!$C$2:$C$12,MATCH($D4,[1]GAE!$D$2:$D$12,0))="","",INDEX([1]GAE!$C$2:$C$12,MATCH($D4,[1]GAE!$D$2:$D$12,0))),"") -> 46121 | D4: 548877808 | E4: HF540310616 | F4: 46027 | G4: Humana Gold Plus HMO | H4: Humana Gold Plus HMO | I4: No Payer | J4: 36246+59+RT x1; 36245+59 x1; 37242 x1; 36248+59 x3 | K4: =IFERROR(IF(INDEX([1]GAE!$K$2:$K$12,MATCH($D4,[1]GAE!$D$2:$D$12,0))="","",INDEX([1]GAE!$K$2:$K$12,MATCH($D4,[1]GAE!$D$2:$D$12,0))),"") | L4: =IF($O4="","",$O4-TODAY()) -> -187 | M4: =IF(AND(TRIM($A4)="Finalized",$K4<>""),"",IF($F4="","",$F4+90-TODAY())) -> -187 | N4: =IF(AND(TRIM($A4)="Finalized",$K4<>""),"",IF($C4="","",$C4+540-TODAY())) -> 357 | O4: =IF(AND(TRIM($A4)="Finalized",$K4<>""),"",DATE(2026,4,5)) -> 46117 | P4: 90 days | Q4: HUMANA MA | R4: 90 days | S4: Date of service | T4: 540 days | U4: Processed date | V4: 2026-01 January | W4: GAE | X4: 59 | Y4: RT | AA4: 1, 3 | AB4: 65892.82 | AC4: 0 | AD4: 0 | AE4: 46121 | AF4: 65892.82 | AG4: 215 | AH4: M1711 | AI4: I798 | AJ4: M25561 | AM4: HUNTER, DREW | AN4: ASAP Surgery Centers North Valley LLC | AO4: 46062
A5: =IFERROR(IF(INDEX([1]GAE!$A$2:$A$12,MATCH($D5,[1]GAE!$D$2:$D$12,0))="","",INDEX([1]GAE!$A$2:$A$12,MATCH($D5,[1]GAE!$D$2:$D$12,0))),"") | B5: =IFERROR(IF(INDEX([1]GAE!$B$2:$B$12,MATCH($D5,[1]GAE!$D$2:$D$12,0))="","",INDEX([1]GAE!$B$2:$B$12,MATCH($D5,[1]GAE!$D$2:$D$12,0))),"") | C5: =IFERROR(IF(INDEX([1]GAE!$C$2:$C$12,MATCH($D5,[1]GAE!$D$2:$D$12,0))="","",INDEX([1]GAE!$C$2:$C$12,MATCH($D5,[1]GAE!$D$2:$D$12,0))),"") -> 46142 | D5: 554116779 | E5: HF479029623 | F5: 46027 | G5: Humana Gold Plus HMO | H5: Humana Gold Plus HMO | I5: No Payer | J5: 36248+59 x2; 37242 x1; 36246+59+RT x1; 36245+59 x1 | K5: =IFERROR(IF(INDEX([1]GAE!$K$2:$K$12,MATCH($D5,[1]GAE!$D$2:$D$12,0))="","",INDEX([1]GAE!$K$2:$K$12,MATCH($D5,[1]GAE!$D$2:$D$12,0))),"") | L5: =IF($O5="","",$O5-TODAY()) -> -187 | M5: =IF(AND(TRIM($A5)="Finalized",$K5<>""),"",IF($F5="","",$F5+90-TODAY())) -> -187 | N5: =IF(AND(TRIM($A5)="Finalized",$K5<>""),"",IF($C5="","",$C5+540-TODAY())) -> 378 | O5: =IF(AND(TRIM($A5)="Finalized",$K5<>""),"",DATE(2026,4,5)) -> 46117 | P5: 90 days | Q5: HUMANA MA | R5: 90 days | S5: Date of service | T5: 540 days | U5: Processed date | V5: 2026-01 January | W5: GAE | X5: 59 | Y5: RT | AA5: 2, 1 | AB5: 65085.23 | AC5: 0 | AD5: 0 | AE5: 46142 | AF5: 65085.23 | AG5: 215 | AH5: M1711 | AI5: I798 | AJ5: M25561 | AM5: HUNTER, DREW | AN5: ASAP Surgery Centers North Valley LLC | AO5: 46062
A6: =IFERROR(IF(INDEX([1]BH!$A$2:$A$17,MATCH($D6,[1]BH!$D$2:$D$17,0))="","",INDEX([1]BH!$A$2:$A$17,MATCH($D6,[1]BH!$D$2:$D$17,0))),"") -> Denied | B6: =IFERROR(IF(INDEX([1]BH!$B$2:$B$17,MATCH($D6,[1]BH!$D$2:$D$17,0))="","",INDEX([1]BH!$B$2:$B$17,MATCH($D6,[1]BH!$D$2:$D$17,0))),"") -> Uploaded MR - PIQ-82135368 | C6: =IFERROR(IF(INDEX([1]BH!$C$2:$C$17,MATCH($D6,[1]BH!$D$2:$D$17,0))="","",INDEX([1]BH!$C$2:$C$17,MATCH($D6,[1]BH!$D$2:$D$17,0))),"") -> 46142 | D6: 545332485 | E6: HF532613047 | F6: 46028 | G6: United Healthcare | H6: United Healthcare | I6: No Payer | J6: 99494 x1 | K6: =IFERROR(IF(INDEX([1]BH!$K$2:$K$17,MATCH($D6,[1]BH!$D$2:$D$17,0))="","",INDEX([1]BH!$K$2:$K$17,MATCH($D6,[1]BH!$D$2:$D$17,0))),"") -> 46122 | L6: =IF($O6="","",$O6-TODAY()) -> -186 | M6: =IF(AND(TRIM($A6)="Finalized",$K6<>""),"",IF($C6="","",$C6+180-TODAY())) -> 18 | N6: =IF(AND(TRIM($A6)="Finalized",$K6<>""),"",IF($C6="","",$C6+365-TODAY())) -> 203 | O6: =IF(AND(TRIM($A6)="Finalized",$K6<>""),"",DATE(2026,4,6)) -> 46118 | P6: 90 days | Q6: UHC COMMERCIAL | R6: 180 days | S6: Processed date | T6: 365 days | U6: Processed date | V6: 2026-01 January | W6: BH | AA6: 1 | AB6: 396.27 | AC6: 0 | AD6: 0 | AE6: 46142 | AF6: 396.27 | AG6: 214 | AH6: F4320 | AM6: MEARS, CHAD | AN6: ASAP Peoria | AO6: 46057
A7: =IFERROR(IF(INDEX([1]BH!$A$2:$A$17,MATCH($D7,[1]BH!$D$2:$D$17,0))="","",INDEX([1]BH!$A$2:$A$17,MATCH($D7,[1]BH!$D$2:$D$17,0))),"") -> Denied | B7: =IFERROR(IF(INDEX([1]BH!$B$2:$B$17,MATCH($D7,[1]BH!$D$2:$D$17,0))="","",INDEX([1]BH!$B$2:$B$17,MATCH($D7,[1]BH!$D$2:$D$17,0))),"") -> Jess uploaded MR | C7: =IFERROR(IF(INDEX([1]BH!$C$2:$C$17,MATCH($D7,[1]BH!$D$2:$D$17,0))="","",INDEX([1]BH!$C$2:$C$17,MATCH($D7,[1]BH!$D$2:$D$17,0))),"") -> 46063 | D7: 545484752 | E7: HF331360774 | F7: 46029 | G7: Blue Cross Blue Shield of Arizona (BCBS AZ) | H7: Blue Cross Blue Shield of Arizona (BCBS AZ) | I7: No Payer | J7: 99494 x1; 99492 x1 | K7: =IFERROR(IF(INDEX([1]BH!$K$2:$K$17,MATCH($D7,[1]BH!$D$2:$D$17,0))="","",INDEX([1]BH!$K$2:$K$17,MATCH($D7,[1]BH!$D$2:$D$17,0))),"") | L7: =IF($O7="","",$O7-TODAY()) -> -185 | M7: =IF(AND(TRIM($A7)="Finalized",$K7<>""),"",IF($F7="","",$F7+90-TODAY())) -> -185 | N7: =IF(AND(TRIM($A7)="Finalized",$K7<>""),"",IF($C7="","",$C7+365-TODAY())) -> 124 | O7: =IF(AND(TRIM($A7)="Finalized",$K7<>""),"",DATE(2026,4,7)) -> 46119 | P7: 90 days | Q7: BCBS | R7: 90 days | S7: Date of service | T7: 365 days | U7: Processed date | V7: 2026-01 January | W7: BH | AA7: 1 | AB7: 1426.25 | AC7: 0 | AD7: 0 | AE7: 46063 | AF7: 1426.25 | AG7: 213 | AH7: F4320 | AM7: SARKAR, AWNIK | AN7: ASAP Peoria | AO7: 46057
A8: =IFERROR(IF(INDEX([1]US!$A$2:$A$8,MATCH($D8,[1]US!$D$2:$D$8,0))="","",INDEX([1]US!$A$2:$A$8,MATCH($D8,[1]US!$D$2:$D$8,0))),"") -> Received | B8: =IFERROR(IF(INDEX([1]US!$B$2:$B$8,MATCH($D8,[1]US!$D$2:$D$8,0))="","",INDEX([1]US!$B$2:$B$8,MATCH($D8,[1]US!$D$2:$D$8,0))),"") | C8: =IFERROR(IF(INDEX([1]US!$C$2:$C$8,MATCH($D8,[1]US!$D$2:$D$8,0))="","",INDEX([1]US!$C$2:$C$8,MATCH($D8,[1]US!$D$2:$D$8,0))),"") -> 46199 | D8: 555109108 | E8: HF537320032 | F8: 46030 | G8: Humana Gold Plus HMO | H8: Humana Gold Plus HMO | I8: No Payer | J8: 93925 x1 | K8: =IFERROR(IF(INDEX([1]US!$K$2:$K$8,MATCH($D8,[1]US!$D$2:$D$8,0))="","",INDEX([1]US!$K$2:$K$8,MATCH($D8,[1]US!$D$2:$D$8,0))),"") | L8: =IF($O8="","",$O8-TODAY()) -> -184 | M8: =IF(AND(TRIM($A8)="Finalized",$K8<>""),"",IF($F8="","",$F8+90-TODAY())) -> -184 | N8: =IF(AND(TRIM($A8)="Finalized",$K8<>""),"",IF($C8="","",$C8+540-TODAY())) -> 435 | O8: =IF(AND(TRIM($A8)="Finalized",$K8<>""),"",DATE(2026,4,8)) -> 46120 | P8: 90 days | Q8: HUMANA MA | R8: 90 days | S8: Date of service | T8: 540 days | U8: Processed date | V8: 2026-01 January | W8: US | AA8: 1 | AB8: 1649.2 | AC8: 1468.48 | AD8: 291.98 | AE8: 46199 | AF8: -111.26 | AG8: 212 | AH8: I739 | AM8: TURLEY, TODD | AN8: ASAP - DEER VALLEY | AO8: 46048
A9: =IFERROR(IF(INDEX([1]US!$A$2:$A$8,MATCH($D9,[1]US!$D$2:$D$8,0))="","",INDEX([1]US!$A$2:$A$8,MATCH($D9,[1]US!$D$2:$D$8,0))),"") | B9: =IFERROR(IF(INDEX([1]US!$B$2:$B$8,MATCH($D9,[1]US!$D$2:$D$8,0))="","",INDEX([1]US!$B$2:$B$8,MATCH($D9,[1]US!$D$2:$D$8,0))),"") | C9: =IFERROR(IF(INDEX([1]US!$C$2:$C$8,MATCH($D9,[1]US!$D$2:$D$8,0))="","",INDEX([1]US!$C$2:$C$8,MATCH($D9,[1]US!$D$2:$D$8,0))),"") | D9: 557356991 | E9: HF536495012 | F9: 46030 | G9: Optum Care Medical Network of Arizona, Utah, & Washington (LifePrint) | H9: Optum Care Medical Network of Arizona, Utah, & Washington (LifePrint) | I9: No Payer | J9: 93970 x1 | K9: =IFERROR(IF(INDEX([1]US!$K$2:$K$8,MATCH($D9,[1]US!$D$2:$D$8,0))="","",INDEX([1]US!$K$2:$K$8,MATCH($D9,[1]US!$D$2:$D$8,0))),"") | L9: =IF($O9="","",$O9-TODAY()) -> -184 | M9: =IF(AND(TRIM($A9)="Finalized",$K9<>""),"",IF($C9="","",$C9+365-TODAY())) | N9: =IF(AND(TRIM($A9)="Finalized",$K9<>""),"",IF($C9="","",$C9+365-TODAY())) | O9: =IF(AND(TRIM($A9)="Finalized",$K9<>""),"",DATE(2026,4,8)) -> 46120 | P9: 90 days | Q9: OPTUM | R9: 365 days | S9: Processed date | T9: 365 days | U9: Processed date | V9: 2026-01 January | W9: US | AA9: 1 | AB9: 1294.23 | AC9: 0 | AD9: 0 | AF9: 1294.23 | AG9: 212 | AH9: R600 | AI9: M79605 | AJ9: M79604 | AM9: TURLEY, TODD | AN9: ASAP - DEER VALLEY | AO9: 46048
A10: =IFERROR(IF(INDEX([1]BH!$A$2:$A$17,MATCH($D10,[1]BH!$D$2:$D$17,0))="","",INDEX([1]BH!$A$2:$A$17,MATCH($D10,[1]BH!$D$2:$D$17,0))),"") -> Denied | B10: =IFERROR(IF(INDEX([1]BH!$B$2:$B$17,MATCH($D10,[1]BH!$D$2:$D$17,0))="","",INDEX([1]BH!$B$2:$B$17,MATCH($D10,[1]BH!$D$2:$D$17,0))),"") -> Jess uploaded MR | C10: =IFERROR(IF(INDEX([1]BH!$C$2:$C$17,MATCH($D10,[1]BH!$D$2:$D$17,0))="","",INDEX([1]BH!$C$2:$C$17,MATCH($D10,[1]BH!$D$2:$D$17,0))),"") -> 46141 | D10: 545748574 | E10: HF537684538 | F10: 46031 | G10: United Healthcare | H10: United Healthcare | I10: No Payer | J10: 99494 x1; 99492 x1 | K10: =IFERROR(IF(INDEX([1]BH!$K$2:$K$17,MATCH($D10,[1]BH!$D$2:$D$17,0))="","",INDEX([1]BH!$K$2:$K$17,MATCH($D10,[1]BH!$D$2:$D$17,0))),"") | L10: =IF($O10="","",$O10-TODAY()) -> -183 | M10: =IF(AND(TRIM($A10)="Finalized",$K10<>""),"",IF($C10="","",$C10+180-TODAY())) -> 17 | N10: =IF(AND(TRIM($A10)="Finalized",$K10<>""),"",IF($C10="","",$C10+365-TODAY())) -> 202 | O10: =IF(AND(TRIM($A10)="Finalized",$K10<>""),"",DATE(2026,4,9)) -> 46121 | P10: 90 days | Q10: UHC COMMERCIAL | R10: 180 days | S10: Processed date | T10: 365 days | U10: Processed date | V10: 2026-01 January | W10: BH | AA10: 1 | AB10: 1426.25 | AC10: 0 | AD10: 0 | AE10: 46141 | AF10: 1426.25 | AG10: 211 | AH10: F4320 | AM10: TURLEY, TODD | AN10: ASAP Peoria | AO10: 46057
A11: =IFERROR(IF(INDEX([1]ORTHO!$A$2:$A$10,MATCH($D11,[1]ORTHO!$D$2:$D$10,0))="","",INDEX([1]ORTHO!$A$2:$A$10,MATCH($D11,[1]ORTHO!$D$2:$D$10,0))),"") -> Received | B11: =IFERROR(IF(INDEX([1]ORTHO!$B$2:$B$10,MATCH($D11,[1]ORTHO!$D$2:$D$10,0))="","",INDEX([1]ORTHO!$B$2:$B$10,MATCH($D11,[1]ORTHO!$D$2:$D$10,0))),"") | C11: =IFERROR(IF(INDEX([1]ORTHO!$C$2:$C$10,MATCH($D11,[1]ORTHO!$D$2:$D$10,0))="","",INDEX([1]ORTHO!$C$2:$C$10,MATCH($D11,[1]ORTHO!$D$2:$D$10,0))),"") -> 46112 | D11: 545934422 | E11: HF533641085 | F11: 46031 | G11: CIGNA | H11: CIGNA | I11: No Payer | J11: 63047 x1 | K11: =IFERROR(IF(INDEX([1]ORTHO!$K$2:$K$10,MATCH($D11,[1]ORTHO!$D$2:$D$10,0))="","",INDEX([1]ORTHO!$K$2:$K$10,MATCH($D11,[1]ORTHO!$D$2:$D$10,0))),"") | L11: =IF($O11="","",$O11-TODAY()) -> -183 | M11: =IF(AND(TRIM($A11)="Finalized",$K11<>""),"",IF($F11="","",$F11+90-TODAY())) -> -183 | N11: =IF(AND(TRIM($A11)="Finalized",$K11<>""),"",IF($C11="","",$C11+180-TODAY())) -> -12 | O11: =IF(AND(TRIM($A11)="Finalized",$K11<>""),"",DATE(2026,4,9)) -> 46121 | P11: 90 days | Q11: CIGNA / CIGNA MEDICARE | R11: 90 days | S11: Date of service | T11: 180 days | U11: Processed date | V11: 2026-01 January | W11: ORTHO | AA11: 1 | AB11: 7623.07 | AC11: 0 | AD11: 0 | AE11: 46112 | AF11: 7623.07 | AG11: 211 | AH11: M48062 | AM11: O'NEIL, ROY | AN11: ASAP Surgery Centers North Valley LLC | AO11: 46037
A12: =IFERROR(IF(INDEX([1]ORTHO!$A$2:$A$10,MATCH($D12,[1]ORTHO!$D$2:$D$10,0))="","",INDEX([1]ORTHO!$A$2:$A$10,MATCH($D12,[1]ORTHO!$D$2:$D$10,0))),"") -> Finalized | B12: =IFERROR(IF(INDEX([1]ORTHO!$B$2:$B$10,MATCH($D12,[1]ORTHO!$D$2:$D$10,0))="","",INDEX([1]ORTHO!$B$2:$B$10,MATCH($D12,[1]ORTHO!$D$2:$D$10,0))),"") | C12: =IFERROR(IF(INDEX([1]ORTHO!$C$2:$C$10,MATCH($D12,[1]ORTHO!$D$2:$D$10,0))="","",INDEX([1]ORTHO!$C$2:$C$10,MATCH($D12,[1]ORTHO!$D$2:$D$10,0))),"") -> 46156 | D12: 545934840 | E12: HF456567442 | F12: 46031 | G12: UnitedHealthcare Community Plan / Arizona Long Term Care | H12: United Healthcare | I12: UnitedHealthcare Community Plan / Arizona Long Term Care | J12: 63685 x1 | K12: =IFERROR(IF(INDEX([1]ORTHO!$K$2:$K$10,MATCH($D12,[1]ORTHO!$D$2:$D$10,0))="","",INDEX([1]ORTHO!$K$2:$K$10,MATCH($D12,[1]ORTHO!$D$2:$D$10,0))),"") | L12: =IF($O12="","",$O12-TODAY()) -> -183 | M12: =IF(AND(TRIM($A12)="Finalized",$K12<>""),"",IF($C12="","",$C12+180-TODAY())) -> 32 | N12: =IF(AND(TRIM($A12)="Finalized",$K12<>""),"",IF($C12="","",$C12+365-TODAY())) -> 217 | O12: =IF(AND(TRIM($A12)="Finalized",$K12<>""),"",DATE(2026,4,9)) -> 46121 | P12: 90 days | Q12: UHC COMMERCIAL | R12: 180 days | S12: Processed date | T12: 365 days | U12: Processed date | V12: 2026-01 January | W12: ORTHO | AA12: 1 | AB12: 2493.33 | AC12: 2322.61 | AD12: 18.5 | AE12: 46156 | AF12: 152.22 | AG12: 211 | AH12: G90523 | AL12: 556916920 | AM12: O'NEIL, ROY | AN12: ASAP Surgery Centers North Valley LLC | AO12: 46037
A13: =IFERROR(IF(INDEX([1]ORTHO!$A$2:$A$10,MATCH($D13,[1]ORTHO!$D$2:$D$10,0))="","",INDEX([1]ORTHO!$A$2:$A$10,MATCH($D13,[1]ORTHO!$D$2:$D$10,0))),"") | B13: =IFERROR(IF(INDEX([1]ORTHO!$B$2:$B$10,MATCH($D13,[1]ORTHO!$D$2:$D$10,0))="","",INDEX([1]ORTHO!$B$2:$B$10,MATCH($D13,[1]ORTHO!$D$2:$D$10,0))),"") | C13: =IFERROR(IF(INDEX([1]ORTHO!$C$2:$C$10,MATCH($D13,[1]ORTHO!$D$2:$D$10,0))="","",INDEX([1]ORTHO!$C$2:$C$10,MATCH($D13,[1]ORTHO!$D$2:$D$10,0))),"") -> 46045 | D13: 546049607 | E13: HF491900072 | F13: 46035 | G13: UnitedHealthcare Community Plan / Arizona Long Term Care | H13: UnitedHealthcare Community Plan / Arizona Long Term Care | I13: No Payer | J13: 63047+LT x1 | K13: =IFERROR(IF(INDEX([1]ORTHO!$K$2:$K$10,MATCH($D13,[1]ORTHO!$D$2:$D$10,0))="","",INDEX([1]ORTHO!$K$2:$K$10,MATCH($D13,[1]ORTHO!$D$2:$D$10,0))),"") | L13: =IF($O13="","",$O13-TODAY()) -> -179 | M13: =IF(AND(TRIM($A13)="Finalized",$K13<>""),"",IF($C13="","",$C13+180-TODAY())) -> -79 | N13: =IF(AND(TRIM($A13)="Finalized",$K13<>""),"",IF($C13="","",$C13+365-TODAY())) -> 106 | O13: =IF(AND(TRIM($A13)="Finalized",$K13<>""),"",DATE(2026,4,13)) -> 46125 | P13: 90 days | Q13: UHC COMMUNITY | R13: 180 days | S13: Processed date | T13: 365 days | U13: Processed date | V13: 2026-01 January | W13: ORTHO | X13: LT | AA13: 1 | AB13: 7623.07 | AC13: 0 | AD13: 0 | AE13: 46045 | AF13: 7623.07 | AG13: 207 | AH13: M48062 | AM13: KRAUSE, JEFFREY | AN13: ASAP Surgery Centers North Valley LLC | AO13: 46037
A14: =IFERROR(IF(INDEX([1]US!$A$2:$A$8,MATCH($D14,[1]US!$D$2:$D$8,0))="","",INDEX([1]US!$A$2:$A$8,MATCH($D14,[1]US!$D$2:$D$8,0))),"") -> Received | B14: =IFERROR(IF(INDEX([1]US!$B$2:$B$8,MATCH($D14,[1]US!$D$2:$D$8,0))="","",INDEX([1]US!$B$2:$B$8,MATCH($D14,[1]US!$D$2:$D$8,0))),"") | C14: =IFERROR(IF(INDEX([1]US!$C$2:$C$8,MATCH($D14,[1]US!$D$2:$D$8,0))="","",INDEX([1]US!$C$2:$C$8,MATCH($D14,[1]US!$D$2:$D$8,0))),"") -> 46069 | D14: 548717876 | E14: HF442148430 | F14: 46035 | G14: Cigna Medicare Advantage | H14: Cigna Medicare Advantage | I14: No Payer | J14: 93925 x1 | K14: =IFERROR(IF(INDEX([1]US!$K$2:$K$8,MATCH($D14,[1]US!$D$2:$D$8,0))="","",INDEX([1]US!$K$2:$K$8,MATCH($D14,[1]US!$D$2:$D$8,0))),"") | L14: =IF($O14="","",$O14-TODAY()) -> -179 | M14: =IF(AND(TRIM($A14)="Finalized",$K14<>""),"",IF($F14="","",$F14+90-TODAY())) -> -179 | N14: =IF(AND(TRIM($A14)="Finalized",$K14<>""),"",IF($C14="","",$C14+180-TODAY())) -> -55 | O14: =IF(AND(TRIM($A14)="Finalized",$K14<>""),"",DATE(2026,4,13)) -> 46125 | P14: 90 days | Q14: CIGNA / CIGNA MEDICARE | R14: 90 days | S14: Date of service | T14: 180 days | U14: Processed date | V14: 2026-01 January | W14: US | AA14: 1 | AB14: 1649.2 | AC14: 1478.03 | AD14: 390.24 | AE14: 46069 | AF14: -219.07 | AG14: 207 | AH14: I739 | AM14: LEATHEM, JARRETT | AN14: ASAP - Gilbert | AO14: 46051
A15: =IFERROR(IF(INDEX([1]BH!$A$2:$A$17,MATCH($D15,[1]BH!$D$2:$D$17,0))="","",INDEX([1]BH!$A$2:$A$17,MATCH($D15,[1]BH!$D$2:$D$17,0))),"") -> Denied | B15: =IFERROR(IF(INDEX([1]BH!$B$2:$B$17,MATCH($D15,[1]BH!$D$2:$D$17,0))="","",INDEX([1]BH!$B$2:$B$17,MATCH($D15,[1]BH!$D$2:$D$17,0))),"") -> Added Date of Current Illness, claim note, and resubmitted | C15: =IFERROR(IF(INDEX([1]BH!$C$2:$C$17,MATCH($D15,[1]BH!$D$2:$D$17,0))="","",INDEX([1]BH!$C$2:$C$17,MATCH($D15,[1]BH!$D$2:$D$17,0))),"") -> 46133 | D15: 556348109 | E15: HF434792716 | F15: 46036 | G15: Optum Care Medical Network of Arizona, Utah, & Washington (LifePrint) | H15: Optum Care Medical Network of Arizona, Utah, & Washington (LifePrint) | I15: No Payer | J15: 99493 x1 | K15: =IFERROR(IF(INDEX([1]BH!$K$2:$K$17,MATCH($D15,[1]BH!$D$2:$D$17,0))="","",INDEX([1]BH!$K$2:$K$17,MATCH($D15,[1]BH!$D$2:$D$17,0))),"") -> 46129 | L15: =IF($O15="","",$O15-TODAY()) -> -178 | M15: =IF(AND(TRIM($A15)="Finalized",$K15<>""),"",IF($C15="","",$C15+365-TODAY())) -> 194 | N15: =IF(AND(TRIM($A15)="Finalized",$K15<>""),"",IF($C15="","",$C15+365-TODAY())) -> 194 | O15: =IF(AND(TRIM($A15)="Finalized",$K15<>""),"",DATE(2026,4,14)) -> 46126 | P15: 90 days | Q15: OPTUM | R15: 365 days | S15: Processed date | T15: 365 days | U15: Processed date | V15: 2026-01 January | W15: BH | AA15: 1 | AB15: 976.64 | AC15: 0 | AD15: 0 | AE15: 46133 | AF15: 976.64 | AG15: 206 | AH15: F1190 | AM15: LEATHEM, JARRETT | AN15: ASAP - Gilbert | AO15: 46057
A16: =IFERROR(IF(INDEX([1]US!$A$2:$A$8,MATCH($D16,[1]US!$D$2:$D$8,0))="","",INDEX([1]US!$A$2:$A$8,MATCH($D16,[1]US!$D$2:$D$8,0))),"") -> Received | B16: =IFERROR(IF(INDEX([1]US!$B$2:$B$8,MATCH($D16,[1]US!$D$2:$D$8,0))="","",INDEX([1]US!$B$2:$B$8,MATCH($D16,[1]US!$D$2:$D$8,0))),"") | C16: =IFERROR(IF(INDEX([1]US!$C$2:$C$8,MATCH($D16,[1]US!$D$2:$D$8,0))="","",INDEX([1]US!$C$2:$C$8,MATCH($D16,[1]US!$D$2:$D$8,0))),"") -> 46160 | D16: 547451314 | E16: HF494223308 | F16: 46036 | G16: Cigna Medicare Advantage | H16: Cigna Medicare Advantage | I16: No Payer | J16: 93925 x1 | K16: =IFERROR(IF(INDEX([1]US!$K$2:$K$8,MATCH($D16,[1]US!$D$2:$D$8,0))="","",INDEX([1]US!$K$2:$K$8,MATCH($D16,[1]US!$D$2:$D$8,0))),"") | L16: =IF($O16="","",$O16-TODAY()) -> -178 | M16: =IF(AND(TRIM($A16)="Finalized",$K16<>""),"",IF($F16="","",$F16+90-TODAY())) -> -178 | N16: =IF(AND(TRIM($A16)="Finalized",$K16<>""),"",IF($C16="","",$C16+180-TODAY())) -> 36 | O16: =IF(AND(TRIM($A16)="Finalized",$K16<>""),"",DATE(2026,4,14)) -> 46126 | P16: 90 days | Q16: CIGNA / CIGNA MEDICARE | R16: 90 days | S16: Date of service | T16: 180 days | U16: Processed date | V16: 2026-01 January | W16: US | AA16: 1 | AB16: 1649.2 | AC16: -227.03 | AD16: 227.03 | AE16: 46160 | AF16: 1649.2 | AG16: 206 | AH16: M79604 | AI16: M79605 | AJ16: M25551 | AK16: M25552 | AM16: BURGHER, ABRAM | AN16: ASAP - Surprise - Reems | AO16: 46048
A17: =IFERROR(IF(INDEX([1]ORTHO!$A$2:$A$10,MATCH($D17,[1]ORTHO!$D$2:$D$10,0))="","",INDEX([1]ORTHO!$A$2:$A$10,MATCH($D17,[1]ORTHO!$D$2:$D$10,0))),"") | B17: =IFERROR(IF(INDEX([1]ORTHO!$B$2:$B$10,MATCH($D17,[1]ORTHO!$D$2:$D$10,0))="","",INDEX([1]ORTHO!$B$2:$B$10,MATCH($D17,[1]ORTHO!$D$2:$D$10,0))),"") | C17: =IFERROR(IF(INDEX([1]ORTHO!$C$2:$C$10,MATCH($D17,[1]ORTHO!$D$2:$D$10,0))="","",INDEX([1]ORTHO!$C$2:$C$10,MATCH($D17,[1]ORTHO!$D$2:$D$10,0))),"") | D17: 548591390 | E17: HF383758253 | F17: 46036 | G17: Blue Cross Blue Shield of Arizona (BCBS AZ) | H17: Blue Cross Blue Shield of Arizona (BCBS AZ) | I17: No Payer | J17: 63047 x1 | K17: =IFERROR(IF(INDEX([1]ORTHO!$K$2:$K$10,MATCH($D17,[1]ORTHO!$D$2:$D$10,0))="","",INDEX([1]ORTHO!$K$2:$K$10,MATCH($D17,[1]ORTHO!$D$2:$D$10,0))),"") | L17: =IF($O17="","",$O17-TODAY()) -> -178 | M17: =IF(AND(TRIM($A17)="Finalized",$K17<>""),"",IF($F17="","",$F17+90-TODAY())) -> -178 | N17: =IF(AND(TRIM($A17)="Finalized",$K17<>""),"",IF($C17="","",$C17+365-TODAY())) | O17: =IF(AND(TRIM($A17)="Finalized",$K17<>""),"",DATE(2026,4,14)) -> 46126 | P17: 90 days | Q17: BCBS | R17: 90 days | S17: Date of service | T17: 365 days | U17: Processed date | V17: 2026-01 January | W17: ORTHO | AA17: 1 | AB17: 7623.07 | AC17: 0 | AD17: 0 | AF17: 7623.07 | AG17: 206 | AH17: M48061 | AI17: M5416 | AM17: MAYURAN, VIKRAM | AN17: ASAP Surgery Centers North Valley LLC | AO17: 46042
A18: =IFERROR(IF(INDEX([1]US!$A$2:$A$8,MATCH($D18,[1]US!$D$2:$D$8,0))="","",INDEX([1]US!$A$2:$A$8,MATCH($D18,[1]US!$D$2:$D$8,0))),"") | B18: =IFERROR(IF(INDEX([1]US!$B$2:$B$8,MATCH($D18,[1]US!$D$2:$D$8,0))="","",INDEX([1]US!$B$2:$B$8,MATCH($D18,[1]US!$D$2:$D$8,0))),"") | C18: =IFERROR(IF(INDEX([1]US!$C$2:$C$8,MATCH($D18,[1]US!$D$2:$D$8,0))="","",INDEX([1]US!$C$2:$C$8,MATCH($D18,[1]US!$D$2:$D$8,0))),"") -> 46163 | D18: 547465291 | E18: HF526889546 | F18: 46037 | G18: United Healthcare | H18: United Healthcare | I18: No Payer | J18: 93970 x1 | K18: =IFERROR(IF(INDEX([1]US!$K$2:$K$8,MATCH($D18,[1]US!$D$2:$D$8,0))="","",INDEX([1]US!$K$2:$K$8,MATCH($D18,[1]US!$D$2:$D$8,0))),"") | L18: =IF($O18="","",$O18-TODAY()) -> -177 | M18: =IF(AND(TRIM($A18)="Finalized",$K18<>""),"",IF($C18="","",$C18+180-TODAY())) -> 39 | N18: =IF(AND(TRIM($A18)="Finalized",$K18<>""),"",IF($C18="","",$C18+365-TODAY())) -> 224 | O18: =IF(AND(TRIM($A18)="Finalized",$K18<>""),"",DATE(2026,4,15)) -> 46127 | P18: 90 days | Q18: UHC COMMERCIAL | R18: 180 days | S18: Processed date | T18: 365 days | U18: Processed date | V18: 2026-01 January | W18: US | AA18: 1 | AB18: 1294.23 | AC18: 0 | AD18: 0 | AE18: 46163 | AF18: 1294.23 | AG18: 205 | AH18: R600 | AI18: M5416 | AM18: TURLEY, TODD | AN18: ASAP - DEER VALLEY | AO18: 46048
A19: =IFERROR(IF(INDEX([1]BH!$A$2:$A$17,MATCH($D19,[1]BH!$D$2:$D$17,0))="","",INDEX([1]BH!$A$2:$A$17,MATCH($D19,[1]BH!$D$2:$D$17,0))),"") -> Denied | B19: =IFERROR(IF(INDEX([1]BH!$B$2:$B$17,MATCH($D19,[1]BH!$D$2:$D$17,0))="","",INDEX([1]BH!$B$2:$B$17,MATCH($D19,[1]BH!$D$2:$D$17,0))),"") -> Under review - TAT 15 days - Ref # 10605826 - Rep Muthamma | C19: =IFERROR(IF(INDEX([1]BH!$C$2:$C$17,MATCH($D19,[1]BH!$D$2:$D$17,0))="","",INDEX([1]BH!$C$2:$C$17,MATCH($D19,[1]BH!$D$2:$D$17,0))),"") -> 46064 | D19: 548015539 | E19: HF537685966 | F19: 46043 | G19: Blue Cross Blue Shield of Arizona (BCBS AZ) | H19: Blue Cross Blue Shield of Arizona (BCBS AZ) | I19: Medicare Part B Arizona * | J19: 99494 x1; 99492 x1 | K19: =IFERROR(IF(INDEX([1]BH!$K$2:$K$17,MATCH($D19,[1]BH!$D$2:$D$17,0))="","",INDEX([1]BH!$K$2:$K$17,MATCH($D19,[1]BH!$D$2:$D$17,0))),"") -> 46134 | L19: =IF($O19="","",$O19-TODAY()) -> -171 | M19: =IF(AND(TRIM($A19)="Finalized",$K19<>""),"",IF($F19="","",$F19+90-TODAY())) -> -171 | N19: =IF(AND(TRIM($A19)="Finalized",$K19<>""),"",IF($C19="","",$C19+365-TODAY())) -> 125 | O19: =IF(AND(TRIM($A19)="Finalized",$K19<>""),"",DATE(2026,4,21)) -> 46133 | P19: 90 days | Q19: BCBS | R19: 90 days | S19: Date of service | T19: 365 days | U19: Processed date | V19: 2026-01 January | W19: BH | AA19: 1 | AB19: 1426.25 | AC19: 0 | AD19: 0 | AE19: 46064 | AF19: 1426.25 | AG19: 199 | AH19: F330 | AM19: LEATHEM, JARRETT | AN19: ASAP - Gilbert | AO19: 46057
A20: =IFERROR(IF(INDEX([1]US!$A$2:$A$8,MATCH($D20,[1]US!$D$2:$D$8,0))="","",INDEX([1]US!$A$2:$A$8,MATCH($D20,[1]US!$D$2:$D$8,0))),"") -> Received | B20: =IFERROR(IF(INDEX([1]US!$B$2:$B$8,MATCH($D20,[1]US!$D$2:$D$8,0))="","",INDEX([1]US!$B$2:$B$8,MATCH($D20,[1]US!$D$2:$D$8,0))),"") | C20: =IFERROR(IF(INDEX([1]US!$C$2:$C$8,MATCH($D20,[1]US!$D$2:$D$8,0))="","",INDEX([1]US!$C$2:$C$8,MATCH($D20,[1]US!$D$2:$D$8,0))),"") -> 46160 | D20: 547481511 | E20: HF513229920 | F20: 46043 | G20: HealthSpring Medicare Advantage | H20: HealthSpring Medicare Advantage | I20: No Payer | J20: 93970 x1 | K20: =IFERROR(IF(INDEX([1]US!$K$2:$K$8,MATCH($D20,[1]US!$D$2:$D$8,0))="","",INDEX([1]US!$K$2:$K$8,MATCH($D20,[1]US!$D$2:$D$8,0))),"") | L20: =IF($O20="","",$O20-TODAY()) -> -171 | M20: =IF(AND(TRIM($A20)="Finalized",$K20<>""),"",IF($F20="","",$F20+90-TODAY())) -> -171 | N20: =IF(AND(TRIM($A20)="Finalized",$K20<>""),"",IF($C20="","",$C20+180-TODAY())) -> 36 | O20: =IF(AND(TRIM($A20)="Finalized",$K20<>""),"",DATE(2026,4,21)) -> 46133 | P20: 90 days | Q20: CIGNA / CIGNA MEDICARE | R20: 90 days | S20: Date of service | T20: 180 days | U20: Processed date | V20: 2026-01 January | W20: US | AA20: 1 | AB20: 1294.23 | AC20: -176 | AD20: 176 | AE20: 46160 | AF20: 1294.23 | AG20: 199 | AH20: I872 | AI20: I83812 | AM20: BURGHER, ABRAM | AN20: ASAP - Surprise - Reems | AO20: 46048
A21: =IFERROR(IF(INDEX([1]BH!$A$2:$A$17,MATCH($D21,[1]BH!$D$2:$D$17,0))="","",INDEX([1]BH!$A$2:$A$17,MATCH($D21,[1]BH!$D$2:$D$17,0))),"") -> Pending | B21: =IFERROR(IF(INDEX([1]BH!$B$2:$B$17,MATCH($D21,[1]BH!$D$2:$D$17,0))="","",INDEX([1]BH!$B$2:$B$17,MATCH($D21,[1]BH!$D$2:$D$17,0))),"") -> secondary - Resubmitted to AmeTrust | C21: =IFERROR(IF(INDEX([1]BH!$C$2:$C$17,MATCH($D21,[1]BH!$D$2:$D$17,0))="","",INDEX([1]BH!$C$2:$C$17,MATCH($D21,[1]BH!$D$2:$D$17,0))),"") -> 46094 | D21: 547442681 | E21: HF359780591 | F21: 46044 | G21: TRIADA GAP BENEFITS | H21: Blue Cross Blue Shield of Arizona (BCBS AZ) | I21: TRIADA GAP BENEFITS | J21: 99493 x1 | K21: =IFERROR(IF(INDEX([1]BH!$K$2:$K$17,MATCH($D21,[1]BH!$D$2:$D$17,0))="","",INDEX([1]BH!$K$2:$K$17,MATCH($D21,[1]BH!$D$2:$D$17,0))),"") -> 46304 | L21: =IF($O21="","",$O21-TODAY()) -> -170 | M21: =IF(AND(TRIM($A21)="Finalized",$K21<>""),"",IF($F21="","",$F21+90-TODAY())) -> -170 | N21: =IF(AND(TRIM($A21)="Finalized",$K21<>""),"",IF($C21="","",$C21+365-TODAY())) -> 155 | O21: =IF(AND(TRIM($A21)="Finalized",$K21<>""),"",DATE(2026,4,22)) -> 46134 | P21: 90 days | Q21: BCBS | R21: 90 days | S21: Date of service | T21: 365 days | U21: Processed date | V21: 2026-01 January | W21: BH | AA21: 1 | AB21: 976.64 | AC21: 840.66 | AD21: 0 | AE21: 46094 | AF21: 135.98 | AG21: 198 | AH21: F411 | AL21: 556556161 | AM21: LEATHEM, JARRETT | AN21: ASAP - DEER VALLEY | AO21: 46056
A22: =IFERROR(IF(INDEX([1]ORTHO!$A$2:$A$10,MATCH($D22,[1]ORTHO!$D$2:$D$10,0))="","",INDEX([1]ORTHO!$A$2:$A$10,MATCH($D22,[1]ORTHO!$D$2:$D$10,0))),"") -> Denied | B22: =IFERROR(IF(INDEX([1]ORTHO!$B$2:$B$10,MATCH($D22,[1]ORTHO!$D$2:$D$10,0))="","",INDEX([1]ORTHO!$B$2:$B$10,MATCH($D22,[1]ORTHO!$D$2:$D$10,0))),"") | C22: =IFERROR(IF(INDEX([1]ORTHO!$C$2:$C$10,MATCH($D22,[1]ORTHO!$D$2:$D$10,0))="","",INDEX([1]ORTHO!$C$2:$C$10,MATCH($D22,[1]ORTHO!$D$2:$D$10,0))),"") -> 46163 | D22: 547275123 | E22: HF470511781 | F22: 46045 | G22: United Healthcare | H22: Blue Cross Blue Shield of Arizona (BCBS AZ) | I22: United Healthcare | J22: 27279+LT x1 | K22: =IFERROR(IF(INDEX([1]ORTHO!$K$2:$K$10,MATCH($D22,[1]ORTHO!$D$2:$D$10,0))="","",INDEX([1]ORTHO!$K$2:$K$10,MATCH($D22,[1]ORTHO!$D$2:$D$10,0))),"") | L22: =IF($O22="","",$O22-TODAY()) -> -169 | M22: =IF(AND(TRIM($A22)="Finalized",$K22<>""),"",IF($F22="","",$F22+90-TODAY())) -> -169 | N22: =IF(AND(TRIM($A22)="Finalized",$K22<>""),"",IF($C22="","",$C22+365-TODAY())) -> 224 | O22: =IF(AND(TRIM($A22)="Finalized",$K22<>""),"",DATE(2026,4,23)) -> 46135 | P22: 90 days | Q22: BCBS | R22: 90 days | S22: Date of service | T22: 365 days | U22: Processed date | V22: 2026-01 January | W22: ORTHO | X22: LT | AA22: 1 | AB22: 5614.63 | AC22: -186.91 | AD22: 0 | AE22: 46163 | AF22: 5614.63 | AG22: 197 | AH22: M461 | AL22: 549237390 | AM22: LEATHEM, JARRETT | AN22: Premier Endoscopy Center, LLC | AO22: 46049
A23: =IFERROR(IF(INDEX([1]ORTHO!$A$2:$A$10,MATCH($D23,[1]ORTHO!$D$2:$D$10,0))="","",INDEX([1]ORTHO!$A$2:$A$10,MATCH($D23,[1]ORTHO!$D$2:$D$10,0))),"") -> Denied | B23: =IFERROR(IF(INDEX([1]ORTHO!$B$2:$B$10,MATCH($D23,[1]ORTHO!$D$2:$D$10,0))="","",INDEX([1]ORTHO!$B$2:$B$10,MATCH($D23,[1]ORTHO!$D$2:$D$10,0))),"") -> On it | C23: =IFERROR(IF(INDEX([1]ORTHO!$C$2:$C$10,MATCH($D23,[1]ORTHO!$D$2:$D$10,0))="","",INDEX([1]ORTHO!$C$2:$C$10,MATCH($D23,[1]ORTHO!$D$2:$D$10,0))),"") -> 46052 | D23: 547576017 | E23: HF524606724 | F23: 46045 | G23: Blue Cross Blue Shield of Arizona (BCBS AZ) | H23: Blue Cross Blue Shield of Arizona (BCBS AZ) | I23: No Payer | J23: 63047 x1 | K23: =IFERROR(IF(INDEX([1]ORTHO!$K$2:$K$10,MATCH($D23,[1]ORTHO!$D$2:$D$10,0))="","",INDEX([1]ORTHO!$K$2:$K$10,MATCH($D23,[1]ORTHO!$D$2:$D$10,0))),"") | L23: =IF($O23="","",$O23-TODAY()) -> -169 | M23: =IF(AND(TRIM($A23)="Finalized",$K23<>""),"",IF($F23="","",$F23+90-TODAY())) -> -169 | N23: =IF(AND(TRIM($A23)="Finalized",$K23<>""),"",IF($C23="","",$C23+365-TODAY())) -> 113 | O23: =IF(AND(TRIM($A23)="Finalized",$K23<>""),"",DATE(2026,4,23)) -> 46135 | P23: 90 days | Q23: BCBS | R23: 90 days | S23: Date of service | T23: 365 days | U23: Processed date | V23: 2026-01 January | W23: ORTHO | AA23: 1 | AB23: 7623.07 | AC23: 0 | AD23: 0 | AE23: 46052 | AF23: 7623.07 | AG23: 197 | AH23: M48062 | AM23: O'NEIL, ROY | AN23: ASAP Surgery Centers North Valley LLC | AO23: 46049
A24: =IFERROR(IF(INDEX([1]DME!$A$2:$A$8,MATCH($D24,[1]DME!$D$2:$D$8,0))="","",INDEX([1]DME!$A$2:$A$8,MATCH($D24,[1]DME!$D$2:$D$8,0))),"") -> Pending | B24: =IFERROR(IF(INDEX([1]DME!$B$2:$B$8,MATCH($D24,[1]DME!$D$2:$D$8,0))="","",INDEX([1]DME!$B$2:$B$8,MATCH($D24,[1]DME!$D$2:$D$8,0))),"") -> secondary - I need to crossover claim - Edited charges for A6219, and resubmitted | C24: =IFERROR(IF(INDEX([1]DME!$C$2:$C$8,MATCH($D24,[1]DME!$D$2:$D$8,0))="","",INDEX([1]DME!$C$2:$C$8,MATCH($D24,[1]DME!$D$2:$D$8,0))),"") -> 46156 | D24: 557162806 | E24: HF518924824 | F24: 46041 | G24: Mercy Care Plan (AHCCCS) - Complete Care & Long Term Care (LTC) | H24: Allwell - All States (Centene) | I24: Mercy Care Plan (AHCCCS) - Complete Care & Long Term Care (LTC) | J24: A6023+A2 x10 | K24: =IFERROR(IF(INDEX([1]DME!$K$2:$K$8,MATCH($D24,[1]DME!$D$2:$D$8,0))="","",INDEX([1]DME!$K$2:$K$8,MATCH($D24,[1]DME!$D$2:$D$8,0))),"") -> 46136 | L24: =IF($O24="","",$O24-TODAY()) -> -168 | M24: =IF(AND(TRIM($A24)="Finalized",$K24<>""),"",IF($C24="","",$C24+90-TODAY())) -> -58 | N24: =IF(AND(TRIM($A24)="Finalized",$K24<>""),"",IF($C24="","",$C24+90-TODAY())) -> -58 | O24: =IF(AND(TRIM($A24)="Finalized",$K24<>""),"",DATE(2026,4,24)) -> 46136 | P24: 95 days | Q24: WELLCARE BY ALLWELL | R24: 90 days | S24: Processed date | T24: 90 days | U24: Processed date | V24: 2026-01 January | W24: DME | X24: A2 | AA24: 10 | AB24: 18176.9 | AC24: 16142.75 | AD24: 1627.48 | AE24: 46156 | AF24: 406.67 | AG24: 201 | AH24: G894 | AI24: M961 | AJ24: M5416 | AL24: 551367817 | AM24: KALLGREN, MARK | AN24: ASAP - Mesa | AO24: 46063
A25: =IFERROR(IF(INDEX([1]GAE!$A$2:$A$12,MATCH($D25,[1]GAE!$D$2:$D$12,0))="","",INDEX([1]GAE!$A$2:$A$12,MATCH($D25,[1]GAE!$D$2:$D$12,0))),"") | B25: =IFERROR(IF(INDEX([1]GAE!$B$2:$B$12,MATCH($D25,[1]GAE!$D$2:$D$12,0))="","",INDEX([1]GAE!$B$2:$B$12,MATCH($D25,[1]GAE!$D$2:$D$12,0))),"") | C25: =IFERROR(IF(INDEX([1]GAE!$C$2:$C$12,MATCH($D25,[1]GAE!$D$2:$D$12,0))="","",INDEX([1]GAE!$C$2:$C$12,MATCH($D25,[1]GAE!$D$2:$D$12,0))),"") -> 46111 | D25: 552170540 | E25: HF505789977 | F25: 46048 | G25: Humana Gold Plus HMO | H25: Humana Gold Plus HMO | I25: No Payer | J25: 37242 x1; 36245+59 x1; 36248+59 x1; 36246+59+RT x1 | K25: =IFERROR(IF(INDEX([1]GAE!$K$2:$K$12,MATCH($D25,[1]GAE!$D$2:$D$12,0))="","",INDEX([1]GAE!$K$2:$K$12,MATCH($D25,[1]GAE!$D$2:$D$12,0))),"") | L25: =IF($O25="","",$O25-TODAY()) -> -166 | M25: =IF(AND(TRIM($A25)="Finalized",$K25<>""),"",IF($F25="","",$F25+90-TODAY())) -> -166 | N25: =IF(AND(TRIM($A25)="Finalized",$K25<>""),"",IF($C25="","",$C25+540-TODAY())) -> 347 | O25: =IF(AND(TRIM($A25)="Finalized",$K25<>""),"",DATE(2026,4,26)) -> 46138 | P25: 90 days | Q25: HUMANA MA | R25: 90 days | S25: Date of service | T25: 540 days | U25: Processed date | V25: 2026-01 January | W25: GAE | X25: 59 | Y25: RT | AA25: 1 | AB25: 64277.64 | AC25: 0 | AD25: 0 | AE25: 46111 | AF25: 64277.64 | AG25: 194 | AH25: M1711 | AI25: I798 | AJ25: M25561 | AM25: HUNTER, DREW | AN25: ASAP Surgery Centers North Valley LLC | AO25: 46062
A26: =IFERROR(IF(INDEX([1]BH!$A$2:$A$17,MATCH($D26,[1]BH!$D$2:$D$17,0))="","",INDEX([1]BH!$A$2:$A$17,MATCH($D26,[1]BH!$D$2:$D$17,0))),"") -> Received | B26: =IFERROR(IF(INDEX([1]BH!$B$2:$B$17,MATCH($D26,[1]BH!$D$2:$D$17,0))="","",INDEX([1]BH!$B$2:$B$17,MATCH($D26,[1]BH!$D$2:$D$17,0))),"") -> Resubmitted - no changes | C26: =IFERROR(IF(INDEX([1]BH!$C$2:$C$17,MATCH($D26,[1]BH!$D$2:$D$17,0))="","",INDEX([1]BH!$C$2:$C$17,MATCH($D26,[1]BH!$D$2:$D$17,0))),"") -> 46128 | D26: 555599776 | E26: HF475536429 | F26: 46049 | G26: Blue Cross Blue Shield of Arizona (BCBS AZ) | H26: Blue Cross Blue Shield of Arizona (BCBS AZ) | I26: No Payer | J26: 99492 x1; 99494 x1 | K26: =IFERROR(IF(INDEX([1]BH!$K$2:$K$17,MATCH($D26,[1]BH!$D$2:$D$17,0))="","",INDEX([1]BH!$K$2:$K$17,MATCH($D26,[1]BH!$D$2:$D$17,0))),"") -> 46122 | L26: =IF($O26="","",$O26-TODAY()) -> -165 | M26: =IF(AND(TRIM($A26)="Finalized",$K26<>""),"",IF($F26="","",$F26+90-TODAY())) -> -165 | N26: =IF(AND(TRIM($A26)="Finalized",$K26<>""),"",IF($C26="","",$C26+365-TODAY())) -> 189 | O26: =IF(AND(TRIM($A26)="Finalized",$K26<>""),"",DATE(2026,4,27)) -> 46139 | P26: 90 days | Q26: BCBS | R26: 90 days | S26: Date of service | T26: 365 days | U26: Processed date | V26: 2026-01 January | W26: BH | AA26: 1 | AB26: 1426.25 | AC26: 0 | AD26: 0 | AE26: 46128 | AF26: 1426.25 | AG26: 193 | AH26: F4320 | AM26: O'NEIL, ROY | AN26: ASAP Peoria | AO26: 46057
A27: =IFERROR(IF(INDEX([1]BH!$A$2:$A$17,MATCH($D27,[1]BH!$D$2:$D$17,0))="","",INDEX([1]BH!$A$2:$A$17,MATCH($D27,[1]BH!$D$2:$D$17,0))),"") -> Denied | B27: =IFERROR(IF(INDEX([1]BH!$B$2:$B$17,MATCH($D27,[1]BH!$D$2:$D$17,0))="","",INDEX([1]BH!$B$2:$B$17,MATCH($D27,[1]BH!$D$2:$D$17,0))),"") -> Resubmitted with 99492 - Recon filed - Request ID TT2647830 - Claim 26A635462200 DOS 01/27/26 99493 denied no prior CoCM 6mo. Prior 99493 DOS 12/16/25 paid clm 26A070631100 under old ID 2062477. Req reprocess; PRA attached - DND 99493 This non-payable code is for required reporting only - Added Date of Current Illness, claim note, and resubmitted | C27: =IFERROR(IF(INDEX([1]BH!$C$2:$C$17,MATCH($D27,[1]BH!$D$2:$D$17,0))="","",INDEX([1]BH!$C$2:$C$17,MATCH($D27,[1]BH!$D$2:$D$17,0))),"") -> 46287 | D27: 556349314 | E27: HF431164004 | F27: 46049 | G27: Optum Care Medical Network of Arizona, Utah, & Washington (LifePrint) | H27: Optum Care Medical Network of Arizona, Utah, & Washington (LifePrint) | I27: No Payer | J27: 99493 x1 | K27: =IFERROR(IF(INDEX([1]BH!$K$2:$K$17,MATCH($D27,[1]BH!$D$2:$D$17,0))="","",INDEX([1]BH!$K$2:$K$17,MATCH($D27,[1]BH!$D$2:$D$17,0))),"") -> 46300 | L27: =IF($O27="","",$O27-TODAY()) -> -165 | M27: =IF(AND(TRIM($A27)="Finalized",$K27<>""),"",IF($C27="","",$C27+365-TODAY())) -> 348 | N27: =IF(AND(TRIM($A27)="Finalized",$K27<>""),"",IF($C27="","",$C27+365-TODAY())) -> 348 | O27: =IF(AND(TRIM($A27)="Finalized",$K27<>""),"",DATE(2026,4,27)) -> 46139 | P27: 90 days | Q27: OPTUM | R27: 365 days | S27: Processed date | T27: 365 days | U27: Processed date | V27: 2026-01 January | W27: BH | AA27: 1 | AB27: 976.64 | AC27: 0 | AD27: 0 | AE27: 46133 | AF27: 976.64 | AG27: 193 | AH27: F331 | AI27: F411 | AM27: O'NEIL, ROY | AN27: ASAP - Goodyear | AO27: 46056
A28: =IFERROR(IF(INDEX([1]BH!$A$2:$A$17,MATCH($D28,[1]BH!$D$2:$D$17,0))="","",INDEX([1]BH!$A$2:$A$17,MATCH($D28,[1]BH!$D$2:$D$17,0))),"") -> Pending | B28: =IFERROR(IF(INDEX([1]BH!$B$2:$B$17,MATCH($D28,[1]BH!$D$2:$D$17,0))="","",INDEX([1]BH!$B$2:$B$17,MATCH($D28,[1]BH!$D$2:$D$17,0))),"") -> Not shifting - working on it Shifted to PR - Ins didn't receive PT update - I talked to PT on the phone, she said she will contact the insurance to take care of the IQ this week | C28: =IFERROR(IF(INDEX([1]BH!$C$2:$C$17,MATCH($D28,[1]BH!$D$2:$D$17,0))="","",INDEX([1]BH!$C$2:$C$17,MATCH($D28,[1]BH!$D$2:$D$17,0))),"") -> 46066 | D28: 547976909 | E28: HF535417942 | F28: 46051 | G28: Blue Cross Blue Shield of Arizona (BCBS AZ) | H28: Blue Cross Blue Shield of Arizona (BCBS AZ) | I28: LIEN 05 | J28: 99493 x1 | K28: =IFERROR(IF(INDEX([1]BH!$K$2:$K$17,MATCH($D28,[1]BH!$D$2:$D$17,0))="","",INDEX([1]BH!$K$2:$K$17,MATCH($D28,[1]BH!$D$2:$D$17,0))),"") -> 46245 | L28: =IF($O28="","",$O28-TODAY()) -> -163 | M28: =IF(AND(TRIM($A28)="Finalized",$K28<>""),"",IF($F28="","",$F28+90-TODAY())) -> -163 | N28: =IF(AND(TRIM($A28)="Finalized",$K28<>""),"",IF($C28="","",$C28+365-TODAY())) -> 127 | O28: =IF(AND(TRIM($A28)="Finalized",$K28<>""),"",DATE(2026,4,29)) -> 46141 | P28: 90 days | Q28: BCBS | R28: 90 days | S28: Date of service | T28: 365 days | U28: Processed date | V28: 2026-01 January | W28: BH | AA28: 1 | AB28: 976.64 | AC28: 0 | AD28: 0 | AE28: 46066 | AF28: 976.64 | AG28: 191 | AH28: F4323 | AM28: TURLEY, TODD | AN28: ASAP - DEER VALLEY | AO28: 46056
A29: =IFERROR(IF(INDEX([1]US!$A$2:$A$8,MATCH($D29,[1]US!$D$2:$D$8,0))="","",INDEX([1]US!$A$2:$A$8,MATCH($D29,[1]US!$D$2:$D$8,0))),"") | B29: =IFERROR(IF(INDEX([1]US!$B$2:$B$8,MATCH($D29,[1]US!$D$2:$D$8,0))="","",INDEX([1]US!$B$2:$B$8,MATCH($D29,[1]US!$D$2:$D$8,0))),"") | C29: =IFERROR(IF(INDEX([1]US!$C$2:$C$8,MATCH($D29,[1]US!$D$2:$D$8,0))="","",INDEX([1]US!$C$2:$C$8,MATCH($D29,[1]US!$D$2:$D$8,0))),"") -> 46156 | D29: 548573158 | E29: HF537684538 | F29: 46051 | G29: United Healthcare | H29: United Healthcare | I29: No Payer | J29: 93970 x1 | K29: =IFERROR(IF(INDEX([1]US!$K$2:$K$8,MATCH($D29,[1]US!$D$2:$D$8,0))="","",INDEX([1]US!$K$2:$K$8,MATCH($D29,[1]US!$D$2:$D$8,0))),"") | L29: =IF($O29="","",$O29-TODAY()) -> -163 | M29: =IF(AND(TRIM($A29)="Finalized",$K29<>""),"",IF($C29="","",$C29+180-TODAY())) -> 32 | N29: =IF(AND(TRIM($A29)="Finalized",$K29<>""),"",IF($C29="","",$C29+365-TODAY())) -> 217 | O29: =IF(AND(TRIM($A29)="Finalized",$K29<>""),"",DATE(2026,4,29)) -> 46141 | P29: 90 days | Q29: UHC COMMERCIAL | R29: 180 days | S29: Processed date | T29: 365 days | U29: Processed date | V29: 2026-01 January | W29: US | AA29: 1 | AB29: 1294.23 | AC29: 0 | AD29: 0 | AE29: 46156 | AF29: 1294.23 | AG29: 191 | AH29: R600 | AI29: M79604 | AJ29: M79605 | AM29: TURLEY, TODD | AN29: ASAP - DEER VALLEY | AO29: 46058
A30: =IFERROR(IF(INDEX([2]BH!$A$2:$A$9,MATCH($D30,[2]BH!$D$2:$D$9,0))="","",INDEX([2]BH!$A$2:$A$9,MATCH($D30,[2]BH!$D$2:$D$9,0))),"") -> Denied | B30: =IFERROR(IF(INDEX([2]BH!$B$2:$B$9,MATCH($D30,[2]BH!$D$2:$D$9,0))="","",INDEX([2]BH!$B$2:$B$9,MATCH($D30,[2]BH!$D$2:$D$9,0))),"") -> Rep Briana - Jarrett Leathem is not contracted with member's Focus Network - Reference number 11216220 | C30: =IFERROR(IF(INDEX([2]BH!$C$2:$C$9,MATCH($D30,[2]BH!$D$2:$D$9,0))="","",INDEX([2]BH!$C$2:$C$9,MATCH($D30,[2]BH!$D$2:$D$9,0))),"") -> 46098 | D30: 548676737 | E30: HF499806568 | F30: 46056 | G30: Blue Cross Blue Shield of Arizona (BCBS AZ) | H30: Blue Cross Blue Shield of Arizona (BCBS AZ) | I30: No Payer | J30: 99494 x1; 99493 x1 | K30: =IFERROR(IF(INDEX([2]BH!$K$2:$K$9,MATCH($D30,[2]BH!$D$2:$D$9,0))="","",INDEX([2]BH!$K$2:$K$9,MATCH($D30,[2]BH!$D$2:$D$9,0))),"") -> 46183 | L30: =IF($O30="","",$O30-TODAY()) -> -158 | M30: =IF(AND(TRIM($A30)="Finalized",$K30<>""),"",IF($F30="","",$F30+90-TODAY())) -> -158 | N30: =IF(AND(TRIM($A30)="Finalized",$K30<>""),"",IF($C30="","",$C30+365-TODAY())) -> 159 | O30: =IF(AND(TRIM($A30)="Finalized",$K30<>""),"",DATE(2026,5,4)) -> 46146 | P30: 90 days | Q30: BCBS | R30: 90 days | S30: Date of service | T30: 365 days | U30: Processed date | V30: 2026-02 February | W30: BH | AA30: 1 | AB30: 1372.91 | AC30: 0 | AD30: 0 | AE30: 46098 | AF30: 1372.91 | AG30: 186 | AH30: F4320 | AM30: LEATHEM, JARRETT | AN30: ASAP - Goodyear | AO30: 46086
A31: =IFERROR(IF(INDEX([1]GAE!$A$2:$A$12,MATCH($D31,[1]GAE!$D$2:$D$12,0))="","",INDEX([1]GAE!$A$2:$A$12,MATCH($D31,[1]GAE!$D$2:$D$12,0))),"") | B31: =IFERROR(IF(INDEX([1]GAE!$B$2:$B$12,MATCH($D31,[1]GAE!$D$2:$D$12,0))="","",INDEX([1]GAE!$B$2:$B$12,MATCH($D31,[1]GAE!$D$2:$D$12,0))),"") | C31: =IFERROR(IF(INDEX([1]GAE!$C$2:$C$12,MATCH($D31,[1]GAE!$D$2:$D$12,0))="","",INDEX([1]GAE!$C$2:$C$12,MATCH($D31,[1]GAE!$D$2:$D$12,0))),"") -> 46127 | D31: 555373347 | E31: HF543361488 | F31: 46027 | G31: Aetna Medicare PPO | H31: Aetna Medicare PPO | I31: No Payer | J31: 36248+59 x3; 37242 x1; 36246+59+RT x1 | K31: =IFERROR(IF(INDEX([1]GAE!$K$2:$K$12,MATCH($D31,[1]GAE!$D$2:$D$12,0))="","",INDEX([1]GAE!$K$2:$K$12,MATCH($D31,[1]GAE!$D$2:$D$12,0))),"") | L31: =IF($O31="","",$O31-TODAY()) -> -157 | M31: =IF(AND(TRIM($A31)="Finalized",$K31<>""),"",IF($C31="","",$C31+180-TODAY())) -> 3 | N31: =IF(AND(TRIM($A31)="Finalized",$K31<>""),"",IF($C31="","",$C31+180-TODAY())) -> 3 | O31: =IF(AND(TRIM($A31)="Finalized",$K31<>""),"",DATE(2026,5,5)) -> 46147 | P31: 120 days | Q31: AETNA | R31: 180 days | S31: Processed date | T31: 180 days | U31: Processed date | V31: 2026-01 January | W31: GAE | X31: 59 | Y31: RT | AA31: 3, 1 | AB31: 57326.78 | AC31: 0 | AD31: 0 | AE31: 46127 | AF31: 57326.78 | AG31: 215 | AH31: M1711 | AI31: I798 | AJ31: M25561 | AM31: HUNTER, DREW | AN31: ASAP - DEER VALLEY | AO31: 46062
A32: =IFERROR(IF(INDEX([2]ORTHO!$A$2:$A$11,MATCH($D32,[2]ORTHO!$D$2:$D$11,0))="","",INDEX([2]ORTHO!$A$2:$A$11,MATCH($D32,[2]ORTHO!$D$2:$D$11,0))),"") -> Denied | B32: =IFERROR(IF(INDEX([2]ORTHO!$B$2:$B$11,MATCH($D32,[2]ORTHO!$D$2:$D$11,0))="","",INDEX([2]ORTHO!$B$2:$B$11,MATCH($D32,[2]ORTHO!$D$2:$D$11,0))),"") -> Deanne is reviewing this one - Rep Jessie - Claim contains a non anesthesia service, and rendering is listed as an anesthesiologist on ins end | C32: =IFERROR(IF(INDEX([2]ORTHO!$C$2:$C$11,MATCH($D32,[2]ORTHO!$D$2:$D$11,0))="","",INDEX([2]ORTHO!$C$2:$C$11,MATCH($D32,[2]ORTHO!$D$2:$D$11,0))),"") -> 46147 | D32: 555677002 | E32: HF540909294 | F32: 46059 | G32: Humana Gold Plus HMO | H32: Humana Gold Plus HMO | I32: No Payer | J32: 63048 x1; 63047 x1 | K32: =IFERROR(IF(INDEX([2]ORTHO!$K$2:$K$11,MATCH($D32,[2]ORTHO!$D$2:$D$11,0))="","",INDEX([2]ORTHO!$K$2:$K$11,MATCH($D32,[2]ORTHO!$D$2:$D$11,0))),"") -> 46247 | L32: =IF($O32="","",$O32-TODAY()) -> -155 | M32: =IF(AND(TRIM($A32)="Finalized",$K32<>""),"",IF($F32="","",$F32+90-TODAY())) -> -155 | N32: =IF(AND(TRIM($A32)="Finalized",$K32<>""),"",IF($C32="","",$C32+540-TODAY())) -> 383 | O32: =IF(AND(TRIM($A32)="Finalized",$K32<>""),"",DATE(2026,5,7)) -> 46149 | P32: 90 days | Q32: HUMANA MA | R32: 90 days | S32: Date of service | T32: 540 days | U32: Processed date | V32: 2026-02 February | W32: ORTHO | AA32: 1 | AB32: 9056.39 | AC32: 0 | AD32: 0 | AE32: 46147 | AF32: 9056.39 | AG32: 183 | AH32: M48062 | AM32: O'NEIL, ROY | AN32: ASAP Surgery Centers North Valley LLC | AO32: 46065
A33: =IFERROR(IF(INDEX([2]BH!$A$2:$A$9,MATCH($D33,[2]BH!$D$2:$D$9,0))="","",INDEX([2]BH!$A$2:$A$9,MATCH($D33,[2]BH!$D$2:$D$9,0))),"") -> Denied | B33: =IFERROR(IF(INDEX([2]BH!$B$2:$B$9,MATCH($D33,[2]BH!$D$2:$D$9,0))="","",INDEX([2]BH!$B$2:$B$9,MATCH($D33,[2]BH!$D$2:$D$9,0))),"") -> DND - Non contracted provider | C33: =IFERROR(IF(INDEX([2]BH!$C$2:$C$9,MATCH($D33,[2]BH!$D$2:$D$9,0))="","",INDEX([2]BH!$C$2:$C$9,MATCH($D33,[2]BH!$D$2:$D$9,0))),"") -> 46148 | D33: 548979329 | E33: HF527306886 | F33: 46062 | G33: Blue Cross Blue Shield of Arizona (BCBS AZ) | H33: Blue Cross Blue Shield of Arizona (BCBS AZ) | I33: No Payer | J33: 99493 x1; 99494 x1 | K33: =IFERROR(IF(INDEX([2]BH!$K$2:$K$9,MATCH($D33,[2]BH!$D$2:$D$9,0))="","",INDEX([2]BH!$K$2:$K$9,MATCH($D33,[2]BH!$D$2:$D$9,0))),"") -> 46183 | L33: =IF($O33="","",$O33-TODAY()) -> -152 | M33: =IF(AND(TRIM($A33)="Finalized",$K33<>""),"",IF($F33="","",$F33+90-TODAY())) -> -152 | N33: =IF(AND(TRIM($A33)="Finalized",$K33<>""),"",IF($C33="","",$C33+365-TODAY())) -> 209 | O33: =IF(AND(TRIM($A33)="Finalized",$K33<>""),"",DATE(2026,5,10)) -> 46152 | P33: 90 days | Q33: BCBS | R33: 90 days | S33: Date of service | T33: 365 days | U33: Processed date | V33: 2026-02 February | W33: BH | AA33: 1 | AB33: 1372.91 | AC33: 0 | AD33: 0 | AE33: 46148 | AF33: 1372.91 | AG33: 180 | AH33: F4320 | AM33: KALLGREN, MARK | AN33: ASAP Peoria | AO33: 46090
A34: =IFERROR(IF(INDEX([2]BH!$A$2:$A$9,MATCH($D34,[2]BH!$D$2:$D$9,0))="","",INDEX([2]BH!$A$2:$A$9,MATCH($D34,[2]BH!$D$2:$D$9,0))),"") -> Finalized | B34: =IFERROR(IF(INDEX([2]BH!$B$2:$B$9,MATCH($D34,[2]BH!$D$2:$D$9,0))="","",INDEX([2]BH!$B$2:$B$9,MATCH($D34,[2]BH!$D$2:$D$9,0))),"") | C34: =IFERROR(IF(INDEX([2]BH!$C$2:$C$9,MATCH($D34,[2]BH!$D$2:$D$9,0))="","",INDEX([2]BH!$C$2:$C$9,MATCH($D34,[2]BH!$D$2:$D$9,0))),"") -> 46119 | D34: 549765437 | E34: HF359780591 | F34: 46065 | G34: TRIADA GAP BENEFITS | H34: Blue Cross Blue Shield of Arizona (BCBS AZ) | I34: TRIADA GAP BENEFITS | J34: 99493 x1; 99494 x1 | K34: =IFERROR(IF(INDEX([2]BH!$K$2:$K$9,MATCH($D34,[2]BH!$D$2:$D$9,0))="","",INDEX([2]BH!$K$2:$K$9,MATCH($D34,[2]BH!$D$2:$D$9,0))),"") | L34: =IF($O34="","",$O34-TODAY()) -> -149 | M34: =IF(AND(TRIM($A34)="Finalized",$K34<>""),"",IF($F34="","",$F34+90-TODAY())) -> -149 | N34: =IF(AND(TRIM($A34)="Finalized",$K34<>""),"",IF($C34="","",$C34+365-TODAY())) -> 180 | O34: =IF(AND(TRIM($A34)="Finalized",$K34<>""),"",DATE(2026,5,13)) -> 46155 | P34: 90 days | Q34: BCBS | R34: 90 days | S34: Date of service | T34: 365 days | U34: Processed date | V34: 2026-02 February | W34: BH | AA34: 1 | AB34: 1372.91 | AC34: 1179.89 | AD34: 0 | AE34: 46119 | AF34: 193.02 | AG34: 177 | AH34: F411 | AL34: 558453526 | AM34: LEATHEM, JARRETT | AN34: ASAP - DEER VALLEY | AO34: 46086
A35: =IFERROR(IF(INDEX([1]BH!$A$2:$A$17,MATCH($D35,[1]BH!$D$2:$D$17,0))="","",INDEX([1]BH!$A$2:$A$17,MATCH($D35,[1]BH!$D$2:$D$17,0))),"") -> Rejected | B35: =IFERROR(IF(INDEX([1]BH!$B$2:$B$17,MATCH($D35,[1]BH!$D$2:$D$17,0))="","",INDEX([1]BH!$B$2:$B$17,MATCH($D35,[1]BH!$D$2:$D$17,0))),"") -> ASAP DEER VALLEY NPI missing - Resubmitted | C35: =IFERROR(IF(INDEX([1]BH!$C$2:$C$17,MATCH($D35,[1]BH!$D$2:$D$17,0))="","",INDEX([1]BH!$C$2:$C$17,MATCH($D35,[1]BH!$D$2:$D$17,0))),"") -> 46098 | D35: 557090486 | E35: HF342585384 | F35: 46036 | G35: TRIWEST VA CCN CLAIMS | H35: TRIWEST VA CCN CLAIMS | I35: No Payer | J35: 99494 x2; 99493 x1 | K35: =IFERROR(IF(INDEX([1]BH!$K$2:$K$17,MATCH($D35,[1]BH!$D$2:$D$17,0))="","",INDEX([1]BH!$K$2:$K$17,MATCH($D35,[1]BH!$D$2:$D$17,0))),"") -> 46135 | L35: =IF($O35="","",$O35-TODAY()) -> -148 | M35: =IF(AND(TRIM($A35)="Finalized",$K35<>""),"",IF($C35="","",$C35+365-TODAY())) -> 159 | N35: =IF(AND(TRIM($A35)="Finalized",$K35<>""),"",IF($C35="","",$C35+90-TODAY())) -> -116 | O35: =IF(AND(TRIM($A35)="Finalized",$K35<>""),"",DATE(2026,5,14)) -> 46156 | P35: 120 days | Q35: TRIWEST | R35: 365 days | S35: Processed date | T35: 90 days | U35: Processed date | V35: 2026-01 January | W35: BH | AA35: 2, 1 | AB35: 1769.18 | AC35: 0 | AD35: 0 | AE35: 46098 | AF35: 1769.18 | AG35: 206 | AH35: F332 | AM35: TURLEY, TODD | AN35: ASAP - DEER VALLEY | AO35: 46056
A36: =IFERROR(IF(INDEX([2]BH!$A$2:$A$9,MATCH($D36,[2]BH!$D$2:$D$9,0))="","",INDEX([2]BH!$A$2:$A$9,MATCH($D36,[2]BH!$D$2:$D$9,0))),"") -> Denied | B36: =IFERROR(IF(INDEX([2]BH!$B$2:$B$9,MATCH($D36,[2]BH!$D$2:$D$9,0))="","",INDEX([2]BH!$B$2:$B$9,MATCH($D36,[2]BH!$D$2:$D$9,0))),"") -> Added Date of Current Illness, claim note, and resubmitted | C36: =IFERROR(IF(INDEX([2]BH!$C$2:$C$9,MATCH($D36,[2]BH!$D$2:$D$9,0))="","",INDEX([2]BH!$C$2:$C$9,MATCH($D36,[2]BH!$D$2:$D$9,0))),"") -> 46147 | D36: 557794433 | E36: HF434792716 | F36: 46066 | G36: Optum Care Medical Network of Arizona, Utah, & Washington (LifePrint) | H36: Optum Care Medical Network of Arizona, Utah, & Washington (LifePrint) | I36: No Payer | J36: 99493 x1 | K36: =IFERROR(IF(INDEX([2]BH!$K$2:$K$9,MATCH($D36,[2]BH!$D$2:$D$9,0))="","",INDEX([2]BH!$K$2:$K$9,MATCH($D36,[2]BH!$D$2:$D$9,0))),"") -> 46142 | L36: =IF($O36="","",$O36-TODAY()) -> -148 | M36: =IF(AND(TRIM($A36)="Finalized",$K36<>""),"",IF($C36="","",$C36+365-TODAY())) -> 208 | N36: =IF(AND(TRIM($A36)="Finalized",$K36<>""),"",IF($C36="","",$C36+365-TODAY())) -> 208 | O36: =IF(AND(TRIM($A36)="Finalized",$K36<>""),"",DATE(2026,5,14)) -> 46156 | P36: 90 days | Q36: OPTUM | R36: 365 days | S36: Processed date | T36: 365 days | U36: Processed date | V36: 2026-02 February | W36: BH | AA36: 1 | AB36: 976.64 | AC36: 0 | AD36: 0 | AE36: 46147 | AF36: 976.64 | AG36: 176 | AH36: F1190 | AM36: LEATHEM, JARRETT | AN36: ASAP - Gilbert | AO36: 46086
A37: =IFERROR(IF(INDEX([2]GAE!$A$2:$A$6,MATCH($D37,[2]GAE!$D$2:$D$6,0))="","",INDEX([2]GAE!$A$2:$A$6,MATCH($D37,[2]GAE!$D$2:$D$6,0))),"") -> Denied | B37: =IFERROR(IF(INDEX([2]GAE!$B$2:$B$6,MATCH($D37,[2]GAE!$D$2:$D$6,0))="","",INDEX([2]GAE!$B$2:$B$6,MATCH($D37,[2]GAE!$D$2:$D$6,0))),"") -> Provider active, resubmitted | C37: =IFERROR(IF(INDEX([2]GAE!$C$2:$C$6,MATCH($D37,[2]GAE!$D$2:$D$6,0))="","",INDEX([2]GAE!$C$2:$C$6,MATCH($D37,[2]GAE!$D$2:$D$6,0))),"") -> 46154 | D37: 557784595 | E37: HF489558936 | F37: 46069 | G37: Blue Cross Blue Shield of Arizona (BCBS AZ) | H37: Blue Cross Blue Shield of Arizona (BCBS AZ) | I37: No Payer | J37: 36246+59+RT x1; 75710+XU+RT x1; 76937 x1; 75774+XU x4; 36248+59 x3; 37242 x1 | K37: =IFERROR(IF(INDEX([2]GAE!$K$2:$K$6,MATCH($D37,[2]GAE!$D$2:$D$6,0))="","",INDEX([2]GAE!$K$2:$K$6,MATCH($D37,[2]GAE!$D$2:$D$6,0))),"") -> 46142 | L37: =IF($O37="","",$O37-TODAY()) -> -145 | M37: =IF(AND(TRIM($A37)="Finalized",$K37<>""),"",IF($F37="","",$F37+90-TODAY())) -> -145 | N37: =IF(AND(TRIM($A37)="Finalized",$K37<>""),"",IF($C37="","",$C37+365-TODAY())) -> 215 | O37: =IF(AND(TRIM($A37)="Finalized",$K37<>""),"",DATE(2026,5,17)) -> 46159 | P37: 90 days | Q37: BCBS | R37: 90 days | S37: Date of service | T37: 365 days | U37: Processed date | V37: 2026-02 February | W37: GAE | X37: 59, XU | Y37: RT | AA37: 1, 4, 3 | AB37: 61320.35 | AC37: 0 | AD37: 0 | AE37: 46154 | AF37: 61320.35 | AG37: 173 | AH37: M1711 | AI37: I798 | AJ37: M25561 | AM37: HUNTER, DREW | AN37: ASAP - DEER VALLEY | AO37: 46090
A38: =IFERROR(IF(INDEX([2]DME!$A$2:$A$12,MATCH($D38,[2]DME!$D$2:$D$12,0))="","",INDEX([2]DME!$A$2:$A$12,MATCH($D38,[2]DME!$D$2:$D$12,0))),"") -> Under Review | B38: =IFERROR(IF(INDEX([2]DME!$B$2:$B$12,MATCH($D38,[2]DME!$D$2:$D$12,0))="","",INDEX([2]DME!$B$2:$B$12,MATCH($D38,[2]DME!$D$2:$D$12,0))),"") -> Auth issue - Denied payment again - Bri resubmitted - Provider TAX ID/NPI Combination is not on file with BCBS AZ. | C38: =IFERROR(IF(INDEX([2]DME!$C$2:$C$12,MATCH($D38,[2]DME!$D$2:$D$12,0))="","",INDEX([2]DME!$C$2:$C$12,MATCH($D38,[2]DME!$D$2:$D$12,0))),"") -> 46227 | D38: 565140993 | E38: HF513477727 | F38: 46069 | G38: Blue Cross Blue Shield of Arizona (BCBS AZ) | H38: Blue Cross Blue Shield of Arizona (BCBS AZ) | I38: No Payer | J38: L0648+KX x1 | K38: =IFERROR(IF(INDEX([2]DME!$K$2:$K$12,MATCH($D38,[2]DME!$D$2:$D$12,0))="","",INDEX([2]DME!$K$2:$K$12,MATCH($D38,[2]DME!$D$2:$D$12,0))),"") -> 46196 | L38: =IF($O38="","",$O38-TODAY()) -> -145 | M38: =IF(AND(TRIM($A38)="Finalized",$K38<>""),"",IF($F38="","",$F38+90-TODAY())) -> -145 | N38: =IF(AND(TRIM($A38)="Finalized",$K38<>""),"",IF($C38="","",$C38+365-TODAY())) -> 288 | O38: =IF(AND(TRIM($A38)="Finalized",$K38<>""),"",DATE(2026,5,17)) -> 46159 | P38: 90 days | Q38: BCBS | R38: 90 days | S38: Date of service | T38: 365 days | U38: Processed date | V38: 2026-02 February | W38: DME | X38: KX | AA38: 1 | AB38: 5492.55 | AC38: 0 | AD38: 0 | AF38: 5492.55 | AG38: 173 | AH38: M4316 | AI38: M51362 | AM38: MAYURAN, VIKRAM | AN38: ASAP - Mesa | AO38: 46080
A39: =IFERROR(IF(INDEX([2]BH!$A$2:$A$9,MATCH($D39,[2]BH!$D$2:$D$9,0))="","",INDEX([2]BH!$A$2:$A$9,MATCH($D39,[2]BH!$D$2:$D$9,0))),"") -> Denied | B39: =IFERROR(IF(INDEX([2]BH!$B$2:$B$9,MATCH($D39,[2]BH!$D$2:$D$9,0))="","",INDEX([2]BH!$B$2:$B$9,MATCH($D39,[2]BH!$D$2:$D$9,0))),"") -> Awaiting resolution on claim #556349314 (DOS 01/27/2026) before reprocessing DND 99493 This non-payable code is for required reporting only - Added Date of Current Illness, claim note, and resubmitted | C39: =IFERROR(IF(INDEX([2]BH!$C$2:$C$9,MATCH($D39,[2]BH!$D$2:$D$9,0))="","",INDEX([2]BH!$C$2:$C$9,MATCH($D39,[2]BH!$D$2:$D$9,0))),"") -> 46147 | D39: 557794882 | E39: HF431164004 | F39: 46070 | G39: Optum Care Medical Network of Arizona, Utah, & Washington (LifePrint) | H39: Optum Care Medical Network of Arizona, Utah, & Washington (LifePrint) | I39: No Payer | J39: 99493 x1 | K39: =IFERROR(IF(INDEX([2]BH!$K$2:$K$9,MATCH($D39,[2]BH!$D$2:$D$9,0))="","",INDEX([2]BH!$K$2:$K$9,MATCH($D39,[2]BH!$D$2:$D$9,0))),"") -> 46284 | L39: =IF($O39="","",$O39-TODAY()) -> -144 | M39: =IF(AND(TRIM($A39)="Finalized",$K39<>""),"",IF($C39="","",$C39+365-TODAY())) -> 208 | N39: =IF(AND(TRIM($A39)="Finalized",$K39<>""),"",IF($C39="","",$C39+365-TODAY())) -> 208 | O39: =IF(AND(TRIM($A39)="Finalized",$K39<>""),"",DATE(2026,5,18)) -> 46160 | P39: 90 days | Q39: OPTUM | R39: 365 days | S39: Processed date | T39: 365 days | U39: Processed date | V39: 2026-02 February | W39: BH | AA39: 1 | AB39: 976.64 | AC39: 0 | AD39: 0 | AE39: 46147 | AF39: 976.64 | AG39: 172 | AH39: F331 | AI39: F411 | AM39: O'NEIL, ROY | AN39: ASAP - Goodyear | AO39: 46086
